{"timestamp": "2025-08-27T07:39:18.908774Z", "level": "ERROR", "trace_id": "2a6bf0a3-b19e-409e-9187-8888e244c68f", "module": "app.middleware.rate_limiting", "message": "Failed to connect to Redis: Error Multiple exceptions: [Errno 10061] Connect call failed ('::1', 6379, 0, 0), [Errno 10061] Connect call failed ('127.0.0.1', 6379) connecting to localhost:6379.", "location": {"file": "D:\\dex\\backend\\app\\middleware\\rate_limiting.py", "line": 167, "function": "connect"}}
{"timestamp": "2025-08-27T07:39:18.908774Z", "level": "ERROR", "trace_id": "2a6bf0a3-b19e-409e-9187-8888e244c68f", "module": "main", "message": "Failed to initialize Redis rate limiter", "location": {"file": "D:\\dex\\backend\\main.py", "line": 445, "function": "setup_enhanced_rate_limiting"}}
{"timestamp": "2025-08-27T07:40:01.127445Z", "level": "ERROR", "trace_id": "2a6bf0a3-b19e-409e-9187-8888e244c68f", "module": "app.api.wallet", "message": "Logging failed: \"Attempt to overwrite 'message' in LogRecord\". Original message: Wallet registration request received", "location": {"file": "D:\\dex\\backend\\app\\api\\wallet.py", "line": 198, "function": "log_wallet_operation"}}
{"timestamp": "2025-08-27T07:40:01.127445Z", "level": "ERROR", "trace_id": "2a6bf0a3-b19e-409e-9187-8888e244c68f", "module": "app.api.wallet", "message": "Logging failed: \"Attempt to overwrite 'message' in LogRecord\". Original message: Wallet registration completed successfully", "location": {"file": "D:\\dex\\backend\\app\\api\\wallet.py", "line": 198, "function": "log_wallet_operation"}}
{"timestamp": "2025-08-27T07:40:01.234097Z", "level": "ERROR", "trace_id": "2a6bf0a3-b19e-409e-9187-8888e244c68f", "module": "app.api.wallet", "message": "Logging failed: \"Attempt to overwrite 'message' in LogRecord\". Original message: Wallet registration metrics logged", "location": {"file": "D:\\dex\\backend\\app\\api\\wallet.py", "line": 198, "function": "log_wallet_operation"}}
{"timestamp": "2025-08-27T07:40:09.633096Z", "level": "ERROR", "trace_id": "2a6bf0a3-b19e-409e-9187-8888e244c68f", "module": "app.api.wallet", "message": "Logging failed: \"Attempt to overwrite 'message' in LogRecord\". Original message: Wallet connection check", "location": {"file": "D:\\dex\\backend\\app\\api\\wallet.py", "line": 198, "function": "log_wallet_operation"}}
{"timestamp": "2025-08-27T07:40:09.634116Z", "level": "ERROR", "trace_id": "2a6bf0a3-b19e-409e-9187-8888e244c68f", "module": "app.api.wallet", "message": "Logging failed: \"Attempt to overwrite 'message' in LogRecord\". Original message: Wallet connection check", "location": {"file": "D:\\dex\\backend\\app\\api\\wallet.py", "line": 198, "function": "log_wallet_operation"}}
{"timestamp": "2025-08-27T07:40:09.636086Z", "level": "ERROR", "trace_id": "2a6bf0a3-b19e-409e-9187-8888e244c68f", "module": "app.api.wallet", "message": "Logging failed: \"Attempt to overwrite 'message' in LogRecord\". Original message: Wallet connection check", "location": {"file": "D:\\dex\\backend\\app\\api\\wallet.py", "line": 198, "function": "log_wallet_operation"}}
{"timestamp": "2025-08-27T07:40:09.638081Z", "level": "ERROR", "trace_id": "2a6bf0a3-b19e-409e-9187-8888e244c68f", "module": "app.api.wallet", "message": "Logging failed: \"Attempt to overwrite 'message' in LogRecord\". Original message: Wallet connection check", "location": {"file": "D:\\dex\\backend\\app\\api\\wallet.py", "line": 198, "function": "log_wallet_operation"}}
{"timestamp": "2025-08-27T07:40:09.712865Z", "level": "ERROR", "trace_id": "2a6bf0a3-b19e-409e-9187-8888e244c68f", "module": "app.api.wallet", "message": "Logging failed: \"Attempt to overwrite 'message' in LogRecord\". Original message: Wallet connection check", "location": {"file": "D:\\dex\\backend\\app\\api\\wallet.py", "line": 198, "function": "log_wallet_operation"}}
{"timestamp": "2025-08-27T07:40:09.715024Z", "level": "ERROR", "trace_id": "2a6bf0a3-b19e-409e-9187-8888e244c68f", "module": "app.api.wallet", "message": "Logging failed: \"Attempt to overwrite 'message' in LogRecord\". Original message: Wallet connection check", "location": {"file": "D:\\dex\\backend\\app\\api\\wallet.py", "line": 198, "function": "log_wallet_operation"}}
{"timestamp": "2025-08-27T07:40:12.025263Z", "level": "ERROR", "trace_id": "2a6bf0a3-b19e-409e-9187-8888e244c68f", "module": "app.api.wallet", "message": "Logging failed: \"Attempt to overwrite 'message' in LogRecord\". Original message: Wallet connection check", "location": {"file": "D:\\dex\\backend\\app\\api\\wallet.py", "line": 198, "function": "log_wallet_operation"}}
{"timestamp": "2025-08-27T07:40:12.028246Z", "level": "ERROR", "trace_id": "2a6bf0a3-b19e-409e-9187-8888e244c68f", "module": "app.api.wallet", "message": "Logging failed: \"Attempt to overwrite 'message' in LogRecord\". Original message: Wallet connection check", "location": {"file": "D:\\dex\\backend\\app\\api\\wallet.py", "line": 198, "function": "log_wallet_operation"}}
{"timestamp": "2025-08-27T07:40:37.970796Z", "level": "ERROR", "trace_id": "2a6bf0a3-b19e-409e-9187-8888e244c68f", "module": "app.api.wallet", "message": "Logging failed: \"Attempt to overwrite 'message' in LogRecord\". Original message: Wallet connection check", "location": {"file": "D:\\dex\\backend\\app\\api\\wallet.py", "line": 198, "function": "log_wallet_operation"}}
{"timestamp": "2025-08-27T07:40:37.972305Z", "level": "ERROR", "trace_id": "2a6bf0a3-b19e-409e-9187-8888e244c68f", "module": "app.api.wallet", "message": "Logging failed: \"Attempt to overwrite 'message' in LogRecord\". Original message: Wallet connection check", "location": {"file": "D:\\dex\\backend\\app\\api\\wallet.py", "line": 198, "function": "log_wallet_operation"}}
{"timestamp": "2025-08-27T07:57:42.284898Z", "level": "ERROR", "trace_id": "d18ba9d5-b02a-40f7-888b-1bf0477244c5", "module": "app.middleware.rate_limiting", "message": "Failed to connect to Redis: Error Multiple exceptions: [Errno 10061] Connect call failed ('::1', 6379, 0, 0), [Errno 10061] Connect call failed ('127.0.0.1', 6379) connecting to localhost:6379.", "location": {"file": "D:\\dex\\backend\\app\\middleware\\rate_limiting.py", "line": 167, "function": "connect"}}
{"timestamp": "2025-08-27T07:57:42.286174Z", "level": "ERROR", "trace_id": "d18ba9d5-b02a-40f7-888b-1bf0477244c5", "module": "main", "message": "Failed to initialize Redis rate limiter", "location": {"file": "D:\\dex\\backend\\main.py", "line": 445, "function": "setup_enhanced_rate_limiting"}}
{"timestamp": "2025-08-27T07:58:37.889380Z", "level": "ERROR", "trace_id": "495c8406-8b8e-4337-b3d2-882734a8b845", "module": "app.middleware.rate_limiting", "message": "Failed to connect to Redis: Error Multiple exceptions: [Errno 10061] Connect call failed ('::1', 6379, 0, 0), [Errno 10061] Connect call failed ('127.0.0.1', 6379) connecting to localhost:6379.", "location": {"file": "D:\\dex\\backend\\app\\middleware\\rate_limiting.py", "line": 167, "function": "connect"}}
{"timestamp": "2025-08-27T07:58:37.889885Z", "level": "ERROR", "trace_id": "495c8406-8b8e-4337-b3d2-882734a8b845", "module": "main", "message": "Failed to initialize Redis rate limiter", "location": {"file": "D:\\dex\\backend\\main.py", "line": 445, "function": "setup_enhanced_rate_limiting"}}
{"timestamp": "2025-08-27T07:59:45.217549Z", "level": "ERROR", "trace_id": "0350f3c8-d25d-4077-9587-feed5fa4fb9a", "module": "app.middleware.rate_limiting", "message": "Failed to connect to Redis: Error Multiple exceptions: [Errno 10061] Connect call failed ('::1', 6379, 0, 0), [Errno 10061] Connect call failed ('127.0.0.1', 6379) connecting to localhost:6379.", "location": {"file": "D:\\dex\\backend\\app\\middleware\\rate_limiting.py", "line": 167, "function": "connect"}}
{"timestamp": "2025-08-27T07:59:45.218057Z", "level": "ERROR", "trace_id": "0350f3c8-d25d-4077-9587-feed5fa4fb9a", "module": "main", "message": "Failed to initialize Redis rate limiter", "location": {"file": "D:\\dex\\backend\\main.py", "line": 445, "function": "setup_enhanced_rate_limiting"}}
{"timestamp": "2025-08-27T08:00:01.596409Z", "level": "ERROR", "trace_id": "b02fcf21-1cf0-43ac-acff-848d3610016a", "module": "app.middleware.rate_limiting", "message": "Failed to connect to Redis: Error Multiple exceptions: [Errno 10061] Connect call failed ('::1', 6379, 0, 0), [Errno 10061] Connect call failed ('127.0.0.1', 6379) connecting to localhost:6379.", "location": {"file": "D:\\dex\\backend\\app\\middleware\\rate_limiting.py", "line": 167, "function": "connect"}}
{"timestamp": "2025-08-27T08:00:01.596409Z", "level": "ERROR", "trace_id": "b02fcf21-1cf0-43ac-acff-848d3610016a", "module": "main", "message": "Failed to initialize Redis rate limiter", "location": {"file": "D:\\dex\\backend\\main.py", "line": 445, "function": "setup_enhanced_rate_limiting"}}
{"timestamp": "2025-08-27T08:00:13.414482Z", "level": "ERROR", "trace_id": "f93e611b-de0e-4969-86de-6ec4ae6fa471", "module": "app.middleware.rate_limiting", "message": "Failed to connect to Redis: Error Multiple exceptions: [Errno 10061] Connect call failed ('::1', 6379, 0, 0), [Errno 10061] Connect call failed ('127.0.0.1', 6379) connecting to localhost:6379.", "location": {"file": "D:\\dex\\backend\\app\\middleware\\rate_limiting.py", "line": 167, "function": "connect"}}
{"timestamp": "2025-08-27T08:00:13.415532Z", "level": "ERROR", "trace_id": "f93e611b-de0e-4969-86de-6ec4ae6fa471", "module": "main", "message": "Failed to initialize Redis rate limiter", "location": {"file": "D:\\dex\\backend\\main.py", "line": 445, "function": "setup_enhanced_rate_limiting"}}
{"timestamp": "2025-08-27T08:00:27.235864Z", "level": "ERROR", "trace_id": "dc7e28ab-d022-479b-9e3c-a2b5adf2c26b", "module": "app.middleware.rate_limiting", "message": "Failed to connect to Redis: Error Multiple exceptions: [Errno 10061] Connect call failed ('::1', 6379, 0, 0), [Errno 10061] Connect call failed ('127.0.0.1', 6379) connecting to localhost:6379.", "location": {"file": "D:\\dex\\backend\\app\\middleware\\rate_limiting.py", "line": 167, "function": "connect"}}
{"timestamp": "2025-08-27T08:00:27.236467Z", "level": "ERROR", "trace_id": "dc7e28ab-d022-479b-9e3c-a2b5adf2c26b", "module": "main", "message": "Failed to initialize Redis rate limiter", "location": {"file": "D:\\dex\\backend\\main.py", "line": 445, "function": "setup_enhanced_rate_limiting"}}
{"timestamp": "2025-08-27T09:49:35.449490Z", "level": "ERROR", "trace_id": "6080f39c-0503-49e3-b8c9-0a8f03b20b5b", "module": "app.middleware.rate_limiting", "message": "Failed to connect to Redis: Error Multiple exceptions: [Errno 10061] Connect call failed ('::1', 6379, 0, 0), [Errno 10061] Connect call failed ('127.0.0.1', 6379) connecting to localhost:6379.", "location": {"file": "D:\\dex\\backend\\app\\middleware\\rate_limiting.py", "line": 167, "function": "connect"}}
{"timestamp": "2025-08-27T09:49:35.449490Z", "level": "ERROR", "trace_id": "6080f39c-0503-49e3-b8c9-0a8f03b20b5b", "module": "main", "message": "Failed to initialize Redis rate limiter", "location": {"file": "D:\\dex\\backend\\main.py", "line": 445, "function": "setup_enhanced_rate_limiting"}}
{"timestamp": "2025-08-27T09:55:58.491556Z", "level": "ERROR", "trace_id": "9bd09eec-714e-431f-aacb-29dea15ef837", "module": "app.api", "message": "\u274c Database Operations API registration failed: name 'BaseModel' is not defined", "location": {"file": "D:\\dex\\backend\\app\\api\\__init__.py", "line": 51, "function": "_register_router"}}
{"timestamp": "2025-08-27T09:55:58.715907Z", "level": "ERROR", "trace_id": "9bd09eec-714e-431f-aacb-29dea15ef837", "module": "app.api", "message": "\u274c Automated Trading API registration failed: name 'BaseModel' is not defined", "location": {"file": "D:\\dex\\backend\\app\\api\\__init__.py", "line": 51, "function": "_register_router"}}
{"timestamp": "2025-08-27T09:55:58.804188Z", "level": "ERROR", "trace_id": "9bd09eec-714e-431f-aacb-29dea15ef837", "module": "app.api", "message": "\u274c Ledger & Portfolio Tracking API registration failed: name 'BaseModel' is not defined", "location": {"file": "D:\\dex\\backend\\app\\api\\__init__.py", "line": 51, "function": "_register_router"}}
{"timestamp": "2025-08-27T09:55:58.829601Z", "level": "ERROR", "trace_id": "9bd09eec-714e-431f-aacb-29dea15ef837", "module": "app.api", "message": "\ud83d\udea8 PORTFOLIO LIMITED: Ledger router failed - portfolio will use demo data", "location": {"file": "D:\\dex\\backend\\app\\api\\__init__.py", "line": 148, "function": "<module>"}}
{"timestamp": "2025-08-27T09:56:02.955751Z", "level": "ERROR", "trace_id": "9bd09eec-714e-431f-aacb-29dea15ef837", "module": "app.middleware.rate_limiting", "message": "Failed to connect to Redis: Error Multiple exceptions: [Errno 10061] Connect call failed ('::1', 6379, 0, 0), [Errno 10061] Connect call failed ('127.0.0.1', 6379) connecting to localhost:6379.", "location": {"file": "D:\\dex\\backend\\app\\middleware\\rate_limiting.py", "line": 167, "function": "connect"}}
{"timestamp": "2025-08-27T09:56:02.955751Z", "level": "ERROR", "trace_id": "9bd09eec-714e-431f-aacb-29dea15ef837", "module": "main", "message": "Failed to initialize Redis rate limiter", "location": {"file": "D:\\dex\\backend\\main.py", "line": 445, "function": "setup_enhanced_rate_limiting"}}
{"timestamp": "2025-08-27T09:56:03.006238Z", "level": "ERROR", "trace_id": "9bd09eec-714e-431f-aacb-29dea15ef837", "module": "app.storage.database", "message": "Failed to create database tables: name 'BaseModel' is not defined", "location": {"file": "D:\\dex\\backend\\app\\storage\\database.py", "line": 412, "function": "create_tables"}}
{"timestamp": "2025-08-27T09:56:03.006238Z", "level": "ERROR", "trace_id": "9bd09eec-714e-431f-aacb-29dea15ef837", "module": "app.storage.database", "message": "Failed to create tables: name 'BaseModel' is not defined", "location": {"file": "D:\\dex\\backend\\app\\storage\\database.py", "line": 439, "function": "create_tables"}}
{"timestamp": "2025-08-27T09:56:03.006746Z", "level": "ERROR", "trace_id": "9bd09eec-714e-431f-aacb-29dea15ef837", "module": "app.storage.database", "message": "Database initialization failed: name 'BaseModel' is not defined", "location": {"file": "D:\\dex\\backend\\app\\storage\\database.py", "line": 461, "function": "init_database"}}
{"timestamp": "2025-08-27T09:56:03.006746Z", "level": "ERROR", "trace_id": "9bd09eec-714e-431f-aacb-29dea15ef837", "module": "main", "message": "Database initialization failed: name 'BaseModel' is not defined", "location": {"file": "D:\\dex\\backend\\main.py", "line": 511, "function": "lifespan"}}
{"timestamp": "2025-08-27T09:56:03.050948Z", "level": "ERROR", "trace_id": "9bd09eec-714e-431f-aacb-29dea15ef837", "module": "main", "message": "Wallet registry initialization failed: name 'BaseModel' is not defined", "location": {"file": "D:\\dex\\backend\\main.py", "line": 528, "function": "lifespan"}}
{"timestamp": "2025-08-27T09:56:03.450140Z", "level": "ERROR", "trace_id": "9bd09eec-714e-431f-aacb-29dea15ef837", "module": "main", "message": "Startup completed with 1 errors:", "location": {"file": "D:\\dex\\backend\\main.py", "line": 734, "function": "lifespan"}}
{"timestamp": "2025-08-27T09:56:03.450140Z", "level": "ERROR", "trace_id": "9bd09eec-714e-431f-aacb-29dea15ef837", "module": "main", "message": "  - Database initialization failed: name 'BaseModel' is not defined", "location": {"file": "D:\\dex\\backend\\main.py", "line": 736, "function": "lifespan"}}
{"timestamp": "2025-08-27T09:56:05.616725Z", "level": "ERROR", "trace_id": "4ba51fe2-a2f6-452c-a873-b30695d386d8", "module": "app.api", "message": "\u274c Database Operations API registration failed: name 'BaseModel' is not defined", "location": {"file": "D:\\dex\\backend\\app\\api\\__init__.py", "line": 51, "function": "_register_router"}}
{"timestamp": "2025-08-27T09:56:05.841743Z", "level": "ERROR", "trace_id": "4ba51fe2-a2f6-452c-a873-b30695d386d8", "module": "app.api", "message": "\u274c Automated Trading API registration failed: name 'BaseModel' is not defined", "location": {"file": "D:\\dex\\backend\\app\\api\\__init__.py", "line": 51, "function": "_register_router"}}
{"timestamp": "2025-08-27T09:56:05.930066Z", "level": "ERROR", "trace_id": "4ba51fe2-a2f6-452c-a873-b30695d386d8", "module": "app.api", "message": "\u274c Ledger & Portfolio Tracking API registration failed: name 'BaseModel' is not defined", "location": {"file": "D:\\dex\\backend\\app\\api\\__init__.py", "line": 51, "function": "_register_router"}}
{"timestamp": "2025-08-27T09:56:05.956140Z", "level": "ERROR", "trace_id": "4ba51fe2-a2f6-452c-a873-b30695d386d8", "module": "app.api", "message": "\ud83d\udea8 PORTFOLIO LIMITED: Ledger router failed - portfolio will use demo data", "location": {"file": "D:\\dex\\backend\\app\\api\\__init__.py", "line": 148, "function": "<module>"}}
{"timestamp": "2025-08-27T09:56:10.091175Z", "level": "ERROR", "trace_id": "4ba51fe2-a2f6-452c-a873-b30695d386d8", "module": "app.middleware.rate_limiting", "message": "Failed to connect to Redis: Error Multiple exceptions: [Errno 10061] Connect call failed ('::1', 6379, 0, 0), [Errno 10061] Connect call failed ('127.0.0.1', 6379) connecting to localhost:6379.", "location": {"file": "D:\\dex\\backend\\app\\middleware\\rate_limiting.py", "line": 167, "function": "connect"}}
{"timestamp": "2025-08-27T09:56:10.091175Z", "level": "ERROR", "trace_id": "4ba51fe2-a2f6-452c-a873-b30695d386d8", "module": "main", "message": "Failed to initialize Redis rate limiter", "location": {"file": "D:\\dex\\backend\\main.py", "line": 445, "function": "setup_enhanced_rate_limiting"}}
{"timestamp": "2025-08-27T09:56:10.141786Z", "level": "ERROR", "trace_id": "4ba51fe2-a2f6-452c-a873-b30695d386d8", "module": "app.storage.database", "message": "Failed to create database tables: name 'BaseModel' is not defined", "location": {"file": "D:\\dex\\backend\\app\\storage\\database.py", "line": 412, "function": "create_tables"}}
{"timestamp": "2025-08-27T09:56:10.141786Z", "level": "ERROR", "trace_id": "4ba51fe2-a2f6-452c-a873-b30695d386d8", "module": "app.storage.database", "message": "Failed to create tables: name 'BaseModel' is not defined", "location": {"file": "D:\\dex\\backend\\app\\storage\\database.py", "line": 439, "function": "create_tables"}}
{"timestamp": "2025-08-27T09:56:10.142753Z", "level": "ERROR", "trace_id": "4ba51fe2-a2f6-452c-a873-b30695d386d8", "module": "app.storage.database", "message": "Database initialization failed: name 'BaseModel' is not defined", "location": {"file": "D:\\dex\\backend\\app\\storage\\database.py", "line": 461, "function": "init_database"}}
{"timestamp": "2025-08-27T09:56:10.142753Z", "level": "ERROR", "trace_id": "4ba51fe2-a2f6-452c-a873-b30695d386d8", "module": "main", "message": "Database initialization failed: name 'BaseModel' is not defined", "location": {"file": "D:\\dex\\backend\\main.py", "line": 511, "function": "lifespan"}}
{"timestamp": "2025-08-27T09:56:10.188798Z", "level": "ERROR", "trace_id": "4ba51fe2-a2f6-452c-a873-b30695d386d8", "module": "main", "message": "Wallet registry initialization failed: name 'BaseModel' is not defined", "location": {"file": "D:\\dex\\backend\\main.py", "line": 528, "function": "lifespan"}}
{"timestamp": "2025-08-27T09:56:10.587030Z", "level": "ERROR", "trace_id": "4ba51fe2-a2f6-452c-a873-b30695d386d8", "module": "main", "message": "Startup completed with 1 errors:", "location": {"file": "D:\\dex\\backend\\main.py", "line": 734, "function": "lifespan"}}
{"timestamp": "2025-08-27T09:56:10.587030Z", "level": "ERROR", "trace_id": "4ba51fe2-a2f6-452c-a873-b30695d386d8", "module": "main", "message": "  - Database initialization failed: name 'BaseModel' is not defined", "location": {"file": "D:\\dex\\backend\\main.py", "line": 736, "function": "lifespan"}}
{"timestamp": "2025-08-27T09:59:35.477453Z", "level": "ERROR", "trace_id": "abcb8731-0406-4250-b645-5ed096244eb8", "module": "app.middleware.rate_limiting", "message": "Failed to connect to Redis: Error Multiple exceptions: [Errno 10061] Connect call failed ('::1', 6379, 0, 0), [Errno 10061] Connect call failed ('127.0.0.1', 6379) connecting to localhost:6379.", "location": {"file": "D:\\dex\\backend\\app\\middleware\\rate_limiting.py", "line": 167, "function": "connect"}}
{"timestamp": "2025-08-27T09:59:35.477453Z", "level": "ERROR", "trace_id": "abcb8731-0406-4250-b645-5ed096244eb8", "module": "main", "message": "Failed to initialize Redis rate limiter", "location": {"file": "D:\\dex\\backend\\main.py", "line": 445, "function": "setup_enhanced_rate_limiting"}}
{"timestamp": "2025-08-27T10:12:28.472365Z", "level": "ERROR", "trace_id": "febd3214-e33a-458f-9c8d-6c4c93ee11cb", "module": "app.middleware.rate_limiting", "message": "Failed to connect to Redis: Error Multiple exceptions: [Errno 10061] Connect call failed ('::1', 6379, 0, 0), [Errno 10061] Connect call failed ('127.0.0.1', 6379) connecting to localhost:6379.", "location": {"file": "D:\\dex\\backend\\app\\middleware\\rate_limiting.py", "line": 167, "function": "connect"}}
{"timestamp": "2025-08-27T10:12:28.472365Z", "level": "ERROR", "trace_id": "febd3214-e33a-458f-9c8d-6c4c93ee11cb", "module": "main", "message": "Failed to initialize Redis rate limiter", "location": {"file": "D:\\dex\\backend\\main.py", "line": 445, "function": "setup_enhanced_rate_limiting"}}
{"timestamp": "2025-08-27T10:23:10.863587Z", "level": "ERROR", "trace_id": "8925f954-53a5-42c4-b388-67eade8dd7ab", "module": "app.middleware.rate_limiting", "message": "Failed to connect to Redis: Error Multiple exceptions: [Errno 10061] Connect call failed ('::1', 6379, 0, 0), [Errno 10061] Connect call failed ('127.0.0.1', 6379) connecting to localhost:6379.", "location": {"file": "D:\\dex\\backend\\app\\middleware\\rate_limiting.py", "line": 167, "function": "connect"}}
{"timestamp": "2025-08-27T10:23:10.863587Z", "level": "ERROR", "trace_id": "8925f954-53a5-42c4-b388-67eade8dd7ab", "module": "main", "message": "Failed to initialize Redis rate limiter", "location": {"file": "D:\\dex\\backend\\main.py", "line": 445, "function": "setup_enhanced_rate_limiting"}}
{"timestamp": "2025-08-27T10:23:34.732667Z", "level": "ERROR", "trace_id": "d858844f-d611-4a19-8372-446b6b5402f5", "module": "app.middleware.rate_limiting", "message": "Failed to connect to Redis: Error Multiple exceptions: [Errno 10061] Connect call failed ('::1', 6379, 0, 0), [Errno 10061] Connect call failed ('127.0.0.1', 6379) connecting to localhost:6379.", "location": {"file": "D:\\dex\\backend\\app\\middleware\\rate_limiting.py", "line": 167, "function": "connect"}}
{"timestamp": "2025-08-27T10:23:34.733175Z", "level": "ERROR", "trace_id": "d858844f-d611-4a19-8372-446b6b5402f5", "module": "main", "message": "Failed to initialize Redis rate limiter", "location": {"file": "D:\\dex\\backend\\main.py", "line": 445, "function": "setup_enhanced_rate_limiting"}}
{"timestamp": "2025-08-27T10:31:05.309115Z", "level": "ERROR", "trace_id": "5c96e0b6-a3f9-45c4-940a-12bee2595932", "module": "app.middleware.rate_limiting", "message": "Failed to connect to Redis: Error Multiple exceptions: [Errno 10061] Connect call failed ('::1', 6379, 0, 0), [Errno 10061] Connect call failed ('127.0.0.1', 6379) connecting to localhost:6379.", "location": {"file": "D:\\dex\\backend\\app\\middleware\\rate_limiting.py", "line": 167, "function": "connect"}}
{"timestamp": "2025-08-27T10:31:05.309115Z", "level": "ERROR", "trace_id": "5c96e0b6-a3f9-45c4-940a-12bee2595932", "module": "main", "message": "Failed to initialize Redis rate limiter", "location": {"file": "D:\\dex\\backend\\main.py", "line": 445, "function": "setup_enhanced_rate_limiting"}}
{"timestamp": "2025-08-27T10:31:37.142214Z", "level": "ERROR", "trace_id": "64919b7c-5b85-4294-98b4-c491e9a72857", "module": "app.middleware.rate_limiting", "message": "Failed to connect to Redis: Error Multiple exceptions: [Errno 10061] Connect call failed ('::1', 6379, 0, 0), [Errno 10061] Connect call failed ('127.0.0.1', 6379) connecting to localhost:6379.", "location": {"file": "D:\\dex\\backend\\app\\middleware\\rate_limiting.py", "line": 167, "function": "connect"}}
{"timestamp": "2025-08-27T10:31:37.142214Z", "level": "ERROR", "trace_id": "64919b7c-5b85-4294-98b4-c491e9a72857", "module": "main", "message": "Failed to initialize Redis rate limiter", "location": {"file": "D:\\dex\\backend\\main.py", "line": 445, "function": "setup_enhanced_rate_limiting"}}
{"timestamp": "2025-08-27T10:37:38.231596Z", "level": "ERROR", "trace_id": "5a22560f-bb18-4432-bbbe-04112cc0283f", "module": "app.middleware.rate_limiting", "message": "Failed to connect to Redis: Error Multiple exceptions: [Errno 10061] Connect call failed ('::1', 6379, 0, 0), [Errno 10061] Connect call failed ('127.0.0.1', 6379) connecting to localhost:6379.", "location": {"file": "D:\\dex\\backend\\app\\middleware\\rate_limiting.py", "line": 167, "function": "connect"}}
{"timestamp": "2025-08-27T10:37:38.232102Z", "level": "ERROR", "trace_id": "5a22560f-bb18-4432-bbbe-04112cc0283f", "module": "main", "message": "Failed to initialize Redis rate limiter", "location": {"file": "D:\\dex\\backend\\main.py", "line": 445, "function": "setup_enhanced_rate_limiting"}}
{"timestamp": "2025-08-27T10:39:01.464229Z", "level": "ERROR", "trace_id": "6345e054-3756-409e-8287-6dfc1961d875", "module": "app.middleware.rate_limiting", "message": "Failed to connect to Redis: Error Multiple exceptions: [Errno 10061] Connect call failed ('::1', 6379, 0, 0), [Errno 10061] Connect call failed ('127.0.0.1', 6379) connecting to localhost:6379.", "location": {"file": "D:\\dex\\backend\\app\\middleware\\rate_limiting.py", "line": 167, "function": "connect"}}
{"timestamp": "2025-08-27T10:39:01.464229Z", "level": "ERROR", "trace_id": "6345e054-3756-409e-8287-6dfc1961d875", "module": "main", "message": "Failed to initialize Redis rate limiter", "location": {"file": "D:\\dex\\backend\\main.py", "line": 445, "function": "setup_enhanced_rate_limiting"}}
{"timestamp": "2025-08-27T12:08:06.817870Z", "level": "ERROR", "trace_id": "049eb21a-7a57-4f83-97db-7c85be0fa283", "module": "app.middleware.rate_limiting", "message": "Failed to connect to Redis: Error Multiple exceptions: [Errno 10061] Connect call failed ('::1', 6379, 0, 0), [Errno 10061] Connect call failed ('127.0.0.1', 6379) connecting to localhost:6379.", "location": {"file": "D:\\dex\\backend\\app\\middleware\\rate_limiting.py", "line": 167, "function": "connect"}}
{"timestamp": "2025-08-27T12:08:06.819441Z", "level": "ERROR", "trace_id": "049eb21a-7a57-4f83-97db-7c85be0fa283", "module": "main", "message": "Failed to initialize Redis rate limiter", "location": {"file": "D:\\dex\\backend\\main.py", "line": 445, "function": "setup_enhanced_rate_limiting"}}
{"timestamp": "2025-08-27T12:09:03.238114Z", "level": "ERROR", "trace_id": "8dab411c-e0e0-4e2f-97f2-fce90300deae", "module": "app.middleware.rate_limiting", "message": "Failed to connect to Redis: Error Multiple exceptions: [Errno 10061] Connect call failed ('::1', 6379, 0, 0), [Errno 10061] Connect call failed ('127.0.0.1', 6379) connecting to localhost:6379.", "location": {"file": "D:\\dex\\backend\\app\\middleware\\rate_limiting.py", "line": 167, "function": "connect"}}
{"timestamp": "2025-08-27T12:09:03.238114Z", "level": "ERROR", "trace_id": "8dab411c-e0e0-4e2f-97f2-fce90300deae", "module": "main", "message": "Failed to initialize Redis rate limiter", "location": {"file": "D:\\dex\\backend\\main.py", "line": 445, "function": "setup_enhanced_rate_limiting"}}
{"timestamp": "2025-08-27T12:11:18.542350Z", "level": "ERROR", "trace_id": "086f4ae3-3b07-4a8e-b1bc-9d5318b2f548", "module": "app.middleware.rate_limiting", "message": "Failed to connect to Redis: Error Multiple exceptions: [Errno 10061] Connect call failed ('::1', 6379, 0, 0), [Errno 10061] Connect call failed ('127.0.0.1', 6379) connecting to localhost:6379.", "location": {"file": "D:\\dex\\backend\\app\\middleware\\rate_limiting.py", "line": 167, "function": "connect"}}
{"timestamp": "2025-08-27T12:11:18.542857Z", "level": "ERROR", "trace_id": "086f4ae3-3b07-4a8e-b1bc-9d5318b2f548", "module": "main", "message": "Failed to initialize Redis rate limiter", "location": {"file": "D:\\dex\\backend\\main.py", "line": 445, "function": "setup_enhanced_rate_limiting"}}
{"timestamp": "2025-08-27T12:12:03.632292Z", "level": "ERROR", "trace_id": "8015f46d-d713-4b52-8ab0-8956348b899d", "module": "app.middleware.rate_limiting", "message": "Failed to connect to Redis: Error Multiple exceptions: [Errno 10061] Connect call failed ('::1', 6379, 0, 0), [Errno 10061] Connect call failed ('127.0.0.1', 6379) connecting to localhost:6379.", "location": {"file": "D:\\dex\\backend\\app\\middleware\\rate_limiting.py", "line": 167, "function": "connect"}}
{"timestamp": "2025-08-27T12:12:03.632292Z", "level": "ERROR", "trace_id": "8015f46d-d713-4b52-8ab0-8956348b899d", "module": "main", "message": "Failed to initialize Redis rate limiter", "location": {"file": "D:\\dex\\backend\\main.py", "line": 445, "function": "setup_enhanced_rate_limiting"}}
{"timestamp": "2025-08-27T12:12:10.771588Z", "level": "ERROR", "trace_id": "122e0015-6c91-45c5-9d28-9ad07169e15e", "module": "app.middleware.rate_limiting", "message": "Failed to connect to Redis: Error Multiple exceptions: [Errno 10061] Connect call failed ('::1', 6379, 0, 0), [Errno 10061] Connect call failed ('127.0.0.1', 6379) connecting to localhost:6379.", "location": {"file": "D:\\dex\\backend\\app\\middleware\\rate_limiting.py", "line": 167, "function": "connect"}}
{"timestamp": "2025-08-27T12:12:10.771588Z", "level": "ERROR", "trace_id": "122e0015-6c91-45c5-9d28-9ad07169e15e", "module": "main", "message": "Failed to initialize Redis rate limiter", "location": {"file": "D:\\dex\\backend\\main.py", "line": 445, "function": "setup_enhanced_rate_limiting"}}
{"timestamp": "2025-08-27T12:12:18.803815Z", "level": "ERROR", "trace_id": "5d08fae9-4062-4931-93de-3894bb604103", "module": "app.middleware.rate_limiting", "message": "Failed to connect to Redis: Error Multiple exceptions: [Errno 10061] Connect call failed ('::1', 6379, 0, 0), [Errno 10061] Connect call failed ('127.0.0.1', 6379) connecting to localhost:6379.", "location": {"file": "D:\\dex\\backend\\app\\middleware\\rate_limiting.py", "line": 167, "function": "connect"}}
{"timestamp": "2025-08-27T12:12:18.803815Z", "level": "ERROR", "trace_id": "5d08fae9-4062-4931-93de-3894bb604103", "module": "main", "message": "Failed to initialize Redis rate limiter", "location": {"file": "D:\\dex\\backend\\main.py", "line": 445, "function": "setup_enhanced_rate_limiting"}}
{"timestamp": "2025-08-27T12:12:36.379239Z", "level": "ERROR", "trace_id": "7ae5e5e5-db8a-4745-9bbe-0576e4f99ccc", "module": "app.middleware.rate_limiting", "message": "Failed to connect to Redis: Error Multiple exceptions: [Errno 10061] Connect call failed ('::1', 6379, 0, 0), [Errno 10061] Connect call failed ('127.0.0.1', 6379) connecting to localhost:6379.", "location": {"file": "D:\\dex\\backend\\app\\middleware\\rate_limiting.py", "line": 167, "function": "connect"}}
{"timestamp": "2025-08-27T12:12:36.379746Z", "level": "ERROR", "trace_id": "7ae5e5e5-db8a-4745-9bbe-0576e4f99ccc", "module": "main", "message": "Failed to initialize Redis rate limiter", "location": {"file": "D:\\dex\\backend\\main.py", "line": 445, "function": "setup_enhanced_rate_limiting"}}
{"timestamp": "2025-08-27T12:14:57.758069Z", "level": "ERROR", "trace_id": "00540705-317b-4fc1-80dc-0eea220a1c80", "module": "app.middleware.rate_limiting", "message": "Failed to connect to Redis: Error Multiple exceptions: [Errno 10061] Connect call failed ('::1', 6379, 0, 0), [Errno 10061] Connect call failed ('127.0.0.1', 6379) connecting to localhost:6379.", "location": {"file": "D:\\dex\\backend\\app\\middleware\\rate_limiting.py", "line": 167, "function": "connect"}}
{"timestamp": "2025-08-27T12:14:57.759135Z", "level": "ERROR", "trace_id": "00540705-317b-4fc1-80dc-0eea220a1c80", "module": "main", "message": "Failed to initialize Redis rate limiter", "location": {"file": "D:\\dex\\backend\\main.py", "line": 445, "function": "setup_enhanced_rate_limiting"}}
{"timestamp": "2025-08-27T13:09:17.123151Z", "level": "ERROR", "trace_id": "13db4153-4b5f-4c00-a726-f4e80ef81262", "module": "app.middleware.rate_limiting", "message": "Failed to connect to Redis: Error Multiple exceptions: [Errno 10061] Connect call failed ('::1', 6379, 0, 0), [Errno 10061] Connect call failed ('127.0.0.1', 6379) connecting to localhost:6379.", "location": {"file": "D:\\dex\\backend\\app\\middleware\\rate_limiting.py", "line": 167, "function": "connect"}}
{"timestamp": "2025-08-27T13:09:17.123151Z", "level": "ERROR", "trace_id": "13db4153-4b5f-4c00-a726-f4e80ef81262", "module": "main", "message": "Failed to initialize Redis rate limiter", "location": {"file": "D:\\dex\\backend\\main.py", "line": 445, "function": "setup_enhanced_rate_limiting"}}
{"timestamp": "2025-08-27T13:09:33.688731Z", "level": "ERROR", "trace_id": "31bc7a10-a813-4299-9cfa-57fa6ecf1eef", "module": "app.middleware.rate_limiting", "message": "Failed to connect to Redis: Error Multiple exceptions: [Errno 10061] Connect call failed ('::1', 6379, 0, 0), [Errno 10061] Connect call failed ('127.0.0.1', 6379) connecting to localhost:6379.", "location": {"file": "D:\\dex\\backend\\app\\middleware\\rate_limiting.py", "line": 167, "function": "connect"}}
{"timestamp": "2025-08-27T13:09:33.688731Z", "level": "ERROR", "trace_id": "31bc7a10-a813-4299-9cfa-57fa6ecf1eef", "module": "main", "message": "Failed to initialize Redis rate limiter", "location": {"file": "D:\\dex\\backend\\main.py", "line": 445, "function": "setup_enhanced_rate_limiting"}}
{"timestamp": "2025-08-27T13:09:47.729606Z", "level": "ERROR", "trace_id": "8e10fdfa-d6e2-4517-ac13-3e711d5275b8", "module": "app.middleware.rate_limiting", "message": "Failed to connect to Redis: Error Multiple exceptions: [Errno 10061] Connect call failed ('::1', 6379, 0, 0), [Errno 10061] Connect call failed ('127.0.0.1', 6379) connecting to localhost:6379.", "location": {"file": "D:\\dex\\backend\\app\\middleware\\rate_limiting.py", "line": 167, "function": "connect"}}
{"timestamp": "2025-08-27T13:09:47.729606Z", "level": "ERROR", "trace_id": "8e10fdfa-d6e2-4517-ac13-3e711d5275b8", "module": "main", "message": "Failed to initialize Redis rate limiter", "location": {"file": "D:\\dex\\backend\\main.py", "line": 445, "function": "setup_enhanced_rate_limiting"}}
{"timestamp": "2025-08-27T13:09:54.787095Z", "level": "ERROR", "trace_id": "0f582afe-059d-4a21-bb80-aa24e694e787", "module": "app.middleware.rate_limiting", "message": "Failed to connect to Redis: Error Multiple exceptions: [Errno 10061] Connect call failed ('::1', 6379, 0, 0), [Errno 10061] Connect call failed ('127.0.0.1', 6379) connecting to localhost:6379.", "location": {"file": "D:\\dex\\backend\\app\\middleware\\rate_limiting.py", "line": 167, "function": "connect"}}
{"timestamp": "2025-08-27T13:09:54.788127Z", "level": "ERROR", "trace_id": "0f582afe-059d-4a21-bb80-aa24e694e787", "module": "main", "message": "Failed to initialize Redis rate limiter", "location": {"file": "D:\\dex\\backend\\main.py", "line": 445, "function": "setup_enhanced_rate_limiting"}}
{"timestamp": "2025-08-27T13:10:01.908834Z", "level": "ERROR", "trace_id": "8dbdd01f-04c8-44fd-a533-5f91802e4dc4", "module": "app.middleware.rate_limiting", "message": "Failed to connect to Redis: Error Multiple exceptions: [Errno 10061] Connect call failed ('::1', 6379, 0, 0), [Errno 10061] Connect call failed ('127.0.0.1', 6379) connecting to localhost:6379.", "location": {"file": "D:\\dex\\backend\\app\\middleware\\rate_limiting.py", "line": 167, "function": "connect"}}
{"timestamp": "2025-08-27T13:10:01.908834Z", "level": "ERROR", "trace_id": "8dbdd01f-04c8-44fd-a533-5f91802e4dc4", "module": "main", "message": "Failed to initialize Redis rate limiter", "location": {"file": "D:\\dex\\backend\\main.py", "line": 445, "function": "setup_enhanced_rate_limiting"}}
{"timestamp": "2025-08-27T13:10:08.975036Z", "level": "ERROR", "trace_id": "4fa6e286-b643-4dc5-a1f7-50321d17bddc", "module": "app.middleware.rate_limiting", "message": "Failed to connect to Redis: Error Multiple exceptions: [Errno 10061] Connect call failed ('::1', 6379, 0, 0), [Errno 10061] Connect call failed ('127.0.0.1', 6379) connecting to localhost:6379.", "location": {"file": "D:\\dex\\backend\\app\\middleware\\rate_limiting.py", "line": 167, "function": "connect"}}
{"timestamp": "2025-08-27T13:10:08.976142Z", "level": "ERROR", "trace_id": "4fa6e286-b643-4dc5-a1f7-50321d17bddc", "module": "main", "message": "Failed to initialize Redis rate limiter", "location": {"file": "D:\\dex\\backend\\main.py", "line": 445, "function": "setup_enhanced_rate_limiting"}}
{"timestamp": "2025-08-27T13:27:57.204616Z", "level": "ERROR", "trace_id": "52132947-82db-408e-8bff-a84788e63d3e", "module": "app.middleware.rate_limiting", "message": "Failed to connect to Redis: Error Multiple exceptions: [Errno 10061] Connect call failed ('::1', 6379, 0, 0), [Errno 10061] Connect call failed ('127.0.0.1', 6379) connecting to localhost:6379.", "location": {"file": "D:\\dex\\backend\\app\\middleware\\rate_limiting.py", "line": 167, "function": "connect"}}
{"timestamp": "2025-08-27T13:27:57.204616Z", "level": "ERROR", "trace_id": "52132947-82db-408e-8bff-a84788e63d3e", "module": "main", "message": "Failed to initialize Redis rate limiter", "location": {"file": "D:\\dex\\backend\\main.py", "line": 445, "function": "setup_enhanced_rate_limiting"}}
{"timestamp": "2025-08-27T13:28:04.181921Z", "level": "ERROR", "trace_id": "4862cf6d-9a16-4078-9dc5-364d83de56d6", "module": "app.middleware.rate_limiting", "message": "Failed to connect to Redis: Error Multiple exceptions: [Errno 10061] Connect call failed ('::1', 6379, 0, 0), [Errno 10061] Connect call failed ('127.0.0.1', 6379) connecting to localhost:6379.", "location": {"file": "D:\\dex\\backend\\app\\middleware\\rate_limiting.py", "line": 167, "function": "connect"}}
{"timestamp": "2025-08-27T13:28:04.181921Z", "level": "ERROR", "trace_id": "4862cf6d-9a16-4078-9dc5-364d83de56d6", "module": "main", "message": "Failed to initialize Redis rate limiter", "location": {"file": "D:\\dex\\backend\\main.py", "line": 445, "function": "setup_enhanced_rate_limiting"}}
{"timestamp": "2025-08-27T13:36:07.766417Z", "level": "ERROR", "trace_id": "d317c176-d2b7-43f6-8ffc-b501b7eb3e51", "module": "app.middleware.rate_limiting", "message": "Failed to connect to Redis: Error Multiple exceptions: [Errno 10061] Connect call failed ('::1', 6379, 0, 0), [Errno 10061] Connect call failed ('127.0.0.1', 6379) connecting to localhost:6379.", "location": {"file": "D:\\dex\\backend\\app\\middleware\\rate_limiting.py", "line": 167, "function": "connect"}}
{"timestamp": "2025-08-27T13:36:07.766953Z", "level": "ERROR", "trace_id": "d317c176-d2b7-43f6-8ffc-b501b7eb3e51", "module": "main", "message": "Failed to initialize Redis rate limiter", "location": {"file": "D:\\dex\\backend\\main.py", "line": 445, "function": "setup_enhanced_rate_limiting"}}
{"timestamp": "2025-08-27T13:37:04.022388Z", "level": "ERROR", "trace_id": "b832cd47-b0e0-4666-8a94-596cc70d4008", "module": "app.middleware.rate_limiting", "message": "Failed to connect to Redis: Error Multiple exceptions: [Errno 10061] Connect call failed ('::1', 6379, 0, 0), [Errno 10061] Connect call failed ('127.0.0.1', 6379) connecting to localhost:6379.", "location": {"file": "D:\\dex\\backend\\app\\middleware\\rate_limiting.py", "line": 167, "function": "connect"}}
{"timestamp": "2025-08-27T13:37:04.023334Z", "level": "ERROR", "trace_id": "b832cd47-b0e0-4666-8a94-596cc70d4008", "module": "main", "message": "Failed to initialize Redis rate limiter", "location": {"file": "D:\\dex\\backend\\main.py", "line": 445, "function": "setup_enhanced_rate_limiting"}}
{"timestamp": "2025-08-27T14:07:49.376294Z", "level": "ERROR", "trace_id": "5bd07dc2-81ed-44ce-8741-97a0808a6c71", "module": "app.middleware.rate_limiting", "message": "Failed to connect to Redis: Error Multiple exceptions: [Errno 10061] Connect call failed ('::1', 6379, 0, 0), [Errno 10061] Connect call failed ('127.0.0.1', 6379) connecting to localhost:6379.", "location": {"file": "D:\\dex\\backend\\app\\middleware\\rate_limiting.py", "line": 167, "function": "connect"}}
{"timestamp": "2025-08-27T14:07:49.376294Z", "level": "ERROR", "trace_id": "5bd07dc2-81ed-44ce-8741-97a0808a6c71", "module": "main", "message": "Failed to initialize Redis rate limiter", "location": {"file": "D:\\dex\\backend\\main.py", "line": 445, "function": "setup_enhanced_rate_limiting"}}
{"timestamp": "2025-08-27T14:08:13.290950Z", "level": "ERROR", "trace_id": "d042151c-541a-4ad0-aa05-9da838b6deb5", "module": "app.middleware.rate_limiting", "message": "Failed to connect to Redis: Error Multiple exceptions: [Errno 10061] Connect call failed ('::1', 6379, 0, 0), [Errno 10061] Connect call failed ('127.0.0.1', 6379) connecting to localhost:6379.", "location": {"file": "D:\\dex\\backend\\app\\middleware\\rate_limiting.py", "line": 167, "function": "connect"}}
{"timestamp": "2025-08-27T14:08:13.290950Z", "level": "ERROR", "trace_id": "d042151c-541a-4ad0-aa05-9da838b6deb5", "module": "main", "message": "Failed to initialize Redis rate limiter", "location": {"file": "D:\\dex\\backend\\main.py", "line": 445, "function": "setup_enhanced_rate_limiting"}}
{"timestamp": "2025-08-27T14:08:20.260695Z", "level": "ERROR", "trace_id": "41434827-88ee-459f-a417-9a11cc77346f", "module": "app.middleware.rate_limiting", "message": "Failed to connect to Redis: Error Multiple exceptions: [Errno 10061] Connect call failed ('::1', 6379, 0, 0), [Errno 10061] Connect call failed ('127.0.0.1', 6379) connecting to localhost:6379.", "location": {"file": "D:\\dex\\backend\\app\\middleware\\rate_limiting.py", "line": 167, "function": "connect"}}
{"timestamp": "2025-08-27T14:08:20.260695Z", "level": "ERROR", "trace_id": "41434827-88ee-459f-a417-9a11cc77346f", "module": "main", "message": "Failed to initialize Redis rate limiter", "location": {"file": "D:\\dex\\backend\\main.py", "line": 445, "function": "setup_enhanced_rate_limiting"}}
{"timestamp": "2025-08-27T14:20:08.389003Z", "level": "ERROR", "trace_id": "e60a11f5-fa86-467f-bb7d-2f6262c54e26", "module": "app.middleware.rate_limiting", "message": "Failed to connect to Redis: Error Multiple exceptions: [Errno 10061] Connect call failed ('::1', 6379, 0, 0), [Errno 10061] Connect call failed ('127.0.0.1', 6379) connecting to localhost:6379.", "location": {"file": "D:\\dex\\backend\\app\\middleware\\rate_limiting.py", "line": 167, "function": "connect"}}
{"timestamp": "2025-08-27T14:20:08.389003Z", "level": "ERROR", "trace_id": "e60a11f5-fa86-467f-bb7d-2f6262c54e26", "module": "main", "message": "Failed to initialize Redis rate limiter", "location": {"file": "D:\\dex\\backend\\main.py", "line": 445, "function": "setup_enhanced_rate_limiting"}}
{"timestamp": "2025-08-27T14:20:09.446725Z", "level": "ERROR", "trace_id": "e60a11f5-fa86-467f-bb7d-2f6262c54e26", "module": "app.discovery.event_processor", "message": "Failed to initialize Market Intelligence: \"Attempt to overwrite 'module' in LogRecord\"", "location": {"file": "D:\\dex\\backend\\app\\discovery\\event_processor.py", "line": 131, "function": "__init__"}}
{"timestamp": "2025-08-27T14:20:09.447612Z", "level": "ERROR", "trace_id": "e60a11f5-fa86-467f-bb7d-2f6262c54e26", "module": "app.ws.intelligence_hub", "message": "Failed to start Intelligence WebSocket hub: \"Attempt to overwrite 'module' in LogRecord\"", "location": {"file": "D:\\dex\\backend\\app\\ws\\intelligence_hub.py", "line": 94, "function": "start_hub"}}
{"timestamp": "2025-08-27T14:20:09.448370Z", "level": "ERROR", "trace_id": "e60a11f5-fa86-467f-bb7d-2f6262c54e26", "module": "main", "message": "Intelligence hub initialization failed: \"Attempt to overwrite 'module' in LogRecord\"", "location": {"file": "D:\\dex\\backend\\main.py", "line": 618, "function": "lifespan"}}
{"timestamp": "2025-08-27T14:32:29.376894Z", "level": "ERROR", "trace_id": "c73b1b46-ceb5-4c7b-be2a-b6c1b102fb68", "module": "app.discovery.event_processor", "message": "Failed to initialize Market Intelligence: \"Attempt to overwrite 'module' in LogRecord\"", "location": {"file": "D:\\dex\\backend\\app\\discovery\\event_processor.py", "line": 131, "function": "__init__"}}
{"timestamp": "2025-08-27T14:32:33.680776Z", "level": "ERROR", "trace_id": "c73b1b46-ceb5-4c7b-be2a-b6c1b102fb68", "module": "app.middleware.rate_limiting", "message": "Failed to connect to Redis: Error Multiple exceptions: [Errno 10061] Connect call failed ('::1', 6379, 0, 0), [Errno 10061] Connect call failed ('127.0.0.1', 6379) connecting to localhost:6379.", "location": {"file": "D:\\dex\\backend\\app\\middleware\\rate_limiting.py", "line": 167, "function": "connect"}}
{"timestamp": "2025-08-27T14:32:33.680776Z", "level": "ERROR", "trace_id": "c73b1b46-ceb5-4c7b-be2a-b6c1b102fb68", "module": "main", "message": "Failed to initialize Redis rate limiter", "location": {"file": "D:\\dex\\backend\\main.py", "line": 462, "function": "setup_enhanced_rate_limiting"}}
{"timestamp": "2025-08-27T14:32:34.109057Z", "level": "ERROR", "trace_id": "c73b1b46-ceb5-4c7b-be2a-b6c1b102fb68", "module": "app.ws.intelligence_hub", "message": "Failed to start Intelligence WebSocket hub: \"Attempt to overwrite 'module' in LogRecord\"", "location": {"file": "D:\\dex\\backend\\app\\ws\\intelligence_hub.py", "line": 94, "function": "start_hub"}}
{"timestamp": "2025-08-27T14:32:34.110073Z", "level": "ERROR", "trace_id": "c73b1b46-ceb5-4c7b-be2a-b6c1b102fb68", "module": "main", "message": "Intelligence hub initialization failed: \"Attempt to overwrite 'module' in LogRecord\"", "location": {"file": "D:\\dex\\backend\\main.py", "line": 634, "function": "lifespan"}}
{"timestamp": "2025-08-27T14:41:07.812906Z", "level": "ERROR", "trace_id": "ba2a079c-06e7-4807-a193-98c2e5c9523f", "module": "app.discovery.event_processor", "message": "Failed to initialize Market Intelligence: \"Attempt to overwrite 'module' in LogRecord\"", "location": {"file": "D:\\dex\\backend\\app\\discovery\\event_processor.py", "line": 131, "function": "__init__"}}
{"timestamp": "2025-08-27T14:41:12.103092Z", "level": "ERROR", "trace_id": "ba2a079c-06e7-4807-a193-98c2e5c9523f", "module": "app.middleware.rate_limiting", "message": "Failed to connect to Redis: Error Multiple exceptions: [Errno 10061] Connect call failed ('::1', 6379, 0, 0), [Errno 10061] Connect call failed ('127.0.0.1', 6379) connecting to localhost:6379.", "location": {"file": "D:\\dex\\backend\\app\\middleware\\rate_limiting.py", "line": 167, "function": "connect"}}
{"timestamp": "2025-08-27T14:41:12.103092Z", "level": "ERROR", "trace_id": "ba2a079c-06e7-4807-a193-98c2e5c9523f", "module": "main", "message": "Failed to initialize Redis rate limiter", "location": {"file": "D:\\dex\\backend\\main.py", "line": 462, "function": "setup_enhanced_rate_limiting"}}
{"timestamp": "2025-08-27T14:41:12.531334Z", "level": "ERROR", "trace_id": "ba2a079c-06e7-4807-a193-98c2e5c9523f", "module": "app.ws.intelligence_hub", "message": "Failed to start Intelligence WebSocket hub: \"Attempt to overwrite 'module' in LogRecord\"", "location": {"file": "D:\\dex\\backend\\app\\ws\\intelligence_hub.py", "line": 94, "function": "start_hub"}}
{"timestamp": "2025-08-27T14:41:12.531851Z", "level": "ERROR", "trace_id": "ba2a079c-06e7-4807-a193-98c2e5c9523f", "module": "main", "message": "Intelligence hub initialization failed: \"Attempt to overwrite 'module' in LogRecord\"", "location": {"file": "D:\\dex\\backend\\main.py", "line": 634, "function": "lifespan"}}
{"timestamp": "2025-08-27T14:41:20.268266Z", "level": "ERROR", "trace_id": "7da36363-8156-4343-8f83-18a850202337", "module": "app.discovery.event_processor", "message": "Failed to initialize Market Intelligence: \"Attempt to overwrite 'module' in LogRecord\"", "location": {"file": "D:\\dex\\backend\\app\\discovery\\event_processor.py", "line": 131, "function": "__init__"}}
{"timestamp": "2025-08-27T14:41:24.584125Z", "level": "ERROR", "trace_id": "7da36363-8156-4343-8f83-18a850202337", "module": "app.middleware.rate_limiting", "message": "Failed to connect to Redis: Error Multiple exceptions: [Errno 10061] Connect call failed ('::1', 6379, 0, 0), [Errno 10061] Connect call failed ('127.0.0.1', 6379) connecting to localhost:6379.", "location": {"file": "D:\\dex\\backend\\app\\middleware\\rate_limiting.py", "line": 167, "function": "connect"}}
{"timestamp": "2025-08-27T14:41:24.584709Z", "level": "ERROR", "trace_id": "7da36363-8156-4343-8f83-18a850202337", "module": "main", "message": "Failed to initialize Redis rate limiter", "location": {"file": "D:\\dex\\backend\\main.py", "line": 462, "function": "setup_enhanced_rate_limiting"}}
{"timestamp": "2025-08-27T14:41:25.009495Z", "level": "ERROR", "trace_id": "7da36363-8156-4343-8f83-18a850202337", "module": "app.ws.intelligence_hub", "message": "Failed to start Intelligence WebSocket hub: \"Attempt to overwrite 'module' in LogRecord\"", "location": {"file": "D:\\dex\\backend\\app\\ws\\intelligence_hub.py", "line": 94, "function": "start_hub"}}
{"timestamp": "2025-08-27T14:41:25.010533Z", "level": "ERROR", "trace_id": "7da36363-8156-4343-8f83-18a850202337", "module": "main", "message": "Intelligence hub initialization failed: \"Attempt to overwrite 'module' in LogRecord\"", "location": {"file": "D:\\dex\\backend\\main.py", "line": 634, "function": "lifespan"}}
{"timestamp": "2025-08-27T14:41:28.087891Z", "level": "ERROR", "trace_id": "625f0db8-d698-45a3-8593-1de88fa49172", "module": "app.discovery.event_processor", "message": "Failed to initialize Market Intelligence: \"Attempt to overwrite 'module' in LogRecord\"", "location": {"file": "D:\\dex\\backend\\app\\discovery\\event_processor.py", "line": 131, "function": "__init__"}}
{"timestamp": "2025-08-27T14:41:32.356536Z", "level": "ERROR", "trace_id": "625f0db8-d698-45a3-8593-1de88fa49172", "module": "app.middleware.rate_limiting", "message": "Failed to connect to Redis: Error Multiple exceptions: [Errno 10061] Connect call failed ('::1', 6379, 0, 0), [Errno 10061] Connect call failed ('127.0.0.1', 6379) connecting to localhost:6379.", "location": {"file": "D:\\dex\\backend\\app\\middleware\\rate_limiting.py", "line": 167, "function": "connect"}}
{"timestamp": "2025-08-27T14:41:32.356536Z", "level": "ERROR", "trace_id": "625f0db8-d698-45a3-8593-1de88fa49172", "module": "main", "message": "Failed to initialize Redis rate limiter", "location": {"file": "D:\\dex\\backend\\main.py", "line": 462, "function": "setup_enhanced_rate_limiting"}}
{"timestamp": "2025-08-27T14:41:32.779935Z", "level": "ERROR", "trace_id": "625f0db8-d698-45a3-8593-1de88fa49172", "module": "app.ws.intelligence_hub", "message": "Failed to start Intelligence WebSocket hub: \"Attempt to overwrite 'module' in LogRecord\"", "location": {"file": "D:\\dex\\backend\\app\\ws\\intelligence_hub.py", "line": 94, "function": "start_hub"}}
{"timestamp": "2025-08-27T14:41:32.779935Z", "level": "ERROR", "trace_id": "625f0db8-d698-45a3-8593-1de88fa49172", "module": "main", "message": "Intelligence hub initialization failed: \"Attempt to overwrite 'module' in LogRecord\"", "location": {"file": "D:\\dex\\backend\\main.py", "line": 634, "function": "lifespan"}}
{"timestamp": "2025-08-27T14:42:12.665512Z", "level": "ERROR", "trace_id": "005cadcc-a1ca-4e4f-ba47-41db58f003ac", "module": "app.discovery.event_processor", "message": "Failed to initialize Market Intelligence: \"Attempt to overwrite 'module' in LogRecord\"", "location": {"file": "D:\\dex\\backend\\app\\discovery\\event_processor.py", "line": 131, "function": "__init__"}}
{"timestamp": "2025-08-27T14:42:16.945260Z", "level": "ERROR", "trace_id": "005cadcc-a1ca-4e4f-ba47-41db58f003ac", "module": "app.middleware.rate_limiting", "message": "Redis connection failed: Error Multiple exceptions: [Errno 10061] Connect call failed ('::1', 6379, 0, 0), [Errno 10061] Connect call failed ('127.0.0.1', 6379) connecting to localhost:6379.", "location": {"file": "D:\\dex\\backend\\app\\middleware\\rate_limiting.py", "line": 303, "function": "connect"}}
{"timestamp": "2025-08-27T14:42:16.945260Z", "level": "ERROR", "trace_id": "005cadcc-a1ca-4e4f-ba47-41db58f003ac", "module": "main", "message": "Failed to initialize Redis rate limiter", "location": {"file": "D:\\dex\\backend\\main.py", "line": 462, "function": "setup_enhanced_rate_limiting"}}
{"timestamp": "2025-08-27T14:42:17.369432Z", "level": "ERROR", "trace_id": "005cadcc-a1ca-4e4f-ba47-41db58f003ac", "module": "app.ws.intelligence_hub", "message": "Failed to start Intelligence WebSocket hub: \"Attempt to overwrite 'module' in LogRecord\"", "location": {"file": "D:\\dex\\backend\\app\\ws\\intelligence_hub.py", "line": 94, "function": "start_hub"}}
{"timestamp": "2025-08-27T14:42:17.369432Z", "level": "ERROR", "trace_id": "005cadcc-a1ca-4e4f-ba47-41db58f003ac", "module": "main", "message": "Intelligence hub initialization failed: \"Attempt to overwrite 'module' in LogRecord\"", "location": {"file": "D:\\dex\\backend\\main.py", "line": 634, "function": "lifespan"}}
{"timestamp": "2025-08-27T14:42:24.762690Z", "level": "ERROR", "trace_id": "a675a907-55eb-40af-80e6-42fd1c5ce136", "module": "app.discovery.event_processor", "message": "Failed to initialize Market Intelligence: \"Attempt to overwrite 'module' in LogRecord\"", "location": {"file": "D:\\dex\\backend\\app\\discovery\\event_processor.py", "line": 131, "function": "__init__"}}
{"timestamp": "2025-08-27T14:42:29.046172Z", "level": "ERROR", "trace_id": "a675a907-55eb-40af-80e6-42fd1c5ce136", "module": "app.middleware.rate_limiting", "message": "Redis connection failed: Error Multiple exceptions: [Errno 10061] Connect call failed ('::1', 6379, 0, 0), [Errno 10061] Connect call failed ('127.0.0.1', 6379) connecting to localhost:6379.", "location": {"file": "D:\\dex\\backend\\app\\middleware\\rate_limiting.py", "line": 303, "function": "connect"}}
{"timestamp": "2025-08-27T14:42:29.046172Z", "level": "ERROR", "trace_id": "a675a907-55eb-40af-80e6-42fd1c5ce136", "module": "main", "message": "Failed to initialize Redis rate limiter", "location": {"file": "D:\\dex\\backend\\main.py", "line": 462, "function": "setup_enhanced_rate_limiting"}}
{"timestamp": "2025-08-27T14:42:29.478909Z", "level": "ERROR", "trace_id": "a675a907-55eb-40af-80e6-42fd1c5ce136", "module": "app.ws.intelligence_hub", "message": "Failed to start Intelligence WebSocket hub: \"Attempt to overwrite 'module' in LogRecord\"", "location": {"file": "D:\\dex\\backend\\app\\ws\\intelligence_hub.py", "line": 94, "function": "start_hub"}}
{"timestamp": "2025-08-27T14:42:29.479869Z", "level": "ERROR", "trace_id": "a675a907-55eb-40af-80e6-42fd1c5ce136", "module": "main", "message": "Intelligence hub initialization failed: \"Attempt to overwrite 'module' in LogRecord\"", "location": {"file": "D:\\dex\\backend\\main.py", "line": 634, "function": "lifespan"}}
{"timestamp": "2025-08-27T14:43:40.203618Z", "level": "ERROR", "trace_id": "55f54dae-968a-42fb-abfa-f7eac58c4d3d", "module": "app.discovery.event_processor", "message": "Failed to initialize Market Intelligence: \"Attempt to overwrite 'module' in LogRecord\"", "location": {"file": "D:\\dex\\backend\\app\\discovery\\event_processor.py", "line": 131, "function": "__init__"}}
{"timestamp": "2025-08-27T14:43:44.464199Z", "level": "ERROR", "trace_id": "55f54dae-968a-42fb-abfa-f7eac58c4d3d", "module": "app.middleware.rate_limiting", "message": "Redis connection failed: Error Multiple exceptions: [Errno 10061] Connect call failed ('::1', 6379, 0, 0), [Errno 10061] Connect call failed ('127.0.0.1', 6379) connecting to localhost:6379.", "location": {"file": "D:\\dex\\backend\\app\\middleware\\rate_limiting.py", "line": 303, "function": "connect"}}
{"timestamp": "2025-08-27T14:43:44.465196Z", "level": "ERROR", "trace_id": "55f54dae-968a-42fb-abfa-f7eac58c4d3d", "module": "main", "message": "Failed to initialize Redis rate limiter", "location": {"file": "D:\\dex\\backend\\main.py", "line": 462, "function": "setup_enhanced_rate_limiting"}}
{"timestamp": "2025-08-27T14:43:44.896265Z", "level": "ERROR", "trace_id": "55f54dae-968a-42fb-abfa-f7eac58c4d3d", "module": "app.ws.intelligence_hub", "message": "Failed to start Intelligence WebSocket hub: \"Attempt to overwrite 'module' in LogRecord\"", "location": {"file": "D:\\dex\\backend\\app\\ws\\intelligence_hub.py", "line": 94, "function": "start_hub"}}
{"timestamp": "2025-08-27T14:43:44.896265Z", "level": "ERROR", "trace_id": "55f54dae-968a-42fb-abfa-f7eac58c4d3d", "module": "main", "message": "Intelligence hub initialization failed: \"Attempt to overwrite 'module' in LogRecord\"", "location": {"file": "D:\\dex\\backend\\main.py", "line": 634, "function": "lifespan"}}
{"timestamp": "2025-08-27T14:43:51.921603Z", "level": "ERROR", "trace_id": "3147c261-62bc-4fb0-8d1f-ae9d1c51b3c9", "module": "app.discovery.event_processor", "message": "Failed to initialize Market Intelligence: \"Attempt to overwrite 'module' in LogRecord\"", "location": {"file": "D:\\dex\\backend\\app\\discovery\\event_processor.py", "line": 131, "function": "__init__"}}
{"timestamp": "2025-08-27T14:43:56.200005Z", "level": "ERROR", "trace_id": "3147c261-62bc-4fb0-8d1f-ae9d1c51b3c9", "module": "app.middleware.rate_limiting", "message": "Redis connection failed: Error Multiple exceptions: [Errno 10061] Connect call failed ('::1', 6379, 0, 0), [Errno 10061] Connect call failed ('127.0.0.1', 6379) connecting to localhost:6379.", "location": {"file": "D:\\dex\\backend\\app\\middleware\\rate_limiting.py", "line": 303, "function": "connect"}}
{"timestamp": "2025-08-27T14:43:56.200005Z", "level": "ERROR", "trace_id": "3147c261-62bc-4fb0-8d1f-ae9d1c51b3c9", "module": "main", "message": "Failed to initialize Redis rate limiter", "location": {"file": "D:\\dex\\backend\\main.py", "line": 462, "function": "setup_enhanced_rate_limiting"}}
{"timestamp": "2025-08-27T14:43:56.633087Z", "level": "ERROR", "trace_id": "3147c261-62bc-4fb0-8d1f-ae9d1c51b3c9", "module": "app.ws.intelligence_hub", "message": "Failed to start Intelligence WebSocket hub: \"Attempt to overwrite 'module' in LogRecord\"", "location": {"file": "D:\\dex\\backend\\app\\ws\\intelligence_hub.py", "line": 94, "function": "start_hub"}}
{"timestamp": "2025-08-27T14:43:56.633087Z", "level": "ERROR", "trace_id": "3147c261-62bc-4fb0-8d1f-ae9d1c51b3c9", "module": "main", "message": "Intelligence hub initialization failed: \"Attempt to overwrite 'module' in LogRecord\"", "location": {"file": "D:\\dex\\backend\\main.py", "line": 634, "function": "lifespan"}}
{"timestamp": "2025-08-27T14:44:22.599184Z", "level": "ERROR", "trace_id": "313494df-287c-4485-b73c-4be0d2d9fd65", "module": "app.discovery.event_processor", "message": "Failed to initialize Market Intelligence: \"Attempt to overwrite 'module' in LogRecord\"", "location": {"file": "D:\\dex\\backend\\app\\discovery\\event_processor.py", "line": 131, "function": "__init__"}}
{"timestamp": "2025-08-27T14:44:26.849429Z", "level": "ERROR", "trace_id": "313494df-287c-4485-b73c-4be0d2d9fd65", "module": "app.middleware.rate_limiting", "message": "Redis connection failed: Error Multiple exceptions: [Errno 10061] Connect call failed ('::1', 6379, 0, 0), [Errno 10061] Connect call failed ('127.0.0.1', 6379) connecting to localhost:6379.", "location": {"file": "D:\\dex\\backend\\app\\middleware\\rate_limiting.py", "line": 303, "function": "connect"}}
{"timestamp": "2025-08-27T14:44:26.849429Z", "level": "ERROR", "trace_id": "313494df-287c-4485-b73c-4be0d2d9fd65", "module": "main", "message": "Failed to initialize Redis rate limiter", "location": {"file": "D:\\dex\\backend\\main.py", "line": 462, "function": "setup_enhanced_rate_limiting"}}
{"timestamp": "2025-08-27T14:44:27.277980Z", "level": "ERROR", "trace_id": "313494df-287c-4485-b73c-4be0d2d9fd65", "module": "app.ws.intelligence_hub", "message": "Failed to start Intelligence WebSocket hub: \"Attempt to overwrite 'module' in LogRecord\"", "location": {"file": "D:\\dex\\backend\\app\\ws\\intelligence_hub.py", "line": 94, "function": "start_hub"}}
{"timestamp": "2025-08-27T14:44:27.277980Z", "level": "ERROR", "trace_id": "313494df-287c-4485-b73c-4be0d2d9fd65", "module": "main", "message": "Intelligence hub initialization failed: \"Attempt to overwrite 'module' in LogRecord\"", "location": {"file": "D:\\dex\\backend\\main.py", "line": 634, "function": "lifespan"}}
{"timestamp": "2025-08-27T14:44:43.138229Z", "level": "ERROR", "trace_id": "ec4827f6-65f9-4170-a4d3-72a1783577e9", "module": "app.discovery.event_processor", "message": "Failed to initialize Market Intelligence: \"Attempt to overwrite 'module' in LogRecord\"", "location": {"file": "D:\\dex\\backend\\app\\discovery\\event_processor.py", "line": 131, "function": "__init__"}}
{"timestamp": "2025-08-27T14:44:47.395361Z", "level": "ERROR", "trace_id": "ec4827f6-65f9-4170-a4d3-72a1783577e9", "module": "app.middleware.rate_limiting", "message": "Redis connection failed: Error Multiple exceptions: [Errno 10061] Connect call failed ('::1', 6379, 0, 0), [Errno 10061] Connect call failed ('127.0.0.1', 6379) connecting to localhost:6379.", "location": {"file": "D:\\dex\\backend\\app\\middleware\\rate_limiting.py", "line": 303, "function": "connect"}}
{"timestamp": "2025-08-27T14:44:47.395361Z", "level": "ERROR", "trace_id": "ec4827f6-65f9-4170-a4d3-72a1783577e9", "module": "main", "message": "Failed to initialize Redis rate limiter", "location": {"file": "D:\\dex\\backend\\main.py", "line": 462, "function": "setup_enhanced_rate_limiting"}}
{"timestamp": "2025-08-27T14:44:47.818378Z", "level": "ERROR", "trace_id": "ec4827f6-65f9-4170-a4d3-72a1783577e9", "module": "app.ws.intelligence_hub", "message": "Failed to start Intelligence WebSocket hub: \"Attempt to overwrite 'module' in LogRecord\"", "location": {"file": "D:\\dex\\backend\\app\\ws\\intelligence_hub.py", "line": 94, "function": "start_hub"}}
{"timestamp": "2025-08-27T14:44:47.818378Z", "level": "ERROR", "trace_id": "ec4827f6-65f9-4170-a4d3-72a1783577e9", "module": "main", "message": "Intelligence hub initialization failed: \"Attempt to overwrite 'module' in LogRecord\"", "location": {"file": "D:\\dex\\backend\\main.py", "line": 634, "function": "lifespan"}}
{"timestamp": "2025-08-27T14:45:15.784242Z", "level": "ERROR", "trace_id": "eb4d60cd-3e7e-4985-928b-01eddbb24c44", "module": "app.discovery.event_processor", "message": "Failed to initialize Market Intelligence: \"Attempt to overwrite 'module' in LogRecord\"", "location": {"file": "D:\\dex\\backend\\app\\discovery\\event_processor.py", "line": 131, "function": "__init__"}}
{"timestamp": "2025-08-27T14:45:20.059836Z", "level": "ERROR", "trace_id": "eb4d60cd-3e7e-4985-928b-01eddbb24c44", "module": "app.middleware.rate_limiting", "message": "Redis connection failed: Error Multiple exceptions: [Errno 10061] Connect call failed ('::1', 6379, 0, 0), [Errno 10061] Connect call failed ('127.0.0.1', 6379) connecting to localhost:6379.", "location": {"file": "D:\\dex\\backend\\app\\middleware\\rate_limiting.py", "line": 303, "function": "connect"}}
{"timestamp": "2025-08-27T14:45:20.059836Z", "level": "ERROR", "trace_id": "eb4d60cd-3e7e-4985-928b-01eddbb24c44", "module": "main", "message": "Failed to initialize Redis rate limiter", "location": {"file": "D:\\dex\\backend\\main.py", "line": 462, "function": "setup_enhanced_rate_limiting"}}
{"timestamp": "2025-08-27T14:45:20.511855Z", "level": "ERROR", "trace_id": "eb4d60cd-3e7e-4985-928b-01eddbb24c44", "module": "app.ws.intelligence_hub", "message": "Failed to start Intelligence WebSocket hub: \"Attempt to overwrite 'module' in LogRecord\"", "location": {"file": "D:\\dex\\backend\\app\\ws\\intelligence_hub.py", "line": 94, "function": "start_hub"}}
{"timestamp": "2025-08-27T14:45:20.511855Z", "level": "ERROR", "trace_id": "eb4d60cd-3e7e-4985-928b-01eddbb24c44", "module": "main", "message": "Intelligence hub initialization failed: \"Attempt to overwrite 'module' in LogRecord\"", "location": {"file": "D:\\dex\\backend\\main.py", "line": 634, "function": "lifespan"}}
{"timestamp": "2025-08-27T14:45:37.815253Z", "level": "ERROR", "trace_id": "a8098bed-9584-4b19-a7f0-b4f98e5abba3", "module": "app.discovery.event_processor", "message": "Failed to initialize Market Intelligence: \"Attempt to overwrite 'module' in LogRecord\"", "location": {"file": "D:\\dex\\backend\\app\\discovery\\event_processor.py", "line": 131, "function": "__init__"}}
{"timestamp": "2025-08-27T14:45:42.077149Z", "level": "ERROR", "trace_id": "a8098bed-9584-4b19-a7f0-b4f98e5abba3", "module": "app.middleware.rate_limiting", "message": "Redis connection failed: Error Multiple exceptions: [Errno 10061] Connect call failed ('::1', 6379, 0, 0), [Errno 10061] Connect call failed ('127.0.0.1', 6379) connecting to localhost:6379.", "location": {"file": "D:\\dex\\backend\\app\\middleware\\rate_limiting.py", "line": 303, "function": "connect"}}
{"timestamp": "2025-08-27T14:45:42.077149Z", "level": "ERROR", "trace_id": "a8098bed-9584-4b19-a7f0-b4f98e5abba3", "module": "main", "message": "Failed to initialize Redis rate limiter", "location": {"file": "D:\\dex\\backend\\main.py", "line": 462, "function": "setup_enhanced_rate_limiting"}}
{"timestamp": "2025-08-27T14:45:42.508719Z", "level": "ERROR", "trace_id": "a8098bed-9584-4b19-a7f0-b4f98e5abba3", "module": "app.ws.intelligence_hub", "message": "Failed to start Intelligence WebSocket hub: \"Attempt to overwrite 'module' in LogRecord\"", "location": {"file": "D:\\dex\\backend\\app\\ws\\intelligence_hub.py", "line": 94, "function": "start_hub"}}
{"timestamp": "2025-08-27T14:45:42.508719Z", "level": "ERROR", "trace_id": "a8098bed-9584-4b19-a7f0-b4f98e5abba3", "module": "main", "message": "Intelligence hub initialization failed: \"Attempt to overwrite 'module' in LogRecord\"", "location": {"file": "D:\\dex\\backend\\main.py", "line": 634, "function": "lifespan"}}
{"timestamp": "2025-08-27T14:46:03.121442Z", "level": "ERROR", "trace_id": "4c0d6604-531a-4d3f-a14b-5ee9a3d31f7f", "module": "app.discovery.event_processor", "message": "Failed to initialize Market Intelligence: \"Attempt to overwrite 'module' in LogRecord\"", "location": {"file": "D:\\dex\\backend\\app\\discovery\\event_processor.py", "line": 131, "function": "__init__"}}
{"timestamp": "2025-08-27T14:46:07.398334Z", "level": "ERROR", "trace_id": "4c0d6604-531a-4d3f-a14b-5ee9a3d31f7f", "module": "app.middleware.rate_limiting", "message": "Redis connection failed: Error Multiple exceptions: [Errno 10061] Connect call failed ('::1', 6379, 0, 0), [Errno 10061] Connect call failed ('127.0.0.1', 6379) connecting to localhost:6379.", "location": {"file": "D:\\dex\\backend\\app\\middleware\\rate_limiting.py", "line": 303, "function": "connect"}}
{"timestamp": "2025-08-27T14:46:07.398406Z", "level": "ERROR", "trace_id": "4c0d6604-531a-4d3f-a14b-5ee9a3d31f7f", "module": "main", "message": "Failed to initialize Redis rate limiter", "location": {"file": "D:\\dex\\backend\\main.py", "line": 462, "function": "setup_enhanced_rate_limiting"}}
{"timestamp": "2025-08-27T14:46:07.835688Z", "level": "ERROR", "trace_id": "4c0d6604-531a-4d3f-a14b-5ee9a3d31f7f", "module": "app.ws.intelligence_hub", "message": "Failed to start Intelligence WebSocket hub: \"Attempt to overwrite 'module' in LogRecord\"", "location": {"file": "D:\\dex\\backend\\app\\ws\\intelligence_hub.py", "line": 94, "function": "start_hub"}}
{"timestamp": "2025-08-27T14:46:07.835688Z", "level": "ERROR", "trace_id": "4c0d6604-531a-4d3f-a14b-5ee9a3d31f7f", "module": "main", "message": "Intelligence hub initialization failed: \"Attempt to overwrite 'module' in LogRecord\"", "location": {"file": "D:\\dex\\backend\\main.py", "line": 634, "function": "lifespan"}}
{"timestamp": "2025-08-27T14:46:13.914943Z", "level": "ERROR", "trace_id": "429d8ab4-5b94-46de-8520-6f7b558cd7a5", "module": "app.discovery.event_processor", "message": "Failed to initialize Market Intelligence: \"Attempt to overwrite 'module' in LogRecord\"", "location": {"file": "D:\\dex\\backend\\app\\discovery\\event_processor.py", "line": 131, "function": "__init__"}}
{"timestamp": "2025-08-27T14:46:18.214614Z", "level": "ERROR", "trace_id": "429d8ab4-5b94-46de-8520-6f7b558cd7a5", "module": "app.middleware.rate_limiting", "message": "Redis connection failed: Error Multiple exceptions: [Errno 10061] Connect call failed ('::1', 6379, 0, 0), [Errno 10061] Connect call failed ('127.0.0.1', 6379) connecting to localhost:6379.", "location": {"file": "D:\\dex\\backend\\app\\middleware\\rate_limiting.py", "line": 303, "function": "connect"}}
{"timestamp": "2025-08-27T14:46:18.214614Z", "level": "ERROR", "trace_id": "429d8ab4-5b94-46de-8520-6f7b558cd7a5", "module": "main", "message": "Failed to initialize Redis rate limiter", "location": {"file": "D:\\dex\\backend\\main.py", "line": 462, "function": "setup_enhanced_rate_limiting"}}
{"timestamp": "2025-08-27T14:46:18.634888Z", "level": "ERROR", "trace_id": "429d8ab4-5b94-46de-8520-6f7b558cd7a5", "module": "app.ws.intelligence_hub", "message": "Failed to start Intelligence WebSocket hub: \"Attempt to overwrite 'module' in LogRecord\"", "location": {"file": "D:\\dex\\backend\\app\\ws\\intelligence_hub.py", "line": 94, "function": "start_hub"}}
{"timestamp": "2025-08-27T14:46:18.634888Z", "level": "ERROR", "trace_id": "429d8ab4-5b94-46de-8520-6f7b558cd7a5", "module": "main", "message": "Intelligence hub initialization failed: \"Attempt to overwrite 'module' in LogRecord\"", "location": {"file": "D:\\dex\\backend\\main.py", "line": 634, "function": "lifespan"}}
{"timestamp": "2025-08-27T14:46:43.073137Z", "level": "ERROR", "trace_id": "b66f8cee-07db-4deb-8779-0904cc4594cf", "module": "app.discovery.event_processor", "message": "Failed to initialize Market Intelligence: \"Attempt to overwrite 'module' in LogRecord\"", "location": {"file": "D:\\dex\\backend\\app\\discovery\\event_processor.py", "line": 131, "function": "__init__"}}
{"timestamp": "2025-08-27T14:46:47.120418Z", "level": "ERROR", "trace_id": "b66f8cee-07db-4deb-8779-0904cc4594cf", "module": "app.middleware.rate_limiting", "message": "Redis connection failed: Error Multiple exceptions: [Errno 10061] Connect call failed ('::1', 6379, 0, 0), [Errno 10061] Connect call failed ('127.0.0.1', 6379) connecting to localhost:6379.", "location": {"file": "D:\\dex\\backend\\app\\middleware\\rate_limiting.py", "line": 303, "function": "connect"}}
{"timestamp": "2025-08-27T14:46:47.120418Z", "level": "ERROR", "trace_id": "b66f8cee-07db-4deb-8779-0904cc4594cf", "module": "app.core.lifespan", "message": "Failed to initialize Redis rate limiter", "location": {"file": "D:\\dex\\backend\\app\\core\\lifespan.py", "line": 94, "function": "setup_enhanced_rate_limiting"}}
{"timestamp": "2025-08-27T14:46:47.535104Z", "level": "ERROR", "trace_id": "b66f8cee-07db-4deb-8779-0904cc4594cf", "module": "app.ws.intelligence_hub", "message": "Failed to start Intelligence WebSocket hub: \"Attempt to overwrite 'module' in LogRecord\"", "location": {"file": "D:\\dex\\backend\\app\\ws\\intelligence_hub.py", "line": 94, "function": "start_hub"}}
{"timestamp": "2025-08-27T14:46:47.535104Z", "level": "ERROR", "trace_id": "b66f8cee-07db-4deb-8779-0904cc4594cf", "module": "app.core.lifespan", "message": "Intelligence hub initialization failed: \"Attempt to overwrite 'module' in LogRecord\"", "location": {"file": "D:\\dex\\backend\\app\\core\\lifespan.py", "line": 276, "function": "lifespan"}}
{"timestamp": "2025-08-27T14:47:00.391428Z", "level": "ERROR", "trace_id": "2f33911a-20bf-4748-a5d9-412d1d6633b7", "module": "app.discovery.event_processor", "message": "Failed to initialize Market Intelligence: \"Attempt to overwrite 'module' in LogRecord\"", "location": {"file": "D:\\dex\\backend\\app\\discovery\\event_processor.py", "line": 131, "function": "__init__"}}
{"timestamp": "2025-08-27T14:47:04.453807Z", "level": "ERROR", "trace_id": "2f33911a-20bf-4748-a5d9-412d1d6633b7", "module": "app.middleware.rate_limiting", "message": "Redis connection failed: Error Multiple exceptions: [Errno 10061] Connect call failed ('::1', 6379, 0, 0), [Errno 10061] Connect call failed ('127.0.0.1', 6379) connecting to localhost:6379.", "location": {"file": "D:\\dex\\backend\\app\\middleware\\rate_limiting.py", "line": 303, "function": "connect"}}
{"timestamp": "2025-08-27T14:47:04.454815Z", "level": "ERROR", "trace_id": "2f33911a-20bf-4748-a5d9-412d1d6633b7", "module": "app.core.lifespan", "message": "Failed to initialize Redis rate limiter", "location": {"file": "D:\\dex\\backend\\app\\core\\lifespan.py", "line": 94, "function": "setup_enhanced_rate_limiting"}}
{"timestamp": "2025-08-27T14:47:04.875727Z", "level": "ERROR", "trace_id": "2f33911a-20bf-4748-a5d9-412d1d6633b7", "module": "app.ws.intelligence_hub", "message": "Failed to start Intelligence WebSocket hub: \"Attempt to overwrite 'module' in LogRecord\"", "location": {"file": "D:\\dex\\backend\\app\\ws\\intelligence_hub.py", "line": 94, "function": "start_hub"}}
{"timestamp": "2025-08-27T14:47:04.876821Z", "level": "ERROR", "trace_id": "2f33911a-20bf-4748-a5d9-412d1d6633b7", "module": "app.core.lifespan", "message": "Intelligence hub initialization failed: \"Attempt to overwrite 'module' in LogRecord\"", "location": {"file": "D:\\dex\\backend\\app\\core\\lifespan.py", "line": 276, "function": "lifespan"}}
{"timestamp": "2025-08-27T14:54:11.234900Z", "level": "ERROR", "trace_id": "2f33911a-20bf-4748-a5d9-412d1d6633b7", "module": "app.middleware.rate_limiting", "message": "Redis connection failed: Error Multiple exceptions: [Errno 10061] Connect call failed ('::1', 6379, 0, 0), [Errno 10061] Connect call failed ('127.0.0.1', 6379) connecting to localhost:6379.", "location": {"file": "D:\\dex\\backend\\app\\middleware\\rate_limiting.py", "line": 303, "function": "connect"}}
{"timestamp": "2025-08-27T14:54:11.239949Z", "level": "ERROR", "trace_id": "2f33911a-20bf-4748-a5d9-412d1d6633b7", "module": "app.api.wallet", "message": "Logging failed: \"Attempt to overwrite 'message' in LogRecord\". Original message: Wallet connection check", "location": {"file": "D:\\dex\\backend\\app\\api\\wallet.py", "line": 198, "function": "log_wallet_operation"}}
{"timestamp": "2025-08-27T14:54:14.127235Z", "level": "ERROR", "trace_id": "2f33911a-20bf-4748-a5d9-412d1d6633b7", "module": "app.middleware.rate_limiting", "message": "Redis connection failed: Error Multiple exceptions: [Errno 10061] Connect call failed ('::1', 6379, 0, 0), [Errno 10061] Connect call failed ('127.0.0.1', 6379) connecting to localhost:6379.", "location": {"file": "D:\\dex\\backend\\app\\middleware\\rate_limiting.py", "line": 303, "function": "connect"}}
{"timestamp": "2025-08-27T14:54:15.288146Z", "level": "ERROR", "trace_id": "2f33911a-20bf-4748-a5d9-412d1d6633b7", "module": "app.middleware.rate_limiting", "message": "Redis connection failed: Error Multiple exceptions: [Errno 10061] Connect call failed ('::1', 6379, 0, 0), [Errno 10061] Connect call failed ('127.0.0.1', 6379) connecting to localhost:6379.", "location": {"file": "D:\\dex\\backend\\app\\middleware\\rate_limiting.py", "line": 303, "function": "connect"}}
{"timestamp": "2025-08-27T14:54:15.289155Z", "level": "ERROR", "trace_id": "2f33911a-20bf-4748-a5d9-412d1d6633b7", "module": "app.middleware.rate_limiting", "message": "Redis connection failed: Error Multiple exceptions: [Errno 10061] Connect call failed ('::1', 6379, 0, 0), [Errno 10061] Connect call failed ('127.0.0.1', 6379) connecting to localhost:6379.", "location": {"file": "D:\\dex\\backend\\app\\middleware\\rate_limiting.py", "line": 303, "function": "connect"}}
{"timestamp": "2025-08-27T14:54:15.289155Z", "level": "ERROR", "trace_id": "2f33911a-20bf-4748-a5d9-412d1d6633b7", "module": "app.api.wallet", "message": "Logging failed: \"Attempt to overwrite 'message' in LogRecord\". Original message: Wallet connection check", "location": {"file": "D:\\dex\\backend\\app\\api\\wallet.py", "line": 198, "function": "log_wallet_operation"}}
{"timestamp": "2025-08-27T14:54:15.290317Z", "level": "ERROR", "trace_id": "2f33911a-20bf-4748-a5d9-412d1d6633b7", "module": "app.api.wallet", "message": "Logging failed: \"Attempt to overwrite 'message' in LogRecord\". Original message: Wallet connection check", "location": {"file": "D:\\dex\\backend\\app\\api\\wallet.py", "line": 198, "function": "log_wallet_operation"}}
{"timestamp": "2025-08-27T14:54:18.210603Z", "level": "ERROR", "trace_id": "2f33911a-20bf-4748-a5d9-412d1d6633b7", "module": "app.middleware.rate_limiting", "message": "Redis connection failed: Error Multiple exceptions: [Errno 10061] Connect call failed ('::1', 6379, 0, 0), [Errno 10061] Connect call failed ('127.0.0.1', 6379) connecting to localhost:6379.", "location": {"file": "D:\\dex\\backend\\app\\middleware\\rate_limiting.py", "line": 303, "function": "connect"}}
{"timestamp": "2025-08-27T14:54:19.200555Z", "level": "ERROR", "trace_id": "2f33911a-20bf-4748-a5d9-412d1d6633b7", "module": "app.middleware.rate_limiting", "message": "Redis connection failed: Error Multiple exceptions: [Errno 10061] Connect call failed ('::1', 6379, 0, 0), [Errno 10061] Connect call failed ('127.0.0.1', 6379) connecting to localhost:6379.", "location": {"file": "D:\\dex\\backend\\app\\middleware\\rate_limiting.py", "line": 303, "function": "connect"}}
{"timestamp": "2025-08-27T14:54:19.369176Z", "level": "ERROR", "trace_id": "2f33911a-20bf-4748-a5d9-412d1d6633b7", "module": "app.middleware.rate_limiting", "message": "Redis connection failed: Error Multiple exceptions: [Errno 10061] Connect call failed ('::1', 6379, 0, 0), [Errno 10061] Connect call failed ('127.0.0.1', 6379) connecting to localhost:6379.", "location": {"file": "D:\\dex\\backend\\app\\middleware\\rate_limiting.py", "line": 303, "function": "connect"}}
{"timestamp": "2025-08-27T14:54:19.370328Z", "level": "ERROR", "trace_id": "2f33911a-20bf-4748-a5d9-412d1d6633b7", "module": "app.api.wallet", "message": "Logging failed: \"Attempt to overwrite 'message' in LogRecord\". Original message: Wallet connection check", "location": {"file": "D:\\dex\\backend\\app\\api\\wallet.py", "line": 198, "function": "log_wallet_operation"}}
{"timestamp": "2025-08-27T14:54:23.270607Z", "level": "ERROR", "trace_id": "2f33911a-20bf-4748-a5d9-412d1d6633b7", "module": "app.middleware.rate_limiting", "message": "Redis connection failed: Error Multiple exceptions: [Errno 10061] Connect call failed ('::1', 6379, 0, 0), [Errno 10061] Connect call failed ('127.0.0.1', 6379) connecting to localhost:6379.", "location": {"file": "D:\\dex\\backend\\app\\middleware\\rate_limiting.py", "line": 303, "function": "connect"}}
{"timestamp": "2025-08-27T14:54:26.590174Z", "level": "ERROR", "trace_id": "2f33911a-20bf-4748-a5d9-412d1d6633b7", "module": "app.middleware.rate_limiting", "message": "Redis connection failed: Error Multiple exceptions: [Errno 10061] Connect call failed ('::1', 6379, 0, 0), [Errno 10061] Connect call failed ('127.0.0.1', 6379) connecting to localhost:6379.", "location": {"file": "D:\\dex\\backend\\app\\middleware\\rate_limiting.py", "line": 303, "function": "connect"}}
{"timestamp": "2025-08-27T14:54:26.604025Z", "level": "ERROR", "trace_id": "2f33911a-20bf-4748-a5d9-412d1d6633b7", "module": "app.middleware.rate_limiting", "message": "Redis connection failed: Error Multiple exceptions: [Errno 10061] Connect call failed ('::1', 6379, 0, 0), [Errno 10061] Connect call failed ('127.0.0.1', 6379) connecting to localhost:6379.", "location": {"file": "D:\\dex\\backend\\app\\middleware\\rate_limiting.py", "line": 303, "function": "connect"}}
{"timestamp": "2025-08-27T14:54:26.686579Z", "level": "ERROR", "trace_id": "2f33911a-20bf-4748-a5d9-412d1d6633b7", "module": "app.middleware.rate_limiting", "message": "Redis connection failed: Error Multiple exceptions: [Errno 10061] Connect call failed ('::1', 6379, 0, 0), [Errno 10061] Connect call failed ('127.0.0.1', 6379) connecting to localhost:6379.", "location": {"file": "D:\\dex\\backend\\app\\middleware\\rate_limiting.py", "line": 303, "function": "connect"}}
{"timestamp": "2025-08-27T14:54:26.687547Z", "level": "ERROR", "trace_id": "2f33911a-20bf-4748-a5d9-412d1d6633b7", "module": "app.middleware.rate_limiting", "message": "Redis connection failed: Error Multiple exceptions: [Errno 10061] Connect call failed ('::1', 6379, 0, 0), [Errno 10061] Connect call failed ('127.0.0.1', 6379) connecting to localhost:6379.", "location": {"file": "D:\\dex\\backend\\app\\middleware\\rate_limiting.py", "line": 303, "function": "connect"}}
{"timestamp": "2025-08-27T14:54:35.951365Z", "level": "ERROR", "trace_id": "2f33911a-20bf-4748-a5d9-412d1d6633b7", "module": "app.middleware.rate_limiting", "message": "Redis connection failed: Error Multiple exceptions: [Errno 10061] Connect call failed ('::1', 6379, 0, 0), [Errno 10061] Connect call failed ('127.0.0.1', 6379) connecting to localhost:6379.", "location": {"file": "D:\\dex\\backend\\app\\middleware\\rate_limiting.py", "line": 303, "function": "connect"}}
{"timestamp": "2025-08-27T14:54:35.952425Z", "level": "ERROR", "trace_id": "2f33911a-20bf-4748-a5d9-412d1d6633b7", "module": "app.middleware.rate_limiting", "message": "Redis connection failed: Error Multiple exceptions: [Errno 10061] Connect call failed ('::1', 6379, 0, 0), [Errno 10061] Connect call failed ('127.0.0.1', 6379) connecting to localhost:6379.", "location": {"file": "D:\\dex\\backend\\app\\middleware\\rate_limiting.py", "line": 303, "function": "connect"}}
{"timestamp": "2025-08-27T14:54:41.037650Z", "level": "ERROR", "trace_id": "2f33911a-20bf-4748-a5d9-412d1d6633b7", "module": "app.middleware.rate_limiting", "message": "Redis connection failed: Error Multiple exceptions: [Errno 10061] Connect call failed ('::1', 6379, 0, 0), [Errno 10061] Connect call failed ('127.0.0.1', 6379) connecting to localhost:6379.", "location": {"file": "D:\\dex\\backend\\app\\middleware\\rate_limiting.py", "line": 303, "function": "connect"}}
{"timestamp": "2025-08-27T14:54:41.037650Z", "level": "ERROR", "trace_id": "2f33911a-20bf-4748-a5d9-412d1d6633b7", "module": "app.middleware.rate_limiting", "message": "Redis connection failed: Error Multiple exceptions: [Errno 10061] Connect call failed ('::1', 6379, 0, 0), [Errno 10061] Connect call failed ('127.0.0.1', 6379) connecting to localhost:6379.", "location": {"file": "D:\\dex\\backend\\app\\middleware\\rate_limiting.py", "line": 303, "function": "connect"}}
{"timestamp": "2025-08-27T14:54:48.437907Z", "level": "ERROR", "trace_id": "2f33911a-20bf-4748-a5d9-412d1d6633b7", "module": "app.middleware.rate_limiting", "message": "Redis connection failed: Error Multiple exceptions: [Errno 10061] Connect call failed ('::1', 6379, 0, 0), [Errno 10061] Connect call failed ('127.0.0.1', 6379) connecting to localhost:6379.", "location": {"file": "D:\\dex\\backend\\app\\middleware\\rate_limiting.py", "line": 303, "function": "connect"}}
{"timestamp": "2025-08-27T14:54:54.473917Z", "level": "ERROR", "trace_id": "2f33911a-20bf-4748-a5d9-412d1d6633b7", "module": "app.middleware.rate_limiting", "message": "Redis connection failed: Error Multiple exceptions: [Errno 10061] Connect call failed ('::1', 6379, 0, 0), [Errno 10061] Connect call failed ('127.0.0.1', 6379) connecting to localhost:6379.", "location": {"file": "D:\\dex\\backend\\app\\middleware\\rate_limiting.py", "line": 303, "function": "connect"}}
{"timestamp": "2025-08-27T14:54:54.476520Z", "level": "ERROR", "trace_id": "2f33911a-20bf-4748-a5d9-412d1d6633b7", "module": "app.api.wallet", "message": "Logging failed: \"Attempt to overwrite 'message' in LogRecord\". Original message: Wallet registration request received", "location": {"file": "D:\\dex\\backend\\app\\api\\wallet.py", "line": 198, "function": "log_wallet_operation"}}
{"timestamp": "2025-08-27T14:54:54.476520Z", "level": "ERROR", "trace_id": "2f33911a-20bf-4748-a5d9-412d1d6633b7", "module": "app.api.wallet", "message": "Logging failed: \"Attempt to overwrite 'message' in LogRecord\". Original message: Wallet registration completed successfully", "location": {"file": "D:\\dex\\backend\\app\\api\\wallet.py", "line": 198, "function": "log_wallet_operation"}}
{"timestamp": "2025-08-27T14:54:54.497126Z", "level": "ERROR", "trace_id": "2f33911a-20bf-4748-a5d9-412d1d6633b7", "module": "app.middleware.rate_limiting", "message": "Redis connection failed: Error Multiple exceptions: [Errno 10061] Connect call failed ('::1', 6379, 0, 0), [Errno 10061] Connect call failed ('127.0.0.1', 6379) connecting to localhost:6379.", "location": {"file": "D:\\dex\\backend\\app\\middleware\\rate_limiting.py", "line": 303, "function": "connect"}}
{"timestamp": "2025-08-27T14:54:54.587800Z", "level": "ERROR", "trace_id": "2f33911a-20bf-4748-a5d9-412d1d6633b7", "module": "app.api.wallet", "message": "Logging failed: \"Attempt to overwrite 'message' in LogRecord\". Original message: Wallet registration metrics logged", "location": {"file": "D:\\dex\\backend\\app\\api\\wallet.py", "line": 198, "function": "log_wallet_operation"}}
{"timestamp": "2025-08-27T14:55:03.730742Z", "level": "ERROR", "trace_id": "2f33911a-20bf-4748-a5d9-412d1d6633b7", "module": "app.middleware.rate_limiting", "message": "Redis connection failed: Error Multiple exceptions: [Errno 10061] Connect call failed ('::1', 6379, 0, 0), [Errno 10061] Connect call failed ('127.0.0.1', 6379) connecting to localhost:6379.", "location": {"file": "D:\\dex\\backend\\app\\middleware\\rate_limiting.py", "line": 303, "function": "connect"}}
{"timestamp": "2025-08-27T14:55:16.599664Z", "level": "ERROR", "trace_id": "2f33911a-20bf-4748-a5d9-412d1d6633b7", "module": "app.middleware.rate_limiting", "message": "Redis connection failed: Error Multiple exceptions: [Errno 10061] Connect call failed ('::1', 6379, 0, 0), [Errno 10061] Connect call failed ('127.0.0.1', 6379) connecting to localhost:6379.", "location": {"file": "D:\\dex\\backend\\app\\middleware\\rate_limiting.py", "line": 303, "function": "connect"}}
{"timestamp": "2025-08-27T14:55:16.657422Z", "level": "ERROR", "trace_id": "2f33911a-20bf-4748-a5d9-412d1d6633b7", "module": "app.middleware.rate_limiting", "message": "Redis connection failed: Error Multiple exceptions: [Errno 10061] Connect call failed ('::1', 6379, 0, 0), [Errno 10061] Connect call failed ('127.0.0.1', 6379) connecting to localhost:6379.", "location": {"file": "D:\\dex\\backend\\app\\middleware\\rate_limiting.py", "line": 303, "function": "connect"}}
{"timestamp": "2025-08-27T14:55:20.638260Z", "level": "ERROR", "trace_id": "2f33911a-20bf-4748-a5d9-412d1d6633b7", "module": "app.middleware.rate_limiting", "message": "Redis connection failed: Error Multiple exceptions: [Errno 10061] Connect call failed ('::1', 6379, 0, 0), [Errno 10061] Connect call failed ('127.0.0.1', 6379) connecting to localhost:6379.", "location": {"file": "D:\\dex\\backend\\app\\middleware\\rate_limiting.py", "line": 303, "function": "connect"}}
{"timestamp": "2025-08-27T14:55:20.643315Z", "level": "ERROR", "trace_id": "2f33911a-20bf-4748-a5d9-412d1d6633b7", "module": "app.api.wallet", "message": "Logging failed: \"Attempt to overwrite 'message' in LogRecord\". Original message: Wallet connection check", "location": {"file": "D:\\dex\\backend\\app\\api\\wallet.py", "line": 198, "function": "log_wallet_operation"}}
{"timestamp": "2025-08-27T14:55:20.672385Z", "level": "ERROR", "trace_id": "2f33911a-20bf-4748-a5d9-412d1d6633b7", "module": "app.middleware.rate_limiting", "message": "Redis connection failed: Error Multiple exceptions: [Errno 10061] Connect call failed ('::1', 6379, 0, 0), [Errno 10061] Connect call failed ('127.0.0.1', 6379) connecting to localhost:6379.", "location": {"file": "D:\\dex\\backend\\app\\middleware\\rate_limiting.py", "line": 303, "function": "connect"}}
{"timestamp": "2025-08-27T14:55:24.732298Z", "level": "ERROR", "trace_id": "2f33911a-20bf-4748-a5d9-412d1d6633b7", "module": "app.middleware.rate_limiting", "message": "Redis connection failed: Error Multiple exceptions: [Errno 10061] Connect call failed ('::1', 6379, 0, 0), [Errno 10061] Connect call failed ('127.0.0.1', 6379) connecting to localhost:6379.", "location": {"file": "D:\\dex\\backend\\app\\middleware\\rate_limiting.py", "line": 303, "function": "connect"}}
{"timestamp": "2025-08-27T14:55:24.733342Z", "level": "ERROR", "trace_id": "2f33911a-20bf-4748-a5d9-412d1d6633b7", "module": "app.middleware.rate_limiting", "message": "Redis connection failed: Error Multiple exceptions: [Errno 10061] Connect call failed ('::1', 6379, 0, 0), [Errno 10061] Connect call failed ('127.0.0.1', 6379) connecting to localhost:6379.", "location": {"file": "D:\\dex\\backend\\app\\middleware\\rate_limiting.py", "line": 303, "function": "connect"}}
{"timestamp": "2025-08-27T14:55:24.733342Z", "level": "ERROR", "trace_id": "2f33911a-20bf-4748-a5d9-412d1d6633b7", "module": "app.middleware.rate_limiting", "message": "Redis connection failed: Error Multiple exceptions: [Errno 10061] Connect call failed ('::1', 6379, 0, 0), [Errno 10061] Connect call failed ('127.0.0.1', 6379) connecting to localhost:6379.", "location": {"file": "D:\\dex\\backend\\app\\middleware\\rate_limiting.py", "line": 303, "function": "connect"}}
{"timestamp": "2025-08-27T14:55:24.734390Z", "level": "ERROR", "trace_id": "2f33911a-20bf-4748-a5d9-412d1d6633b7", "module": "app.middleware.rate_limiting", "message": "Redis connection failed: Error Multiple exceptions: [Errno 10061] Connect call failed ('::1', 6379, 0, 0), [Errno 10061] Connect call failed ('127.0.0.1', 6379) connecting to localhost:6379.", "location": {"file": "D:\\dex\\backend\\app\\middleware\\rate_limiting.py", "line": 303, "function": "connect"}}
{"timestamp": "2025-08-27T14:55:24.734390Z", "level": "ERROR", "trace_id": "2f33911a-20bf-4748-a5d9-412d1d6633b7", "module": "app.middleware.rate_limiting", "message": "Redis connection failed: Error Multiple exceptions: [Errno 10061] Connect call failed ('::1', 6379, 0, 0), [Errno 10061] Connect call failed ('127.0.0.1', 6379) connecting to localhost:6379.", "location": {"file": "D:\\dex\\backend\\app\\middleware\\rate_limiting.py", "line": 303, "function": "connect"}}
{"timestamp": "2025-08-27T14:55:24.735436Z", "level": "ERROR", "trace_id": "2f33911a-20bf-4748-a5d9-412d1d6633b7", "module": "app.middleware.rate_limiting", "message": "Redis connection failed: Error Multiple exceptions: [Errno 10061] Connect call failed ('::1', 6379, 0, 0), [Errno 10061] Connect call failed ('127.0.0.1', 6379) connecting to localhost:6379.", "location": {"file": "D:\\dex\\backend\\app\\middleware\\rate_limiting.py", "line": 303, "function": "connect"}}
{"timestamp": "2025-08-27T14:55:24.751344Z", "level": "ERROR", "trace_id": "2f33911a-20bf-4748-a5d9-412d1d6633b7", "module": "app.api.wallet", "message": "Logging failed: \"Attempt to overwrite 'message' in LogRecord\". Original message: Wallet connection check", "location": {"file": "D:\\dex\\backend\\app\\api\\wallet.py", "line": 198, "function": "log_wallet_operation"}}
{"timestamp": "2025-08-27T14:55:24.880378Z", "level": "ERROR", "trace_id": "2f33911a-20bf-4748-a5d9-412d1d6633b7", "module": "app.api.ledger", "message": "Database error fetching transactions: (sqlite3.OperationalError) no such column: ledger_entries.execution_mode\n[SQL: SELECT ledger_entries.id, ledger_entries.user_id, ledger_entries.trace_id, ledger_entries.created_at, ledger_entries.chain, ledger_entries.dex, ledger_entries.trade_type, ledger_entries.input_token, ledger_entries.input_token_symbol, ledger_entries.output_token, ledger_entries.output_token_symbol, ledger_entries.input_amount, ledger_entries.output_amount, ledger_entries.price, ledger_entries.price_usd, ledger_entries.tx_hash, ledger_entries.block_number, ledger_entries.gas_used, ledger_entries.gas_price, ledger_entries.transaction_fee, ledger_entries.transaction_fee_usd, ledger_entries.status, ledger_entries.error_message, ledger_entries.wallet_address, ledger_entries.realized_pnl, ledger_entries.realized_pnl_usd, ledger_entries.risk_score, ledger_entries.risk_factors, ledger_entries.tags, ledger_entries.notes, ledger_entries.archived, ledger_entries.archived_at, ledger_entries.execution_mode \nFROM ledger_entries \nWHERE ledger_entries.user_id = ? ORDER BY ledger_entries.created_at DESC\n LIMIT ? OFFSET ?]\n[parameters: (1, 100, 0)]\n(Background on this error at: https://sqlalche.me/e/20/e3q8)", "exception": {"type": "OperationalError", "message": "(sqlite3.OperationalError) no such column: ledger_entries.execution_mode\n[SQL: SELECT ledger_entries.id, ledger_entries.user_id, ledger_entries.trace_id, ledger_entries.created_at, ledger_entries.chain, ledger_entries.dex, ledger_entries.trade_type, ledger_entries.input_token, ledger_entries.input_token_symbol, ledger_entries.output_token, ledger_entries.output_token_symbol, ledger_entries.input_amount, ledger_entries.output_amount, ledger_entries.price, ledger_entries.price_usd, ledger_entries.tx_hash, ledger_entries.block_number, ledger_entries.gas_used, ledger_entries.gas_price, ledger_entries.transaction_fee, ledger_entries.transaction_fee_usd, ledger_entries.status, ledger_entries.error_message, ledger_entries.wallet_address, ledger_entries.realized_pnl, ledger_entries.realized_pnl_usd, ledger_entries.risk_score, ledger_entries.risk_factors, ledger_entries.tags, ledger_entries.notes, ledger_entries.archived, ledger_entries.archived_at, ledger_entries.execution_mode \nFROM ledger_entries \nWHERE ledger_entries.user_id = ? ORDER BY ledger_entries.created_at DESC\n LIMIT ? OFFSET ?]\n[parameters: (1, 100, 0)]\n(Background on this error at: https://sqlalche.me/e/20/e3q8)", "traceback": ["Traceback (most recent call last):\n", "  File \"D:\\dex\\.venv\\Lib\\site-packages\\sqlalchemy\\engine\\base.py\", line 1967, in _exec_single_context\n    self.dialect.do_execute(\n", "  File \"D:\\dex\\.venv\\Lib\\site-packages\\sqlalchemy\\engine\\default.py\", line 951, in do_execute\n    cursor.execute(statement, parameters)\n", "  File \"D:\\dex\\.venv\\Lib\\site-packages\\sqlalchemy\\dialects\\sqlite\\aiosqlite.py\", line 177, in execute\n    self._adapt_connection._handle_exception(error)\n", "  File \"D:\\dex\\.venv\\Lib\\site-packages\\sqlalchemy\\dialects\\sqlite\\aiosqlite.py\", line 337, in _handle_exception\n    raise error\n", "  File \"D:\\dex\\.venv\\Lib\\site-packages\\sqlalchemy\\dialects\\sqlite\\aiosqlite.py\", line 159, in execute\n    self.await_(_cursor.execute(operation, parameters))\n", "  File \"D:\\dex\\.venv\\Lib\\site-packages\\sqlalchemy\\util\\_concurrency_py3k.py\", line 132, in await_only\n    return current.parent.switch(awaitable)  # type: ignore[no-any-return,attr-defined] # noqa: E501\n           ^^^^^^^^^^^^^^^^^^^^^^^^^^^^^^^^\n", "  File \"D:\\dex\\.venv\\Lib\\site-packages\\sqlalchemy\\util\\_concurrency_py3k.py\", line 196, in greenlet_spawn\n    value = await result\n            ^^^^^^^^^^^^\n", "  File \"D:\\dex\\.venv\\Lib\\site-packages\\aiosqlite\\cursor.py\", line 40, in execute\n    await self._execute(self._cursor.execute, sql, parameters)\n", "  File \"D:\\dex\\.venv\\Lib\\site-packages\\aiosqlite\\cursor.py\", line 32, in _execute\n    return await self._conn._execute(fn, *args, **kwargs)\n           ^^^^^^^^^^^^^^^^^^^^^^^^^^^^^^^^^^^^^^^^^^^^^^\n", "  File \"D:\\dex\\.venv\\Lib\\site-packages\\aiosqlite\\core.py\", line 122, in _execute\n    return await future\n           ^^^^^^^^^^^^\n", "  File \"D:\\dex\\.venv\\Lib\\site-packages\\aiosqlite\\core.py\", line 105, in run\n    result = function()\n             ^^^^^^^^^^\n", "sqlite3.OperationalError: no such column: ledger_entries.execution_mode\n", "\nThe above exception was the direct cause of the following exception:\n\n", "Traceback (most recent call last):\n", "  File \"D:\\dex\\backend\\app\\api\\ledger.py\", line 264, in get_transactions\n    ledger_entries = await ledger_repo.get_user_ledger(\n                     ^^^^^^^^^^^^^^^^^^^^^^^^^^^^^^^^^^\n", "  File \"D:\\dex\\backend\\app\\storage\\repositories.py\", line 665, in get_user_ledger\n    result = await self.session.execute(stmt)\n             ^^^^^^^^^^^^^^^^^^^^^^^^^^^^^^^^\n", "  File \"D:\\dex\\.venv\\Lib\\site-packages\\sqlalchemy\\ext\\asyncio\\session.py\", line 463, in execute\n    result = await greenlet_spawn(\n             ^^^^^^^^^^^^^^^^^^^^^\n", "  File \"D:\\dex\\.venv\\Lib\\site-packages\\sqlalchemy\\util\\_concurrency_py3k.py\", line 201, in greenlet_spawn\n    result = context.throw(*sys.exc_info())\n             ^^^^^^^^^^^^^^^^^^^^^^^^^^^^^^\n", "  File \"D:\\dex\\.venv\\Lib\\site-packages\\sqlalchemy\\orm\\session.py\", line 2365, in execute\n    return self._execute_internal(\n           ^^^^^^^^^^^^^^^^^^^^^^^\n", "  File \"D:\\dex\\.venv\\Lib\\site-packages\\sqlalchemy\\orm\\session.py\", line 2251, in _execute_internal\n    result: Result[Any] = compile_state_cls.orm_execute_statement(\n                          ^^^^^^^^^^^^^^^^^^^^^^^^^^^^^^^^^^^^^^^^\n", "  File \"D:\\dex\\.venv\\Lib\\site-packages\\sqlalchemy\\orm\\context.py\", line 306, in orm_execute_statement\n    result = conn.execute(\n             ^^^^^^^^^^^^^\n", "  File \"D:\\dex\\.venv\\Lib\\site-packages\\sqlalchemy\\engine\\base.py\", line 1419, in execute\n    return meth(\n           ^^^^^\n", "  File \"D:\\dex\\.venv\\Lib\\site-packages\\sqlalchemy\\sql\\elements.py\", line 526, in _execute_on_connection\n    return connection._execute_clauseelement(\n           ^^^^^^^^^^^^^^^^^^^^^^^^^^^^^^^^^^\n", "  File \"D:\\dex\\.venv\\Lib\\site-packages\\sqlalchemy\\engine\\base.py\", line 1641, in _execute_clauseelement\n    ret = self._execute_context(\n          ^^^^^^^^^^^^^^^^^^^^^^\n", "  File \"D:\\dex\\.venv\\Lib\\site-packages\\sqlalchemy\\engine\\base.py\", line 1846, in _execute_context\n    return self._exec_single_context(\n           ^^^^^^^^^^^^^^^^^^^^^^^^^^\n", "  File \"D:\\dex\\.venv\\Lib\\site-packages\\sqlalchemy\\engine\\base.py\", line 1986, in _exec_single_context\n    self._handle_dbapi_exception(\n", "  File \"D:\\dex\\.venv\\Lib\\site-packages\\sqlalchemy\\engine\\base.py\", line 2355, in _handle_dbapi_exception\n    raise sqlalchemy_exception.with_traceback(exc_info[2]) from e\n", "  File \"D:\\dex\\.venv\\Lib\\site-packages\\sqlalchemy\\engine\\base.py\", line 1967, in _exec_single_context\n    self.dialect.do_execute(\n", "  File \"D:\\dex\\.venv\\Lib\\site-packages\\sqlalchemy\\engine\\default.py\", line 951, in do_execute\n    cursor.execute(statement, parameters)\n", "  File \"D:\\dex\\.venv\\Lib\\site-packages\\sqlalchemy\\dialects\\sqlite\\aiosqlite.py\", line 177, in execute\n    self._adapt_connection._handle_exception(error)\n", "  File \"D:\\dex\\.venv\\Lib\\site-packages\\sqlalchemy\\dialects\\sqlite\\aiosqlite.py\", line 337, in _handle_exception\n    raise error\n", "  File \"D:\\dex\\.venv\\Lib\\site-packages\\sqlalchemy\\dialects\\sqlite\\aiosqlite.py\", line 159, in execute\n    self.await_(_cursor.execute(operation, parameters))\n", "  File \"D:\\dex\\.venv\\Lib\\site-packages\\sqlalchemy\\util\\_concurrency_py3k.py\", line 132, in await_only\n    return current.parent.switch(awaitable)  # type: ignore[no-any-return,attr-defined] # noqa: E501\n           ^^^^^^^^^^^^^^^^^^^^^^^^^^^^^^^^\n", "  File \"D:\\dex\\.venv\\Lib\\site-packages\\sqlalchemy\\util\\_concurrency_py3k.py\", line 196, in greenlet_spawn\n    value = await result\n            ^^^^^^^^^^^^\n", "  File \"D:\\dex\\.venv\\Lib\\site-packages\\aiosqlite\\cursor.py\", line 40, in execute\n    await self._execute(self._cursor.execute, sql, parameters)\n", "  File \"D:\\dex\\.venv\\Lib\\site-packages\\aiosqlite\\cursor.py\", line 32, in _execute\n    return await self._conn._execute(fn, *args, **kwargs)\n           ^^^^^^^^^^^^^^^^^^^^^^^^^^^^^^^^^^^^^^^^^^^^^^\n", "  File \"D:\\dex\\.venv\\Lib\\site-packages\\aiosqlite\\core.py\", line 122, in _execute\n    return await future\n           ^^^^^^^^^^^^\n", "  File \"D:\\dex\\.venv\\Lib\\site-packages\\aiosqlite\\core.py\", line 105, in run\n    result = function()\n             ^^^^^^^^^^\n", "sqlalchemy.exc.OperationalError: (sqlite3.OperationalError) no such column: ledger_entries.execution_mode\n[SQL: SELECT ledger_entries.id, ledger_entries.user_id, ledger_entries.trace_id, ledger_entries.created_at, ledger_entries.chain, ledger_entries.dex, ledger_entries.trade_type, ledger_entries.input_token, ledger_entries.input_token_symbol, ledger_entries.output_token, ledger_entries.output_token_symbol, ledger_entries.input_amount, ledger_entries.output_amount, ledger_entries.price, ledger_entries.price_usd, ledger_entries.tx_hash, ledger_entries.block_number, ledger_entries.gas_used, ledger_entries.gas_price, ledger_entries.transaction_fee, ledger_entries.transaction_fee_usd, ledger_entries.status, ledger_entries.error_message, ledger_entries.wallet_address, ledger_entries.realized_pnl, ledger_entries.realized_pnl_usd, ledger_entries.risk_score, ledger_entries.risk_factors, ledger_entries.tags, ledger_entries.notes, ledger_entries.archived, ledger_entries.archived_at, ledger_entries.execution_mode \nFROM ledger_entries \nWHERE ledger_entries.user_id = ? ORDER BY ledger_entries.created_at DESC\n LIMIT ? OFFSET ?]\n[parameters: (1, 100, 0)]\n(Background on this error at: https://sqlalche.me/e/20/e3q8)\n"]}, "location": {"file": "D:\\dex\\backend\\app\\api\\ledger.py", "line": 340, "function": "get_transactions"}}
{"timestamp": "2025-08-27T14:55:24.888666Z", "level": "ERROR", "trace_id": "2f33911a-20bf-4748-a5d9-412d1d6633b7", "module": "app.api.ledger", "message": "Database error calculating portfolio summary: (sqlite3.OperationalError) no such column: ledger_entries.execution_mode\n[SQL: SELECT ledger_entries.id, ledger_entries.user_id, ledger_entries.trace_id, ledger_entries.created_at, ledger_entries.chain, ledger_entries.dex, ledger_entries.trade_type, ledger_entries.input_token, ledger_entries.input_token_symbol, ledger_entries.output_token, ledger_entries.output_token_symbol, ledger_entries.input_amount, ledger_entries.output_amount, ledger_entries.price, ledger_entries.price_usd, ledger_entries.tx_hash, ledger_entries.block_number, ledger_entries.gas_used, ledger_entries.gas_price, ledger_entries.transaction_fee, ledger_entries.transaction_fee_usd, ledger_entries.status, ledger_entries.error_message, ledger_entries.wallet_address, ledger_entries.realized_pnl, ledger_entries.realized_pnl_usd, ledger_entries.risk_score, ledger_entries.risk_factors, ledger_entries.tags, ledger_entries.notes, ledger_entries.archived, ledger_entries.archived_at, ledger_entries.execution_mode \nFROM ledger_entries \nWHERE ledger_entries.user_id = ? ORDER BY ledger_entries.created_at DESC\n LIMIT ? OFFSET ?]\n[parameters: (1, 5000, 0)]\n(Background on this error at: https://sqlalche.me/e/20/e3q8)", "exception": {"type": "OperationalError", "message": "(sqlite3.OperationalError) no such column: ledger_entries.execution_mode\n[SQL: SELECT ledger_entries.id, ledger_entries.user_id, ledger_entries.trace_id, ledger_entries.created_at, ledger_entries.chain, ledger_entries.dex, ledger_entries.trade_type, ledger_entries.input_token, ledger_entries.input_token_symbol, ledger_entries.output_token, ledger_entries.output_token_symbol, ledger_entries.input_amount, ledger_entries.output_amount, ledger_entries.price, ledger_entries.price_usd, ledger_entries.tx_hash, ledger_entries.block_number, ledger_entries.gas_used, ledger_entries.gas_price, ledger_entries.transaction_fee, ledger_entries.transaction_fee_usd, ledger_entries.status, ledger_entries.error_message, ledger_entries.wallet_address, ledger_entries.realized_pnl, ledger_entries.realized_pnl_usd, ledger_entries.risk_score, ledger_entries.risk_factors, ledger_entries.tags, ledger_entries.notes, ledger_entries.archived, ledger_entries.archived_at, ledger_entries.execution_mode \nFROM ledger_entries \nWHERE ledger_entries.user_id = ? ORDER BY ledger_entries.created_at DESC\n LIMIT ? OFFSET ?]\n[parameters: (1, 5000, 0)]\n(Background on this error at: https://sqlalche.me/e/20/e3q8)", "traceback": ["Traceback (most recent call last):\n", "  File \"D:\\dex\\.venv\\Lib\\site-packages\\sqlalchemy\\engine\\base.py\", line 1967, in _exec_single_context\n    self.dialect.do_execute(\n", "  File \"D:\\dex\\.venv\\Lib\\site-packages\\sqlalchemy\\engine\\default.py\", line 951, in do_execute\n    cursor.execute(statement, parameters)\n", "  File \"D:\\dex\\.venv\\Lib\\site-packages\\sqlalchemy\\dialects\\sqlite\\aiosqlite.py\", line 177, in execute\n    self._adapt_connection._handle_exception(error)\n", "  File \"D:\\dex\\.venv\\Lib\\site-packages\\sqlalchemy\\dialects\\sqlite\\aiosqlite.py\", line 337, in _handle_exception\n    raise error\n", "  File \"D:\\dex\\.venv\\Lib\\site-packages\\sqlalchemy\\dialects\\sqlite\\aiosqlite.py\", line 159, in execute\n    self.await_(_cursor.execute(operation, parameters))\n", "  File \"D:\\dex\\.venv\\Lib\\site-packages\\sqlalchemy\\util\\_concurrency_py3k.py\", line 132, in await_only\n    return current.parent.switch(awaitable)  # type: ignore[no-any-return,attr-defined] # noqa: E501\n           ^^^^^^^^^^^^^^^^^^^^^^^^^^^^^^^^\n", "  File \"D:\\dex\\.venv\\Lib\\site-packages\\sqlalchemy\\util\\_concurrency_py3k.py\", line 196, in greenlet_spawn\n    value = await result\n            ^^^^^^^^^^^^\n", "  File \"D:\\dex\\.venv\\Lib\\site-packages\\aiosqlite\\cursor.py\", line 40, in execute\n    await self._execute(self._cursor.execute, sql, parameters)\n", "  File \"D:\\dex\\.venv\\Lib\\site-packages\\aiosqlite\\cursor.py\", line 32, in _execute\n    return await self._conn._execute(fn, *args, **kwargs)\n           ^^^^^^^^^^^^^^^^^^^^^^^^^^^^^^^^^^^^^^^^^^^^^^\n", "  File \"D:\\dex\\.venv\\Lib\\site-packages\\aiosqlite\\core.py\", line 122, in _execute\n    return await future\n           ^^^^^^^^^^^^\n", "  File \"D:\\dex\\.venv\\Lib\\site-packages\\aiosqlite\\core.py\", line 105, in run\n    result = function()\n             ^^^^^^^^^^\n", "sqlite3.OperationalError: no such column: ledger_entries.execution_mode\n", "\nThe above exception was the direct cause of the following exception:\n\n", "Traceback (most recent call last):\n", "  File \"D:\\dex\\backend\\app\\api\\ledger.py\", line 410, in get_portfolio_summary\n    ledger_entries = await ledger_repo.get_user_ledger(\n                     ^^^^^^^^^^^^^^^^^^^^^^^^^^^^^^^^^^\n", "  File \"D:\\dex\\backend\\app\\storage\\repositories.py\", line 665, in get_user_ledger\n    result = await self.session.execute(stmt)\n             ^^^^^^^^^^^^^^^^^^^^^^^^^^^^^^^^\n", "  File \"D:\\dex\\.venv\\Lib\\site-packages\\sqlalchemy\\ext\\asyncio\\session.py\", line 463, in execute\n    result = await greenlet_spawn(\n             ^^^^^^^^^^^^^^^^^^^^^\n", "  File \"D:\\dex\\.venv\\Lib\\site-packages\\sqlalchemy\\util\\_concurrency_py3k.py\", line 201, in greenlet_spawn\n    result = context.throw(*sys.exc_info())\n             ^^^^^^^^^^^^^^^^^^^^^^^^^^^^^^\n", "  File \"D:\\dex\\.venv\\Lib\\site-packages\\sqlalchemy\\orm\\session.py\", line 2365, in execute\n    return self._execute_internal(\n           ^^^^^^^^^^^^^^^^^^^^^^^\n", "  File \"D:\\dex\\.venv\\Lib\\site-packages\\sqlalchemy\\orm\\session.py\", line 2251, in _execute_internal\n    result: Result[Any] = compile_state_cls.orm_execute_statement(\n                          ^^^^^^^^^^^^^^^^^^^^^^^^^^^^^^^^^^^^^^^^\n", "  File \"D:\\dex\\.venv\\Lib\\site-packages\\sqlalchemy\\orm\\context.py\", line 306, in orm_execute_statement\n    result = conn.execute(\n             ^^^^^^^^^^^^^\n", "  File \"D:\\dex\\.venv\\Lib\\site-packages\\sqlalchemy\\engine\\base.py\", line 1419, in execute\n    return meth(\n           ^^^^^\n", "  File \"D:\\dex\\.venv\\Lib\\site-packages\\sqlalchemy\\sql\\elements.py\", line 526, in _execute_on_connection\n    return connection._execute_clauseelement(\n           ^^^^^^^^^^^^^^^^^^^^^^^^^^^^^^^^^^\n", "  File \"D:\\dex\\.venv\\Lib\\site-packages\\sqlalchemy\\engine\\base.py\", line 1641, in _execute_clauseelement\n    ret = self._execute_context(\n          ^^^^^^^^^^^^^^^^^^^^^^\n", "  File \"D:\\dex\\.venv\\Lib\\site-packages\\sqlalchemy\\engine\\base.py\", line 1846, in _execute_context\n    return self._exec_single_context(\n           ^^^^^^^^^^^^^^^^^^^^^^^^^^\n", "  File \"D:\\dex\\.venv\\Lib\\site-packages\\sqlalchemy\\engine\\base.py\", line 1986, in _exec_single_context\n    self._handle_dbapi_exception(\n", "  File \"D:\\dex\\.venv\\Lib\\site-packages\\sqlalchemy\\engine\\base.py\", line 2355, in _handle_dbapi_exception\n    raise sqlalchemy_exception.with_traceback(exc_info[2]) from e\n", "  File \"D:\\dex\\.venv\\Lib\\site-packages\\sqlalchemy\\engine\\base.py\", line 1967, in _exec_single_context\n    self.dialect.do_execute(\n", "  File \"D:\\dex\\.venv\\Lib\\site-packages\\sqlalchemy\\engine\\default.py\", line 951, in do_execute\n    cursor.execute(statement, parameters)\n", "  File \"D:\\dex\\.venv\\Lib\\site-packages\\sqlalchemy\\dialects\\sqlite\\aiosqlite.py\", line 177, in execute\n    self._adapt_connection._handle_exception(error)\n", "  File \"D:\\dex\\.venv\\Lib\\site-packages\\sqlalchemy\\dialects\\sqlite\\aiosqlite.py\", line 337, in _handle_exception\n    raise error\n", "  File \"D:\\dex\\.venv\\Lib\\site-packages\\sqlalchemy\\dialects\\sqlite\\aiosqlite.py\", line 159, in execute\n    self.await_(_cursor.execute(operation, parameters))\n", "  File \"D:\\dex\\.venv\\Lib\\site-packages\\sqlalchemy\\util\\_concurrency_py3k.py\", line 132, in await_only\n    return current.parent.switch(awaitable)  # type: ignore[no-any-return,attr-defined] # noqa: E501\n           ^^^^^^^^^^^^^^^^^^^^^^^^^^^^^^^^\n", "  File \"D:\\dex\\.venv\\Lib\\site-packages\\sqlalchemy\\util\\_concurrency_py3k.py\", line 196, in greenlet_spawn\n    value = await result\n            ^^^^^^^^^^^^\n", "  File \"D:\\dex\\.venv\\Lib\\site-packages\\aiosqlite\\cursor.py\", line 40, in execute\n    await self._execute(self._cursor.execute, sql, parameters)\n", "  File \"D:\\dex\\.venv\\Lib\\site-packages\\aiosqlite\\cursor.py\", line 32, in _execute\n    return await self._conn._execute(fn, *args, **kwargs)\n           ^^^^^^^^^^^^^^^^^^^^^^^^^^^^^^^^^^^^^^^^^^^^^^\n", "  File \"D:\\dex\\.venv\\Lib\\site-packages\\aiosqlite\\core.py\", line 122, in _execute\n    return await future\n           ^^^^^^^^^^^^\n", "  File \"D:\\dex\\.venv\\Lib\\site-packages\\aiosqlite\\core.py\", line 105, in run\n    result = function()\n             ^^^^^^^^^^\n", "sqlalchemy.exc.OperationalError: (sqlite3.OperationalError) no such column: ledger_entries.execution_mode\n[SQL: SELECT ledger_entries.id, ledger_entries.user_id, ledger_entries.trace_id, ledger_entries.created_at, ledger_entries.chain, ledger_entries.dex, ledger_entries.trade_type, ledger_entries.input_token, ledger_entries.input_token_symbol, ledger_entries.output_token, ledger_entries.output_token_symbol, ledger_entries.input_amount, ledger_entries.output_amount, ledger_entries.price, ledger_entries.price_usd, ledger_entries.tx_hash, ledger_entries.block_number, ledger_entries.gas_used, ledger_entries.gas_price, ledger_entries.transaction_fee, ledger_entries.transaction_fee_usd, ledger_entries.status, ledger_entries.error_message, ledger_entries.wallet_address, ledger_entries.realized_pnl, ledger_entries.realized_pnl_usd, ledger_entries.risk_score, ledger_entries.risk_factors, ledger_entries.tags, ledger_entries.notes, ledger_entries.archived, ledger_entries.archived_at, ledger_entries.execution_mode \nFROM ledger_entries \nWHERE ledger_entries.user_id = ? ORDER BY ledger_entries.created_at DESC\n LIMIT ? OFFSET ?]\n[parameters: (1, 5000, 0)]\n(Background on this error at: https://sqlalche.me/e/20/e3q8)\n"]}, "location": {"file": "D:\\dex\\backend\\app\\api\\ledger.py", "line": 441, "function": "get_portfolio_summary"}}
{"timestamp": "2025-08-27T14:55:24.896343Z", "level": "ERROR", "trace_id": "2f33911a-20bf-4748-a5d9-412d1d6633b7", "module": "app.api.ledger", "message": "Database error fetching positions: (sqlite3.OperationalError) no such column: ledger_entries.execution_mode\n[SQL: SELECT ledger_entries.id, ledger_entries.user_id, ledger_entries.trace_id, ledger_entries.created_at, ledger_entries.chain, ledger_entries.dex, ledger_entries.trade_type, ledger_entries.input_token, ledger_entries.input_token_symbol, ledger_entries.output_token, ledger_entries.output_token_symbol, ledger_entries.input_amount, ledger_entries.output_amount, ledger_entries.price, ledger_entries.price_usd, ledger_entries.tx_hash, ledger_entries.block_number, ledger_entries.gas_used, ledger_entries.gas_price, ledger_entries.transaction_fee, ledger_entries.transaction_fee_usd, ledger_entries.status, ledger_entries.error_message, ledger_entries.wallet_address, ledger_entries.realized_pnl, ledger_entries.realized_pnl_usd, ledger_entries.risk_score, ledger_entries.risk_factors, ledger_entries.tags, ledger_entries.notes, ledger_entries.archived, ledger_entries.archived_at, ledger_entries.execution_mode \nFROM ledger_entries \nWHERE ledger_entries.user_id = ? AND ledger_entries.chain = ? ORDER BY ledger_entries.created_at DESC\n LIMIT ? OFFSET ?]\n[parameters: (1, 'ethereum', 1000, 0)]\n(Background on this error at: https://sqlalche.me/e/20/e3q8)", "exception": {"type": "OperationalError", "message": "(sqlite3.OperationalError) no such column: ledger_entries.execution_mode\n[SQL: SELECT ledger_entries.id, ledger_entries.user_id, ledger_entries.trace_id, ledger_entries.created_at, ledger_entries.chain, ledger_entries.dex, ledger_entries.trade_type, ledger_entries.input_token, ledger_entries.input_token_symbol, ledger_entries.output_token, ledger_entries.output_token_symbol, ledger_entries.input_amount, ledger_entries.output_amount, ledger_entries.price, ledger_entries.price_usd, ledger_entries.tx_hash, ledger_entries.block_number, ledger_entries.gas_used, ledger_entries.gas_price, ledger_entries.transaction_fee, ledger_entries.transaction_fee_usd, ledger_entries.status, ledger_entries.error_message, ledger_entries.wallet_address, ledger_entries.realized_pnl, ledger_entries.realized_pnl_usd, ledger_entries.risk_score, ledger_entries.risk_factors, ledger_entries.tags, ledger_entries.notes, ledger_entries.archived, ledger_entries.archived_at, ledger_entries.execution_mode \nFROM ledger_entries \nWHERE ledger_entries.user_id = ? AND ledger_entries.chain = ? ORDER BY ledger_entries.created_at DESC\n LIMIT ? OFFSET ?]\n[parameters: (1, 'ethereum', 1000, 0)]\n(Background on this error at: https://sqlalche.me/e/20/e3q8)", "traceback": ["Traceback (most recent call last):\n", "  File \"D:\\dex\\.venv\\Lib\\site-packages\\sqlalchemy\\engine\\base.py\", line 1967, in _exec_single_context\n    self.dialect.do_execute(\n", "  File \"D:\\dex\\.venv\\Lib\\site-packages\\sqlalchemy\\engine\\default.py\", line 951, in do_execute\n    cursor.execute(statement, parameters)\n", "  File \"D:\\dex\\.venv\\Lib\\site-packages\\sqlalchemy\\dialects\\sqlite\\aiosqlite.py\", line 177, in execute\n    self._adapt_connection._handle_exception(error)\n", "  File \"D:\\dex\\.venv\\Lib\\site-packages\\sqlalchemy\\dialects\\sqlite\\aiosqlite.py\", line 337, in _handle_exception\n    raise error\n", "  File \"D:\\dex\\.venv\\Lib\\site-packages\\sqlalchemy\\dialects\\sqlite\\aiosqlite.py\", line 159, in execute\n    self.await_(_cursor.execute(operation, parameters))\n", "  File \"D:\\dex\\.venv\\Lib\\site-packages\\sqlalchemy\\util\\_concurrency_py3k.py\", line 132, in await_only\n    return current.parent.switch(awaitable)  # type: ignore[no-any-return,attr-defined] # noqa: E501\n           ^^^^^^^^^^^^^^^^^^^^^^^^^^^^^^^^\n", "  File \"D:\\dex\\.venv\\Lib\\site-packages\\sqlalchemy\\util\\_concurrency_py3k.py\", line 196, in greenlet_spawn\n    value = await result\n            ^^^^^^^^^^^^\n", "  File \"D:\\dex\\.venv\\Lib\\site-packages\\aiosqlite\\cursor.py\", line 40, in execute\n    await self._execute(self._cursor.execute, sql, parameters)\n", "  File \"D:\\dex\\.venv\\Lib\\site-packages\\aiosqlite\\cursor.py\", line 32, in _execute\n    return await self._conn._execute(fn, *args, **kwargs)\n           ^^^^^^^^^^^^^^^^^^^^^^^^^^^^^^^^^^^^^^^^^^^^^^\n", "  File \"D:\\dex\\.venv\\Lib\\site-packages\\aiosqlite\\core.py\", line 122, in _execute\n    return await future\n           ^^^^^^^^^^^^\n", "  File \"D:\\dex\\.venv\\Lib\\site-packages\\aiosqlite\\core.py\", line 105, in run\n    result = function()\n             ^^^^^^^^^^\n", "sqlite3.OperationalError: no such column: ledger_entries.execution_mode\n", "\nThe above exception was the direct cause of the following exception:\n\n", "Traceback (most recent call last):\n", "  File \"D:\\dex\\backend\\app\\api\\ledger.py\", line 131, in get_positions\n    ledger_entries = await ledger_repo.get_user_ledger(\n                     ^^^^^^^^^^^^^^^^^^^^^^^^^^^^^^^^^^\n", "  File \"D:\\dex\\backend\\app\\storage\\repositories.py\", line 665, in get_user_ledger\n    result = await self.session.execute(stmt)\n             ^^^^^^^^^^^^^^^^^^^^^^^^^^^^^^^^\n", "  File \"D:\\dex\\.venv\\Lib\\site-packages\\sqlalchemy\\ext\\asyncio\\session.py\", line 463, in execute\n    result = await greenlet_spawn(\n             ^^^^^^^^^^^^^^^^^^^^^\n", "  File \"D:\\dex\\.venv\\Lib\\site-packages\\sqlalchemy\\util\\_concurrency_py3k.py\", line 201, in greenlet_spawn\n    result = context.throw(*sys.exc_info())\n             ^^^^^^^^^^^^^^^^^^^^^^^^^^^^^^\n", "  File \"D:\\dex\\.venv\\Lib\\site-packages\\sqlalchemy\\orm\\session.py\", line 2365, in execute\n    return self._execute_internal(\n           ^^^^^^^^^^^^^^^^^^^^^^^\n", "  File \"D:\\dex\\.venv\\Lib\\site-packages\\sqlalchemy\\orm\\session.py\", line 2251, in _execute_internal\n    result: Result[Any] = compile_state_cls.orm_execute_statement(\n                          ^^^^^^^^^^^^^^^^^^^^^^^^^^^^^^^^^^^^^^^^\n", "  File \"D:\\dex\\.venv\\Lib\\site-packages\\sqlalchemy\\orm\\context.py\", line 306, in orm_execute_statement\n    result = conn.execute(\n             ^^^^^^^^^^^^^\n", "  File \"D:\\dex\\.venv\\Lib\\site-packages\\sqlalchemy\\engine\\base.py\", line 1419, in execute\n    return meth(\n           ^^^^^\n", "  File \"D:\\dex\\.venv\\Lib\\site-packages\\sqlalchemy\\sql\\elements.py\", line 526, in _execute_on_connection\n    return connection._execute_clauseelement(\n           ^^^^^^^^^^^^^^^^^^^^^^^^^^^^^^^^^^\n", "  File \"D:\\dex\\.venv\\Lib\\site-packages\\sqlalchemy\\engine\\base.py\", line 1641, in _execute_clauseelement\n    ret = self._execute_context(\n          ^^^^^^^^^^^^^^^^^^^^^^\n", "  File \"D:\\dex\\.venv\\Lib\\site-packages\\sqlalchemy\\engine\\base.py\", line 1846, in _execute_context\n    return self._exec_single_context(\n           ^^^^^^^^^^^^^^^^^^^^^^^^^^\n", "  File \"D:\\dex\\.venv\\Lib\\site-packages\\sqlalchemy\\engine\\base.py\", line 1986, in _exec_single_context\n    self._handle_dbapi_exception(\n", "  File \"D:\\dex\\.venv\\Lib\\site-packages\\sqlalchemy\\engine\\base.py\", line 2355, in _handle_dbapi_exception\n    raise sqlalchemy_exception.with_traceback(exc_info[2]) from e\n", "  File \"D:\\dex\\.venv\\Lib\\site-packages\\sqlalchemy\\engine\\base.py\", line 1967, in _exec_single_context\n    self.dialect.do_execute(\n", "  File \"D:\\dex\\.venv\\Lib\\site-packages\\sqlalchemy\\engine\\default.py\", line 951, in do_execute\n    cursor.execute(statement, parameters)\n", "  File \"D:\\dex\\.venv\\Lib\\site-packages\\sqlalchemy\\dialects\\sqlite\\aiosqlite.py\", line 177, in execute\n    self._adapt_connection._handle_exception(error)\n", "  File \"D:\\dex\\.venv\\Lib\\site-packages\\sqlalchemy\\dialects\\sqlite\\aiosqlite.py\", line 337, in _handle_exception\n    raise error\n", "  File \"D:\\dex\\.venv\\Lib\\site-packages\\sqlalchemy\\dialects\\sqlite\\aiosqlite.py\", line 159, in execute\n    self.await_(_cursor.execute(operation, parameters))\n", "  File \"D:\\dex\\.venv\\Lib\\site-packages\\sqlalchemy\\util\\_concurrency_py3k.py\", line 132, in await_only\n    return current.parent.switch(awaitable)  # type: ignore[no-any-return,attr-defined] # noqa: E501\n           ^^^^^^^^^^^^^^^^^^^^^^^^^^^^^^^^\n", "  File \"D:\\dex\\.venv\\Lib\\site-packages\\sqlalchemy\\util\\_concurrency_py3k.py\", line 196, in greenlet_spawn\n    value = await result\n            ^^^^^^^^^^^^\n", "  File \"D:\\dex\\.venv\\Lib\\site-packages\\aiosqlite\\cursor.py\", line 40, in execute\n    await self._execute(self._cursor.execute, sql, parameters)\n", "  File \"D:\\dex\\.venv\\Lib\\site-packages\\aiosqlite\\cursor.py\", line 32, in _execute\n    return await self._conn._execute(fn, *args, **kwargs)\n           ^^^^^^^^^^^^^^^^^^^^^^^^^^^^^^^^^^^^^^^^^^^^^^\n", "  File \"D:\\dex\\.venv\\Lib\\site-packages\\aiosqlite\\core.py\", line 122, in _execute\n    return await future\n           ^^^^^^^^^^^^\n", "  File \"D:\\dex\\.venv\\Lib\\site-packages\\aiosqlite\\core.py\", line 105, in run\n    result = function()\n             ^^^^^^^^^^\n", "sqlalchemy.exc.OperationalError: (sqlite3.OperationalError) no such column: ledger_entries.execution_mode\n[SQL: SELECT ledger_entries.id, ledger_entries.user_id, ledger_entries.trace_id, ledger_entries.created_at, ledger_entries.chain, ledger_entries.dex, ledger_entries.trade_type, ledger_entries.input_token, ledger_entries.input_token_symbol, ledger_entries.output_token, ledger_entries.output_token_symbol, ledger_entries.input_amount, ledger_entries.output_amount, ledger_entries.price, ledger_entries.price_usd, ledger_entries.tx_hash, ledger_entries.block_number, ledger_entries.gas_used, ledger_entries.gas_price, ledger_entries.transaction_fee, ledger_entries.transaction_fee_usd, ledger_entries.status, ledger_entries.error_message, ledger_entries.wallet_address, ledger_entries.realized_pnl, ledger_entries.realized_pnl_usd, ledger_entries.risk_score, ledger_entries.risk_factors, ledger_entries.tags, ledger_entries.notes, ledger_entries.archived, ledger_entries.archived_at, ledger_entries.execution_mode \nFROM ledger_entries \nWHERE ledger_entries.user_id = ? AND ledger_entries.chain = ? ORDER BY ledger_entries.created_at DESC\n LIMIT ? OFFSET ?]\n[parameters: (1, 'ethereum', 1000, 0)]\n(Background on this error at: https://sqlalche.me/e/20/e3q8)\n"]}, "location": {"file": "D:\\dex\\backend\\app\\api\\ledger.py", "line": 173, "function": "get_positions"}}
{"timestamp": "2025-08-27T14:55:24.903019Z", "level": "ERROR", "trace_id": "2f33911a-20bf-4748-a5d9-412d1d6633b7", "module": "app.middleware.rate_limiting", "message": "Redis connection failed: Error Multiple exceptions: [Errno 10061] Connect call failed ('::1', 6379, 0, 0), [Errno 10061] Connect call failed ('127.0.0.1', 6379) connecting to localhost:6379.", "location": {"file": "D:\\dex\\backend\\app\\middleware\\rate_limiting.py", "line": 303, "function": "connect"}}
{"timestamp": "2025-08-27T14:55:24.904016Z", "level": "ERROR", "trace_id": "2f33911a-20bf-4748-a5d9-412d1d6633b7", "module": "app.middleware.rate_limiting", "message": "Redis connection failed: Error Multiple exceptions: [Errno 10061] Connect call failed ('::1', 6379, 0, 0), [Errno 10061] Connect call failed ('127.0.0.1', 6379) connecting to localhost:6379.", "location": {"file": "D:\\dex\\backend\\app\\middleware\\rate_limiting.py", "line": 303, "function": "connect"}}
{"timestamp": "2025-08-27T14:55:24.904690Z", "level": "ERROR", "trace_id": "2f33911a-20bf-4748-a5d9-412d1d6633b7", "module": "app.core.exception_handlers", "message": "HTTP 500: Database error retrieving transactions: ledger_transactions_9ac15a6c77d3", "location": {"file": "D:\\dex\\backend\\app\\core\\exception_handlers.py", "line": 201, "function": "http_exception_handler"}}
{"timestamp": "2025-08-27T14:55:24.905195Z", "level": "ERROR", "trace_id": "2f33911a-20bf-4748-a5d9-412d1d6633b7", "module": "app.core.exception_handlers", "message": "HTTP 500: Database error calculating summary: portfolio_summary_e2002330955d", "location": {"file": "D:\\dex\\backend\\app\\core\\exception_handlers.py", "line": 201, "function": "http_exception_handler"}}
{"timestamp": "2025-08-27T14:55:24.905768Z", "level": "ERROR", "trace_id": "2f33911a-20bf-4748-a5d9-412d1d6633b7", "module": "app.core.exception_handlers", "message": "HTTP 500: Database error retrieving positions: ledger_positions_cb7b9820198f", "location": {"file": "D:\\dex\\backend\\app\\core\\exception_handlers.py", "line": 201, "function": "http_exception_handler"}}
{"timestamp": "2025-08-27T14:55:28.678752Z", "level": "ERROR", "trace_id": "2f33911a-20bf-4748-a5d9-412d1d6633b7", "module": "app.middleware.rate_limiting", "message": "Redis connection failed: Error Multiple exceptions: [Errno 10061] Connect call failed ('::1', 6379, 0, 0), [Errno 10061] Connect call failed ('127.0.0.1', 6379) connecting to localhost:6379.", "location": {"file": "D:\\dex\\backend\\app\\middleware\\rate_limiting.py", "line": 303, "function": "connect"}}
{"timestamp": "2025-08-27T14:55:28.679763Z", "level": "ERROR", "trace_id": "2f33911a-20bf-4748-a5d9-412d1d6633b7", "module": "app.api.wallet", "message": "Logging failed: \"Attempt to overwrite 'message' in LogRecord\". Original message: Wallet registration request received", "location": {"file": "D:\\dex\\backend\\app\\api\\wallet.py", "line": 198, "function": "log_wallet_operation"}}
{"timestamp": "2025-08-27T14:55:28.679763Z", "level": "ERROR", "trace_id": "2f33911a-20bf-4748-a5d9-412d1d6633b7", "module": "app.api.wallet", "message": "Logging failed: \"Attempt to overwrite 'message' in LogRecord\". Original message: Wallet registration completed successfully", "location": {"file": "D:\\dex\\backend\\app\\api\\wallet.py", "line": 198, "function": "log_wallet_operation"}}
{"timestamp": "2025-08-27T14:55:28.780553Z", "level": "ERROR", "trace_id": "2f33911a-20bf-4748-a5d9-412d1d6633b7", "module": "app.api.wallet", "message": "Logging failed: \"Attempt to overwrite 'message' in LogRecord\". Original message: Wallet registration metrics logged", "location": {"file": "D:\\dex\\backend\\app\\api\\wallet.py", "line": 198, "function": "log_wallet_operation"}}
{"timestamp": "2025-08-27T14:55:40.535682Z", "level": "ERROR", "trace_id": "2f33911a-20bf-4748-a5d9-412d1d6633b7", "module": "app.middleware.rate_limiting", "message": "Redis connection failed: Error Multiple exceptions: [Errno 10061] Connect call failed ('::1', 6379, 0, 0), [Errno 10061] Connect call failed ('127.0.0.1', 6379) connecting to localhost:6379.", "location": {"file": "D:\\dex\\backend\\app\\middleware\\rate_limiting.py", "line": 303, "function": "connect"}}
{"timestamp": "2025-08-27T14:55:40.536695Z", "level": "ERROR", "trace_id": "2f33911a-20bf-4748-a5d9-412d1d6633b7", "module": "app.middleware.rate_limiting", "message": "Redis connection failed: Error Multiple exceptions: [Errno 10061] Connect call failed ('::1', 6379, 0, 0), [Errno 10061] Connect call failed ('127.0.0.1', 6379) connecting to localhost:6379.", "location": {"file": "D:\\dex\\backend\\app\\middleware\\rate_limiting.py", "line": 303, "function": "connect"}}
{"timestamp": "2025-08-27T14:55:40.537206Z", "level": "ERROR", "trace_id": "2f33911a-20bf-4748-a5d9-412d1d6633b7", "module": "app.api.wallet", "message": "Logging failed: \"Attempt to overwrite 'message' in LogRecord\". Original message: Wallet connection check", "location": {"file": "D:\\dex\\backend\\app\\api\\wallet.py", "line": 198, "function": "log_wallet_operation"}}
{"timestamp": "2025-08-27T14:55:40.540995Z", "level": "ERROR", "trace_id": "2f33911a-20bf-4748-a5d9-412d1d6633b7", "module": "app.api.wallet", "message": "Logging failed: \"Attempt to overwrite 'message' in LogRecord\". Original message: Wallet registration request received", "location": {"file": "D:\\dex\\backend\\app\\api\\wallet.py", "line": 198, "function": "log_wallet_operation"}}
{"timestamp": "2025-08-27T14:55:40.541552Z", "level": "ERROR", "trace_id": "2f33911a-20bf-4748-a5d9-412d1d6633b7", "module": "app.api.wallet", "message": "Logging failed: \"Attempt to overwrite 'message' in LogRecord\". Original message: Wallet registration completed successfully", "location": {"file": "D:\\dex\\backend\\app\\api\\wallet.py", "line": 198, "function": "log_wallet_operation"}}
{"timestamp": "2025-08-27T14:55:40.640754Z", "level": "ERROR", "trace_id": "2f33911a-20bf-4748-a5d9-412d1d6633b7", "module": "app.api.wallet", "message": "Logging failed: \"Attempt to overwrite 'message' in LogRecord\". Original message: Wallet registration metrics logged", "location": {"file": "D:\\dex\\backend\\app\\api\\wallet.py", "line": 198, "function": "log_wallet_operation"}}
{"timestamp": "2025-08-27T14:55:44.612756Z", "level": "ERROR", "trace_id": "2f33911a-20bf-4748-a5d9-412d1d6633b7", "module": "app.middleware.rate_limiting", "message": "Redis connection failed: Error Multiple exceptions: [Errno 10061] Connect call failed ('::1', 6379, 0, 0), [Errno 10061] Connect call failed ('127.0.0.1', 6379) connecting to localhost:6379.", "location": {"file": "D:\\dex\\backend\\app\\middleware\\rate_limiting.py", "line": 303, "function": "connect"}}
{"timestamp": "2025-08-27T14:55:44.613765Z", "level": "ERROR", "trace_id": "2f33911a-20bf-4748-a5d9-412d1d6633b7", "module": "app.middleware.rate_limiting", "message": "Redis connection failed: Error Multiple exceptions: [Errno 10061] Connect call failed ('::1', 6379, 0, 0), [Errno 10061] Connect call failed ('127.0.0.1', 6379) connecting to localhost:6379.", "location": {"file": "D:\\dex\\backend\\app\\middleware\\rate_limiting.py", "line": 303, "function": "connect"}}
{"timestamp": "2025-08-27T14:55:44.613765Z", "level": "ERROR", "trace_id": "2f33911a-20bf-4748-a5d9-412d1d6633b7", "module": "app.api.wallet", "message": "Logging failed: \"Attempt to overwrite 'message' in LogRecord\". Original message: Wallet connection check", "location": {"file": "D:\\dex\\backend\\app\\api\\wallet.py", "line": 198, "function": "log_wallet_operation"}}
{"timestamp": "2025-08-27T14:55:51.169175Z", "level": "ERROR", "trace_id": "2f33911a-20bf-4748-a5d9-412d1d6633b7", "module": "app.middleware.rate_limiting", "message": "Redis connection failed: Error Multiple exceptions: [Errno 10061] Connect call failed ('::1', 6379, 0, 0), [Errno 10061] Connect call failed ('127.0.0.1', 6379) connecting to localhost:6379.", "location": {"file": "D:\\dex\\backend\\app\\middleware\\rate_limiting.py", "line": 303, "function": "connect"}}
{"timestamp": "2025-08-27T14:55:51.169175Z", "level": "ERROR", "trace_id": "2f33911a-20bf-4748-a5d9-412d1d6633b7", "module": "app.middleware.rate_limiting", "message": "Redis connection failed: Error Multiple exceptions: [Errno 10061] Connect call failed ('::1', 6379, 0, 0), [Errno 10061] Connect call failed ('127.0.0.1', 6379) connecting to localhost:6379.", "location": {"file": "D:\\dex\\backend\\app\\middleware\\rate_limiting.py", "line": 303, "function": "connect"}}
{"timestamp": "2025-08-27T14:55:51.170732Z", "level": "ERROR", "trace_id": "2f33911a-20bf-4748-a5d9-412d1d6633b7", "module": "app.api.wallet", "message": "Logging failed: \"Attempt to overwrite 'message' in LogRecord\". Original message: Wallet connection check", "location": {"file": "D:\\dex\\backend\\app\\api\\wallet.py", "line": 198, "function": "log_wallet_operation"}}
{"timestamp": "2025-08-27T14:55:55.211870Z", "level": "ERROR", "trace_id": "2f33911a-20bf-4748-a5d9-412d1d6633b7", "module": "app.middleware.rate_limiting", "message": "Redis connection failed: Error Multiple exceptions: [Errno 10061] Connect call failed ('::1', 6379, 0, 0), [Errno 10061] Connect call failed ('127.0.0.1', 6379) connecting to localhost:6379.", "location": {"file": "D:\\dex\\backend\\app\\middleware\\rate_limiting.py", "line": 303, "function": "connect"}}
{"timestamp": "2025-08-27T14:55:55.212902Z", "level": "ERROR", "trace_id": "2f33911a-20bf-4748-a5d9-412d1d6633b7", "module": "app.middleware.rate_limiting", "message": "Redis connection failed: Error Multiple exceptions: [Errno 10061] Connect call failed ('::1', 6379, 0, 0), [Errno 10061] Connect call failed ('127.0.0.1', 6379) connecting to localhost:6379.", "location": {"file": "D:\\dex\\backend\\app\\middleware\\rate_limiting.py", "line": 303, "function": "connect"}}
{"timestamp": "2025-08-27T14:55:55.212902Z", "level": "ERROR", "trace_id": "2f33911a-20bf-4748-a5d9-412d1d6633b7", "module": "app.middleware.rate_limiting", "message": "Redis connection failed: Error Multiple exceptions: [Errno 10061] Connect call failed ('::1', 6379, 0, 0), [Errno 10061] Connect call failed ('127.0.0.1', 6379) connecting to localhost:6379.", "location": {"file": "D:\\dex\\backend\\app\\middleware\\rate_limiting.py", "line": 303, "function": "connect"}}
{"timestamp": "2025-08-27T14:55:55.220891Z", "level": "ERROR", "trace_id": "2f33911a-20bf-4748-a5d9-412d1d6633b7", "module": "app.api.wallet", "message": "Logging failed: \"Attempt to overwrite 'message' in LogRecord\". Original message: Wallet connection check", "location": {"file": "D:\\dex\\backend\\app\\api\\wallet.py", "line": 198, "function": "log_wallet_operation"}}
{"timestamp": "2025-08-27T14:55:55.221451Z", "level": "ERROR", "trace_id": "2f33911a-20bf-4748-a5d9-412d1d6633b7", "module": "app.middleware.rate_limiting", "message": "Redis connection failed: Error Multiple exceptions: [Errno 10061] Connect call failed ('::1', 6379, 0, 0), [Errno 10061] Connect call failed ('127.0.0.1', 6379) connecting to localhost:6379.", "location": {"file": "D:\\dex\\backend\\app\\middleware\\rate_limiting.py", "line": 303, "function": "connect"}}
{"timestamp": "2025-08-27T14:55:55.222892Z", "level": "ERROR", "trace_id": "2f33911a-20bf-4748-a5d9-412d1d6633b7", "module": "app.middleware.rate_limiting", "message": "Redis connection failed: Error Multiple exceptions: [Errno 10061] Connect call failed ('::1', 6379, 0, 0), [Errno 10061] Connect call failed ('127.0.0.1', 6379) connecting to localhost:6379.", "location": {"file": "D:\\dex\\backend\\app\\middleware\\rate_limiting.py", "line": 303, "function": "connect"}}
{"timestamp": "2025-08-27T14:55:55.223445Z", "level": "ERROR", "trace_id": "2f33911a-20bf-4748-a5d9-412d1d6633b7", "module": "app.middleware.rate_limiting", "message": "Redis connection failed: Error Multiple exceptions: [Errno 10061] Connect call failed ('::1', 6379, 0, 0), [Errno 10061] Connect call failed ('127.0.0.1', 6379) connecting to localhost:6379.", "location": {"file": "D:\\dex\\backend\\app\\middleware\\rate_limiting.py", "line": 303, "function": "connect"}}
{"timestamp": "2025-08-27T14:55:55.248180Z", "level": "ERROR", "trace_id": "2f33911a-20bf-4748-a5d9-412d1d6633b7", "module": "app.api.ledger", "message": "Database error calculating portfolio summary: (sqlite3.OperationalError) no such column: ledger_entries.execution_mode\n[SQL: SELECT ledger_entries.id, ledger_entries.user_id, ledger_entries.trace_id, ledger_entries.created_at, ledger_entries.chain, ledger_entries.dex, ledger_entries.trade_type, ledger_entries.input_token, ledger_entries.input_token_symbol, ledger_entries.output_token, ledger_entries.output_token_symbol, ledger_entries.input_amount, ledger_entries.output_amount, ledger_entries.price, ledger_entries.price_usd, ledger_entries.tx_hash, ledger_entries.block_number, ledger_entries.gas_used, ledger_entries.gas_price, ledger_entries.transaction_fee, ledger_entries.transaction_fee_usd, ledger_entries.status, ledger_entries.error_message, ledger_entries.wallet_address, ledger_entries.realized_pnl, ledger_entries.realized_pnl_usd, ledger_entries.risk_score, ledger_entries.risk_factors, ledger_entries.tags, ledger_entries.notes, ledger_entries.archived, ledger_entries.archived_at, ledger_entries.execution_mode \nFROM ledger_entries \nWHERE ledger_entries.user_id = ? ORDER BY ledger_entries.created_at DESC\n LIMIT ? OFFSET ?]\n[parameters: (1, 5000, 0)]\n(Background on this error at: https://sqlalche.me/e/20/e3q8)", "exception": {"type": "OperationalError", "message": "(sqlite3.OperationalError) no such column: ledger_entries.execution_mode\n[SQL: SELECT ledger_entries.id, ledger_entries.user_id, ledger_entries.trace_id, ledger_entries.created_at, ledger_entries.chain, ledger_entries.dex, ledger_entries.trade_type, ledger_entries.input_token, ledger_entries.input_token_symbol, ledger_entries.output_token, ledger_entries.output_token_symbol, ledger_entries.input_amount, ledger_entries.output_amount, ledger_entries.price, ledger_entries.price_usd, ledger_entries.tx_hash, ledger_entries.block_number, ledger_entries.gas_used, ledger_entries.gas_price, ledger_entries.transaction_fee, ledger_entries.transaction_fee_usd, ledger_entries.status, ledger_entries.error_message, ledger_entries.wallet_address, ledger_entries.realized_pnl, ledger_entries.realized_pnl_usd, ledger_entries.risk_score, ledger_entries.risk_factors, ledger_entries.tags, ledger_entries.notes, ledger_entries.archived, ledger_entries.archived_at, ledger_entries.execution_mode \nFROM ledger_entries \nWHERE ledger_entries.user_id = ? ORDER BY ledger_entries.created_at DESC\n LIMIT ? OFFSET ?]\n[parameters: (1, 5000, 0)]\n(Background on this error at: https://sqlalche.me/e/20/e3q8)", "traceback": ["Traceback (most recent call last):\n", "  File \"D:\\dex\\.venv\\Lib\\site-packages\\sqlalchemy\\engine\\base.py\", line 1967, in _exec_single_context\n    self.dialect.do_execute(\n", "  File \"D:\\dex\\.venv\\Lib\\site-packages\\sqlalchemy\\engine\\default.py\", line 951, in do_execute\n    cursor.execute(statement, parameters)\n", "  File \"D:\\dex\\.venv\\Lib\\site-packages\\sqlalchemy\\dialects\\sqlite\\aiosqlite.py\", line 177, in execute\n    self._adapt_connection._handle_exception(error)\n", "  File \"D:\\dex\\.venv\\Lib\\site-packages\\sqlalchemy\\dialects\\sqlite\\aiosqlite.py\", line 337, in _handle_exception\n    raise error\n", "  File \"D:\\dex\\.venv\\Lib\\site-packages\\sqlalchemy\\dialects\\sqlite\\aiosqlite.py\", line 159, in execute\n    self.await_(_cursor.execute(operation, parameters))\n", "  File \"D:\\dex\\.venv\\Lib\\site-packages\\sqlalchemy\\util\\_concurrency_py3k.py\", line 132, in await_only\n    return current.parent.switch(awaitable)  # type: ignore[no-any-return,attr-defined] # noqa: E501\n           ^^^^^^^^^^^^^^^^^^^^^^^^^^^^^^^^\n", "  File \"D:\\dex\\.venv\\Lib\\site-packages\\sqlalchemy\\util\\_concurrency_py3k.py\", line 196, in greenlet_spawn\n    value = await result\n            ^^^^^^^^^^^^\n", "  File \"D:\\dex\\.venv\\Lib\\site-packages\\aiosqlite\\cursor.py\", line 40, in execute\n    await self._execute(self._cursor.execute, sql, parameters)\n", "  File \"D:\\dex\\.venv\\Lib\\site-packages\\aiosqlite\\cursor.py\", line 32, in _execute\n    return await self._conn._execute(fn, *args, **kwargs)\n           ^^^^^^^^^^^^^^^^^^^^^^^^^^^^^^^^^^^^^^^^^^^^^^\n", "  File \"D:\\dex\\.venv\\Lib\\site-packages\\aiosqlite\\core.py\", line 122, in _execute\n    return await future\n           ^^^^^^^^^^^^\n", "  File \"D:\\dex\\.venv\\Lib\\site-packages\\aiosqlite\\core.py\", line 105, in run\n    result = function()\n             ^^^^^^^^^^\n", "sqlite3.OperationalError: no such column: ledger_entries.execution_mode\n", "\nThe above exception was the direct cause of the following exception:\n\n", "Traceback (most recent call last):\n", "  File \"D:\\dex\\backend\\app\\api\\ledger.py\", line 410, in get_portfolio_summary\n    ledger_entries = await ledger_repo.get_user_ledger(\n                     ^^^^^^^^^^^^^^^^^^^^^^^^^^^^^^^^^^\n", "  File \"D:\\dex\\backend\\app\\storage\\repositories.py\", line 665, in get_user_ledger\n    result = await self.session.execute(stmt)\n             ^^^^^^^^^^^^^^^^^^^^^^^^^^^^^^^^\n", "  File \"D:\\dex\\.venv\\Lib\\site-packages\\sqlalchemy\\ext\\asyncio\\session.py\", line 463, in execute\n    result = await greenlet_spawn(\n             ^^^^^^^^^^^^^^^^^^^^^\n", "  File \"D:\\dex\\.venv\\Lib\\site-packages\\sqlalchemy\\util\\_concurrency_py3k.py\", line 201, in greenlet_spawn\n    result = context.throw(*sys.exc_info())\n             ^^^^^^^^^^^^^^^^^^^^^^^^^^^^^^\n", "  File \"D:\\dex\\.venv\\Lib\\site-packages\\sqlalchemy\\orm\\session.py\", line 2365, in execute\n    return self._execute_internal(\n           ^^^^^^^^^^^^^^^^^^^^^^^\n", "  File \"D:\\dex\\.venv\\Lib\\site-packages\\sqlalchemy\\orm\\session.py\", line 2251, in _execute_internal\n    result: Result[Any] = compile_state_cls.orm_execute_statement(\n                          ^^^^^^^^^^^^^^^^^^^^^^^^^^^^^^^^^^^^^^^^\n", "  File \"D:\\dex\\.venv\\Lib\\site-packages\\sqlalchemy\\orm\\context.py\", line 306, in orm_execute_statement\n    result = conn.execute(\n             ^^^^^^^^^^^^^\n", "  File \"D:\\dex\\.venv\\Lib\\site-packages\\sqlalchemy\\engine\\base.py\", line 1419, in execute\n    return meth(\n           ^^^^^\n", "  File \"D:\\dex\\.venv\\Lib\\site-packages\\sqlalchemy\\sql\\elements.py\", line 526, in _execute_on_connection\n    return connection._execute_clauseelement(\n           ^^^^^^^^^^^^^^^^^^^^^^^^^^^^^^^^^^\n", "  File \"D:\\dex\\.venv\\Lib\\site-packages\\sqlalchemy\\engine\\base.py\", line 1641, in _execute_clauseelement\n    ret = self._execute_context(\n          ^^^^^^^^^^^^^^^^^^^^^^\n", "  File \"D:\\dex\\.venv\\Lib\\site-packages\\sqlalchemy\\engine\\base.py\", line 1846, in _execute_context\n    return self._exec_single_context(\n           ^^^^^^^^^^^^^^^^^^^^^^^^^^\n", "  File \"D:\\dex\\.venv\\Lib\\site-packages\\sqlalchemy\\engine\\base.py\", line 1986, in _exec_single_context\n    self._handle_dbapi_exception(\n", "  File \"D:\\dex\\.venv\\Lib\\site-packages\\sqlalchemy\\engine\\base.py\", line 2355, in _handle_dbapi_exception\n    raise sqlalchemy_exception.with_traceback(exc_info[2]) from e\n", "  File \"D:\\dex\\.venv\\Lib\\site-packages\\sqlalchemy\\engine\\base.py\", line 1967, in _exec_single_context\n    self.dialect.do_execute(\n", "  File \"D:\\dex\\.venv\\Lib\\site-packages\\sqlalchemy\\engine\\default.py\", line 951, in do_execute\n    cursor.execute(statement, parameters)\n", "  File \"D:\\dex\\.venv\\Lib\\site-packages\\sqlalchemy\\dialects\\sqlite\\aiosqlite.py\", line 177, in execute\n    self._adapt_connection._handle_exception(error)\n", "  File \"D:\\dex\\.venv\\Lib\\site-packages\\sqlalchemy\\dialects\\sqlite\\aiosqlite.py\", line 337, in _handle_exception\n    raise error\n", "  File \"D:\\dex\\.venv\\Lib\\site-packages\\sqlalchemy\\dialects\\sqlite\\aiosqlite.py\", line 159, in execute\n    self.await_(_cursor.execute(operation, parameters))\n", "  File \"D:\\dex\\.venv\\Lib\\site-packages\\sqlalchemy\\util\\_concurrency_py3k.py\", line 132, in await_only\n    return current.parent.switch(awaitable)  # type: ignore[no-any-return,attr-defined] # noqa: E501\n           ^^^^^^^^^^^^^^^^^^^^^^^^^^^^^^^^\n", "  File \"D:\\dex\\.venv\\Lib\\site-packages\\sqlalchemy\\util\\_concurrency_py3k.py\", line 196, in greenlet_spawn\n    value = await result\n            ^^^^^^^^^^^^\n", "  File \"D:\\dex\\.venv\\Lib\\site-packages\\aiosqlite\\cursor.py\", line 40, in execute\n    await self._execute(self._cursor.execute, sql, parameters)\n", "  File \"D:\\dex\\.venv\\Lib\\site-packages\\aiosqlite\\cursor.py\", line 32, in _execute\n    return await self._conn._execute(fn, *args, **kwargs)\n           ^^^^^^^^^^^^^^^^^^^^^^^^^^^^^^^^^^^^^^^^^^^^^^\n", "  File \"D:\\dex\\.venv\\Lib\\site-packages\\aiosqlite\\core.py\", line 122, in _execute\n    return await future\n           ^^^^^^^^^^^^\n", "  File \"D:\\dex\\.venv\\Lib\\site-packages\\aiosqlite\\core.py\", line 105, in run\n    result = function()\n             ^^^^^^^^^^\n", "sqlalchemy.exc.OperationalError: (sqlite3.OperationalError) no such column: ledger_entries.execution_mode\n[SQL: SELECT ledger_entries.id, ledger_entries.user_id, ledger_entries.trace_id, ledger_entries.created_at, ledger_entries.chain, ledger_entries.dex, ledger_entries.trade_type, ledger_entries.input_token, ledger_entries.input_token_symbol, ledger_entries.output_token, ledger_entries.output_token_symbol, ledger_entries.input_amount, ledger_entries.output_amount, ledger_entries.price, ledger_entries.price_usd, ledger_entries.tx_hash, ledger_entries.block_number, ledger_entries.gas_used, ledger_entries.gas_price, ledger_entries.transaction_fee, ledger_entries.transaction_fee_usd, ledger_entries.status, ledger_entries.error_message, ledger_entries.wallet_address, ledger_entries.realized_pnl, ledger_entries.realized_pnl_usd, ledger_entries.risk_score, ledger_entries.risk_factors, ledger_entries.tags, ledger_entries.notes, ledger_entries.archived, ledger_entries.archived_at, ledger_entries.execution_mode \nFROM ledger_entries \nWHERE ledger_entries.user_id = ? ORDER BY ledger_entries.created_at DESC\n LIMIT ? OFFSET ?]\n[parameters: (1, 5000, 0)]\n(Background on this error at: https://sqlalche.me/e/20/e3q8)\n"]}, "location": {"file": "D:\\dex\\backend\\app\\api\\ledger.py", "line": 441, "function": "get_portfolio_summary"}}
{"timestamp": "2025-08-27T14:55:55.256717Z", "level": "ERROR", "trace_id": "2f33911a-20bf-4748-a5d9-412d1d6633b7", "module": "app.api.ledger", "message": "Database error fetching transactions: (sqlite3.OperationalError) no such column: ledger_entries.execution_mode\n[SQL: SELECT ledger_entries.id, ledger_entries.user_id, ledger_entries.trace_id, ledger_entries.created_at, ledger_entries.chain, ledger_entries.dex, ledger_entries.trade_type, ledger_entries.input_token, ledger_entries.input_token_symbol, ledger_entries.output_token, ledger_entries.output_token_symbol, ledger_entries.input_amount, ledger_entries.output_amount, ledger_entries.price, ledger_entries.price_usd, ledger_entries.tx_hash, ledger_entries.block_number, ledger_entries.gas_used, ledger_entries.gas_price, ledger_entries.transaction_fee, ledger_entries.transaction_fee_usd, ledger_entries.status, ledger_entries.error_message, ledger_entries.wallet_address, ledger_entries.realized_pnl, ledger_entries.realized_pnl_usd, ledger_entries.risk_score, ledger_entries.risk_factors, ledger_entries.tags, ledger_entries.notes, ledger_entries.archived, ledger_entries.archived_at, ledger_entries.execution_mode \nFROM ledger_entries \nWHERE ledger_entries.user_id = ? ORDER BY ledger_entries.created_at DESC\n LIMIT ? OFFSET ?]\n[parameters: (1, 100, 0)]\n(Background on this error at: https://sqlalche.me/e/20/e3q8)", "exception": {"type": "OperationalError", "message": "(sqlite3.OperationalError) no such column: ledger_entries.execution_mode\n[SQL: SELECT ledger_entries.id, ledger_entries.user_id, ledger_entries.trace_id, ledger_entries.created_at, ledger_entries.chain, ledger_entries.dex, ledger_entries.trade_type, ledger_entries.input_token, ledger_entries.input_token_symbol, ledger_entries.output_token, ledger_entries.output_token_symbol, ledger_entries.input_amount, ledger_entries.output_amount, ledger_entries.price, ledger_entries.price_usd, ledger_entries.tx_hash, ledger_entries.block_number, ledger_entries.gas_used, ledger_entries.gas_price, ledger_entries.transaction_fee, ledger_entries.transaction_fee_usd, ledger_entries.status, ledger_entries.error_message, ledger_entries.wallet_address, ledger_entries.realized_pnl, ledger_entries.realized_pnl_usd, ledger_entries.risk_score, ledger_entries.risk_factors, ledger_entries.tags, ledger_entries.notes, ledger_entries.archived, ledger_entries.archived_at, ledger_entries.execution_mode \nFROM ledger_entries \nWHERE ledger_entries.user_id = ? ORDER BY ledger_entries.created_at DESC\n LIMIT ? OFFSET ?]\n[parameters: (1, 100, 0)]\n(Background on this error at: https://sqlalche.me/e/20/e3q8)", "traceback": ["Traceback (most recent call last):\n", "  File \"D:\\dex\\.venv\\Lib\\site-packages\\sqlalchemy\\engine\\base.py\", line 1967, in _exec_single_context\n    self.dialect.do_execute(\n", "  File \"D:\\dex\\.venv\\Lib\\site-packages\\sqlalchemy\\engine\\default.py\", line 951, in do_execute\n    cursor.execute(statement, parameters)\n", "  File \"D:\\dex\\.venv\\Lib\\site-packages\\sqlalchemy\\dialects\\sqlite\\aiosqlite.py\", line 177, in execute\n    self._adapt_connection._handle_exception(error)\n", "  File \"D:\\dex\\.venv\\Lib\\site-packages\\sqlalchemy\\dialects\\sqlite\\aiosqlite.py\", line 337, in _handle_exception\n    raise error\n", "  File \"D:\\dex\\.venv\\Lib\\site-packages\\sqlalchemy\\dialects\\sqlite\\aiosqlite.py\", line 159, in execute\n    self.await_(_cursor.execute(operation, parameters))\n", "  File \"D:\\dex\\.venv\\Lib\\site-packages\\sqlalchemy\\util\\_concurrency_py3k.py\", line 132, in await_only\n    return current.parent.switch(awaitable)  # type: ignore[no-any-return,attr-defined] # noqa: E501\n           ^^^^^^^^^^^^^^^^^^^^^^^^^^^^^^^^\n", "  File \"D:\\dex\\.venv\\Lib\\site-packages\\sqlalchemy\\util\\_concurrency_py3k.py\", line 196, in greenlet_spawn\n    value = await result\n            ^^^^^^^^^^^^\n", "  File \"D:\\dex\\.venv\\Lib\\site-packages\\aiosqlite\\cursor.py\", line 40, in execute\n    await self._execute(self._cursor.execute, sql, parameters)\n", "  File \"D:\\dex\\.venv\\Lib\\site-packages\\aiosqlite\\cursor.py\", line 32, in _execute\n    return await self._conn._execute(fn, *args, **kwargs)\n           ^^^^^^^^^^^^^^^^^^^^^^^^^^^^^^^^^^^^^^^^^^^^^^\n", "  File \"D:\\dex\\.venv\\Lib\\site-packages\\aiosqlite\\core.py\", line 122, in _execute\n    return await future\n           ^^^^^^^^^^^^\n", "  File \"D:\\dex\\.venv\\Lib\\site-packages\\aiosqlite\\core.py\", line 105, in run\n    result = function()\n             ^^^^^^^^^^\n", "sqlite3.OperationalError: no such column: ledger_entries.execution_mode\n", "\nThe above exception was the direct cause of the following exception:\n\n", "Traceback (most recent call last):\n", "  File \"D:\\dex\\backend\\app\\api\\ledger.py\", line 264, in get_transactions\n    ledger_entries = await ledger_repo.get_user_ledger(\n                     ^^^^^^^^^^^^^^^^^^^^^^^^^^^^^^^^^^\n", "  File \"D:\\dex\\backend\\app\\storage\\repositories.py\", line 665, in get_user_ledger\n    result = await self.session.execute(stmt)\n             ^^^^^^^^^^^^^^^^^^^^^^^^^^^^^^^^\n", "  File \"D:\\dex\\.venv\\Lib\\site-packages\\sqlalchemy\\ext\\asyncio\\session.py\", line 463, in execute\n    result = await greenlet_spawn(\n             ^^^^^^^^^^^^^^^^^^^^^\n", "  File \"D:\\dex\\.venv\\Lib\\site-packages\\sqlalchemy\\util\\_concurrency_py3k.py\", line 201, in greenlet_spawn\n    result = context.throw(*sys.exc_info())\n             ^^^^^^^^^^^^^^^^^^^^^^^^^^^^^^\n", "  File \"D:\\dex\\.venv\\Lib\\site-packages\\sqlalchemy\\orm\\session.py\", line 2365, in execute\n    return self._execute_internal(\n           ^^^^^^^^^^^^^^^^^^^^^^^\n", "  File \"D:\\dex\\.venv\\Lib\\site-packages\\sqlalchemy\\orm\\session.py\", line 2251, in _execute_internal\n    result: Result[Any] = compile_state_cls.orm_execute_statement(\n                          ^^^^^^^^^^^^^^^^^^^^^^^^^^^^^^^^^^^^^^^^\n", "  File \"D:\\dex\\.venv\\Lib\\site-packages\\sqlalchemy\\orm\\context.py\", line 306, in orm_execute_statement\n    result = conn.execute(\n             ^^^^^^^^^^^^^\n", "  File \"D:\\dex\\.venv\\Lib\\site-packages\\sqlalchemy\\engine\\base.py\", line 1419, in execute\n    return meth(\n           ^^^^^\n", "  File \"D:\\dex\\.venv\\Lib\\site-packages\\sqlalchemy\\sql\\elements.py\", line 526, in _execute_on_connection\n    return connection._execute_clauseelement(\n           ^^^^^^^^^^^^^^^^^^^^^^^^^^^^^^^^^^\n", "  File \"D:\\dex\\.venv\\Lib\\site-packages\\sqlalchemy\\engine\\base.py\", line 1641, in _execute_clauseelement\n    ret = self._execute_context(\n          ^^^^^^^^^^^^^^^^^^^^^^\n", "  File \"D:\\dex\\.venv\\Lib\\site-packages\\sqlalchemy\\engine\\base.py\", line 1846, in _execute_context\n    return self._exec_single_context(\n           ^^^^^^^^^^^^^^^^^^^^^^^^^^\n", "  File \"D:\\dex\\.venv\\Lib\\site-packages\\sqlalchemy\\engine\\base.py\", line 1986, in _exec_single_context\n    self._handle_dbapi_exception(\n", "  File \"D:\\dex\\.venv\\Lib\\site-packages\\sqlalchemy\\engine\\base.py\", line 2355, in _handle_dbapi_exception\n    raise sqlalchemy_exception.with_traceback(exc_info[2]) from e\n", "  File \"D:\\dex\\.venv\\Lib\\site-packages\\sqlalchemy\\engine\\base.py\", line 1967, in _exec_single_context\n    self.dialect.do_execute(\n", "  File \"D:\\dex\\.venv\\Lib\\site-packages\\sqlalchemy\\engine\\default.py\", line 951, in do_execute\n    cursor.execute(statement, parameters)\n", "  File \"D:\\dex\\.venv\\Lib\\site-packages\\sqlalchemy\\dialects\\sqlite\\aiosqlite.py\", line 177, in execute\n    self._adapt_connection._handle_exception(error)\n", "  File \"D:\\dex\\.venv\\Lib\\site-packages\\sqlalchemy\\dialects\\sqlite\\aiosqlite.py\", line 337, in _handle_exception\n    raise error\n", "  File \"D:\\dex\\.venv\\Lib\\site-packages\\sqlalchemy\\dialects\\sqlite\\aiosqlite.py\", line 159, in execute\n    self.await_(_cursor.execute(operation, parameters))\n", "  File \"D:\\dex\\.venv\\Lib\\site-packages\\sqlalchemy\\util\\_concurrency_py3k.py\", line 132, in await_only\n    return current.parent.switch(awaitable)  # type: ignore[no-any-return,attr-defined] # noqa: E501\n           ^^^^^^^^^^^^^^^^^^^^^^^^^^^^^^^^\n", "  File \"D:\\dex\\.venv\\Lib\\site-packages\\sqlalchemy\\util\\_concurrency_py3k.py\", line 196, in greenlet_spawn\n    value = await result\n            ^^^^^^^^^^^^\n", "  File \"D:\\dex\\.venv\\Lib\\site-packages\\aiosqlite\\cursor.py\", line 40, in execute\n    await self._execute(self._cursor.execute, sql, parameters)\n", "  File \"D:\\dex\\.venv\\Lib\\site-packages\\aiosqlite\\cursor.py\", line 32, in _execute\n    return await self._conn._execute(fn, *args, **kwargs)\n           ^^^^^^^^^^^^^^^^^^^^^^^^^^^^^^^^^^^^^^^^^^^^^^\n", "  File \"D:\\dex\\.venv\\Lib\\site-packages\\aiosqlite\\core.py\", line 122, in _execute\n    return await future\n           ^^^^^^^^^^^^\n", "  File \"D:\\dex\\.venv\\Lib\\site-packages\\aiosqlite\\core.py\", line 105, in run\n    result = function()\n             ^^^^^^^^^^\n", "sqlalchemy.exc.OperationalError: (sqlite3.OperationalError) no such column: ledger_entries.execution_mode\n[SQL: SELECT ledger_entries.id, ledger_entries.user_id, ledger_entries.trace_id, ledger_entries.created_at, ledger_entries.chain, ledger_entries.dex, ledger_entries.trade_type, ledger_entries.input_token, ledger_entries.input_token_symbol, ledger_entries.output_token, ledger_entries.output_token_symbol, ledger_entries.input_amount, ledger_entries.output_amount, ledger_entries.price, ledger_entries.price_usd, ledger_entries.tx_hash, ledger_entries.block_number, ledger_entries.gas_used, ledger_entries.gas_price, ledger_entries.transaction_fee, ledger_entries.transaction_fee_usd, ledger_entries.status, ledger_entries.error_message, ledger_entries.wallet_address, ledger_entries.realized_pnl, ledger_entries.realized_pnl_usd, ledger_entries.risk_score, ledger_entries.risk_factors, ledger_entries.tags, ledger_entries.notes, ledger_entries.archived, ledger_entries.archived_at, ledger_entries.execution_mode \nFROM ledger_entries \nWHERE ledger_entries.user_id = ? ORDER BY ledger_entries.created_at DESC\n LIMIT ? OFFSET ?]\n[parameters: (1, 100, 0)]\n(Background on this error at: https://sqlalche.me/e/20/e3q8)\n"]}, "location": {"file": "D:\\dex\\backend\\app\\api\\ledger.py", "line": 340, "function": "get_transactions"}}
{"timestamp": "2025-08-27T14:55:55.264872Z", "level": "ERROR", "trace_id": "2f33911a-20bf-4748-a5d9-412d1d6633b7", "module": "app.api.ledger", "message": "Database error fetching positions: (sqlite3.OperationalError) no such column: ledger_entries.execution_mode\n[SQL: SELECT ledger_entries.id, ledger_entries.user_id, ledger_entries.trace_id, ledger_entries.created_at, ledger_entries.chain, ledger_entries.dex, ledger_entries.trade_type, ledger_entries.input_token, ledger_entries.input_token_symbol, ledger_entries.output_token, ledger_entries.output_token_symbol, ledger_entries.input_amount, ledger_entries.output_amount, ledger_entries.price, ledger_entries.price_usd, ledger_entries.tx_hash, ledger_entries.block_number, ledger_entries.gas_used, ledger_entries.gas_price, ledger_entries.transaction_fee, ledger_entries.transaction_fee_usd, ledger_entries.status, ledger_entries.error_message, ledger_entries.wallet_address, ledger_entries.realized_pnl, ledger_entries.realized_pnl_usd, ledger_entries.risk_score, ledger_entries.risk_factors, ledger_entries.tags, ledger_entries.notes, ledger_entries.archived, ledger_entries.archived_at, ledger_entries.execution_mode \nFROM ledger_entries \nWHERE ledger_entries.user_id = ? AND ledger_entries.chain = ? ORDER BY ledger_entries.created_at DESC\n LIMIT ? OFFSET ?]\n[parameters: (1, 'ethereum', 1000, 0)]\n(Background on this error at: https://sqlalche.me/e/20/e3q8)", "exception": {"type": "OperationalError", "message": "(sqlite3.OperationalError) no such column: ledger_entries.execution_mode\n[SQL: SELECT ledger_entries.id, ledger_entries.user_id, ledger_entries.trace_id, ledger_entries.created_at, ledger_entries.chain, ledger_entries.dex, ledger_entries.trade_type, ledger_entries.input_token, ledger_entries.input_token_symbol, ledger_entries.output_token, ledger_entries.output_token_symbol, ledger_entries.input_amount, ledger_entries.output_amount, ledger_entries.price, ledger_entries.price_usd, ledger_entries.tx_hash, ledger_entries.block_number, ledger_entries.gas_used, ledger_entries.gas_price, ledger_entries.transaction_fee, ledger_entries.transaction_fee_usd, ledger_entries.status, ledger_entries.error_message, ledger_entries.wallet_address, ledger_entries.realized_pnl, ledger_entries.realized_pnl_usd, ledger_entries.risk_score, ledger_entries.risk_factors, ledger_entries.tags, ledger_entries.notes, ledger_entries.archived, ledger_entries.archived_at, ledger_entries.execution_mode \nFROM ledger_entries \nWHERE ledger_entries.user_id = ? AND ledger_entries.chain = ? ORDER BY ledger_entries.created_at DESC\n LIMIT ? OFFSET ?]\n[parameters: (1, 'ethereum', 1000, 0)]\n(Background on this error at: https://sqlalche.me/e/20/e3q8)", "traceback": ["Traceback (most recent call last):\n", "  File \"D:\\dex\\.venv\\Lib\\site-packages\\sqlalchemy\\engine\\base.py\", line 1967, in _exec_single_context\n    self.dialect.do_execute(\n", "  File \"D:\\dex\\.venv\\Lib\\site-packages\\sqlalchemy\\engine\\default.py\", line 951, in do_execute\n    cursor.execute(statement, parameters)\n", "  File \"D:\\dex\\.venv\\Lib\\site-packages\\sqlalchemy\\dialects\\sqlite\\aiosqlite.py\", line 177, in execute\n    self._adapt_connection._handle_exception(error)\n", "  File \"D:\\dex\\.venv\\Lib\\site-packages\\sqlalchemy\\dialects\\sqlite\\aiosqlite.py\", line 337, in _handle_exception\n    raise error\n", "  File \"D:\\dex\\.venv\\Lib\\site-packages\\sqlalchemy\\dialects\\sqlite\\aiosqlite.py\", line 159, in execute\n    self.await_(_cursor.execute(operation, parameters))\n", "  File \"D:\\dex\\.venv\\Lib\\site-packages\\sqlalchemy\\util\\_concurrency_py3k.py\", line 132, in await_only\n    return current.parent.switch(awaitable)  # type: ignore[no-any-return,attr-defined] # noqa: E501\n           ^^^^^^^^^^^^^^^^^^^^^^^^^^^^^^^^\n", "  File \"D:\\dex\\.venv\\Lib\\site-packages\\sqlalchemy\\util\\_concurrency_py3k.py\", line 196, in greenlet_spawn\n    value = await result\n            ^^^^^^^^^^^^\n", "  File \"D:\\dex\\.venv\\Lib\\site-packages\\aiosqlite\\cursor.py\", line 40, in execute\n    await self._execute(self._cursor.execute, sql, parameters)\n", "  File \"D:\\dex\\.venv\\Lib\\site-packages\\aiosqlite\\cursor.py\", line 32, in _execute\n    return await self._conn._execute(fn, *args, **kwargs)\n           ^^^^^^^^^^^^^^^^^^^^^^^^^^^^^^^^^^^^^^^^^^^^^^\n", "  File \"D:\\dex\\.venv\\Lib\\site-packages\\aiosqlite\\core.py\", line 122, in _execute\n    return await future\n           ^^^^^^^^^^^^\n", "  File \"D:\\dex\\.venv\\Lib\\site-packages\\aiosqlite\\core.py\", line 105, in run\n    result = function()\n             ^^^^^^^^^^\n", "sqlite3.OperationalError: no such column: ledger_entries.execution_mode\n", "\nThe above exception was the direct cause of the following exception:\n\n", "Traceback (most recent call last):\n", "  File \"D:\\dex\\backend\\app\\api\\ledger.py\", line 131, in get_positions\n    ledger_entries = await ledger_repo.get_user_ledger(\n                     ^^^^^^^^^^^^^^^^^^^^^^^^^^^^^^^^^^\n", "  File \"D:\\dex\\backend\\app\\storage\\repositories.py\", line 665, in get_user_ledger\n    result = await self.session.execute(stmt)\n             ^^^^^^^^^^^^^^^^^^^^^^^^^^^^^^^^\n", "  File \"D:\\dex\\.venv\\Lib\\site-packages\\sqlalchemy\\ext\\asyncio\\session.py\", line 463, in execute\n    result = await greenlet_spawn(\n             ^^^^^^^^^^^^^^^^^^^^^\n", "  File \"D:\\dex\\.venv\\Lib\\site-packages\\sqlalchemy\\util\\_concurrency_py3k.py\", line 201, in greenlet_spawn\n    result = context.throw(*sys.exc_info())\n             ^^^^^^^^^^^^^^^^^^^^^^^^^^^^^^\n", "  File \"D:\\dex\\.venv\\Lib\\site-packages\\sqlalchemy\\orm\\session.py\", line 2365, in execute\n    return self._execute_internal(\n           ^^^^^^^^^^^^^^^^^^^^^^^\n", "  File \"D:\\dex\\.venv\\Lib\\site-packages\\sqlalchemy\\orm\\session.py\", line 2251, in _execute_internal\n    result: Result[Any] = compile_state_cls.orm_execute_statement(\n                          ^^^^^^^^^^^^^^^^^^^^^^^^^^^^^^^^^^^^^^^^\n", "  File \"D:\\dex\\.venv\\Lib\\site-packages\\sqlalchemy\\orm\\context.py\", line 306, in orm_execute_statement\n    result = conn.execute(\n             ^^^^^^^^^^^^^\n", "  File \"D:\\dex\\.venv\\Lib\\site-packages\\sqlalchemy\\engine\\base.py\", line 1419, in execute\n    return meth(\n           ^^^^^\n", "  File \"D:\\dex\\.venv\\Lib\\site-packages\\sqlalchemy\\sql\\elements.py\", line 526, in _execute_on_connection\n    return connection._execute_clauseelement(\n           ^^^^^^^^^^^^^^^^^^^^^^^^^^^^^^^^^^\n", "  File \"D:\\dex\\.venv\\Lib\\site-packages\\sqlalchemy\\engine\\base.py\", line 1641, in _execute_clauseelement\n    ret = self._execute_context(\n          ^^^^^^^^^^^^^^^^^^^^^^\n", "  File \"D:\\dex\\.venv\\Lib\\site-packages\\sqlalchemy\\engine\\base.py\", line 1846, in _execute_context\n    return self._exec_single_context(\n           ^^^^^^^^^^^^^^^^^^^^^^^^^^\n", "  File \"D:\\dex\\.venv\\Lib\\site-packages\\sqlalchemy\\engine\\base.py\", line 1986, in _exec_single_context\n    self._handle_dbapi_exception(\n", "  File \"D:\\dex\\.venv\\Lib\\site-packages\\sqlalchemy\\engine\\base.py\", line 2355, in _handle_dbapi_exception\n    raise sqlalchemy_exception.with_traceback(exc_info[2]) from e\n", "  File \"D:\\dex\\.venv\\Lib\\site-packages\\sqlalchemy\\engine\\base.py\", line 1967, in _exec_single_context\n    self.dialect.do_execute(\n", "  File \"D:\\dex\\.venv\\Lib\\site-packages\\sqlalchemy\\engine\\default.py\", line 951, in do_execute\n    cursor.execute(statement, parameters)\n", "  File \"D:\\dex\\.venv\\Lib\\site-packages\\sqlalchemy\\dialects\\sqlite\\aiosqlite.py\", line 177, in execute\n    self._adapt_connection._handle_exception(error)\n", "  File \"D:\\dex\\.venv\\Lib\\site-packages\\sqlalchemy\\dialects\\sqlite\\aiosqlite.py\", line 337, in _handle_exception\n    raise error\n", "  File \"D:\\dex\\.venv\\Lib\\site-packages\\sqlalchemy\\dialects\\sqlite\\aiosqlite.py\", line 159, in execute\n    self.await_(_cursor.execute(operation, parameters))\n", "  File \"D:\\dex\\.venv\\Lib\\site-packages\\sqlalchemy\\util\\_concurrency_py3k.py\", line 132, in await_only\n    return current.parent.switch(awaitable)  # type: ignore[no-any-return,attr-defined] # noqa: E501\n           ^^^^^^^^^^^^^^^^^^^^^^^^^^^^^^^^\n", "  File \"D:\\dex\\.venv\\Lib\\site-packages\\sqlalchemy\\util\\_concurrency_py3k.py\", line 196, in greenlet_spawn\n    value = await result\n            ^^^^^^^^^^^^\n", "  File \"D:\\dex\\.venv\\Lib\\site-packages\\aiosqlite\\cursor.py\", line 40, in execute\n    await self._execute(self._cursor.execute, sql, parameters)\n", "  File \"D:\\dex\\.venv\\Lib\\site-packages\\aiosqlite\\cursor.py\", line 32, in _execute\n    return await self._conn._execute(fn, *args, **kwargs)\n           ^^^^^^^^^^^^^^^^^^^^^^^^^^^^^^^^^^^^^^^^^^^^^^\n", "  File \"D:\\dex\\.venv\\Lib\\site-packages\\aiosqlite\\core.py\", line 122, in _execute\n    return await future\n           ^^^^^^^^^^^^\n", "  File \"D:\\dex\\.venv\\Lib\\site-packages\\aiosqlite\\core.py\", line 105, in run\n    result = function()\n             ^^^^^^^^^^\n", "sqlalchemy.exc.OperationalError: (sqlite3.OperationalError) no such column: ledger_entries.execution_mode\n[SQL: SELECT ledger_entries.id, ledger_entries.user_id, ledger_entries.trace_id, ledger_entries.created_at, ledger_entries.chain, ledger_entries.dex, ledger_entries.trade_type, ledger_entries.input_token, ledger_entries.input_token_symbol, ledger_entries.output_token, ledger_entries.output_token_symbol, ledger_entries.input_amount, ledger_entries.output_amount, ledger_entries.price, ledger_entries.price_usd, ledger_entries.tx_hash, ledger_entries.block_number, ledger_entries.gas_used, ledger_entries.gas_price, ledger_entries.transaction_fee, ledger_entries.transaction_fee_usd, ledger_entries.status, ledger_entries.error_message, ledger_entries.wallet_address, ledger_entries.realized_pnl, ledger_entries.realized_pnl_usd, ledger_entries.risk_score, ledger_entries.risk_factors, ledger_entries.tags, ledger_entries.notes, ledger_entries.archived, ledger_entries.archived_at, ledger_entries.execution_mode \nFROM ledger_entries \nWHERE ledger_entries.user_id = ? AND ledger_entries.chain = ? ORDER BY ledger_entries.created_at DESC\n LIMIT ? OFFSET ?]\n[parameters: (1, 'ethereum', 1000, 0)]\n(Background on this error at: https://sqlalche.me/e/20/e3q8)\n"]}, "location": {"file": "D:\\dex\\backend\\app\\api\\ledger.py", "line": 173, "function": "get_positions"}}
{"timestamp": "2025-08-27T14:55:55.272420Z", "level": "ERROR", "trace_id": "2f33911a-20bf-4748-a5d9-412d1d6633b7", "module": "app.core.exception_handlers", "message": "HTTP 500: Database error calculating summary: portfolio_summary_145043ea806b", "location": {"file": "D:\\dex\\backend\\app\\core\\exception_handlers.py", "line": 201, "function": "http_exception_handler"}}
{"timestamp": "2025-08-27T14:55:55.273447Z", "level": "ERROR", "trace_id": "2f33911a-20bf-4748-a5d9-412d1d6633b7", "module": "app.core.exception_handlers", "message": "HTTP 500: Database error retrieving transactions: ledger_transactions_0a5de34c4d2f", "location": {"file": "D:\\dex\\backend\\app\\core\\exception_handlers.py", "line": 201, "function": "http_exception_handler"}}
{"timestamp": "2025-08-27T14:55:55.273447Z", "level": "ERROR", "trace_id": "2f33911a-20bf-4748-a5d9-412d1d6633b7", "module": "app.core.exception_handlers", "message": "HTTP 500: Database error retrieving positions: ledger_positions_ede517a8c5c2", "location": {"file": "D:\\dex\\backend\\app\\core\\exception_handlers.py", "line": 201, "function": "http_exception_handler"}}
{"timestamp": "2025-08-27T14:55:59.324278Z", "level": "ERROR", "trace_id": "2f33911a-20bf-4748-a5d9-412d1d6633b7", "module": "app.middleware.rate_limiting", "message": "Redis connection failed: Error Multiple exceptions: [Errno 10061] Connect call failed ('::1', 6379, 0, 0), [Errno 10061] Connect call failed ('127.0.0.1', 6379) connecting to localhost:6379.", "location": {"file": "D:\\dex\\backend\\app\\middleware\\rate_limiting.py", "line": 303, "function": "connect"}}
{"timestamp": "2025-08-27T14:55:59.325320Z", "level": "ERROR", "trace_id": "2f33911a-20bf-4748-a5d9-412d1d6633b7", "module": "app.middleware.rate_limiting", "message": "Redis connection failed: Error Multiple exceptions: [Errno 10061] Connect call failed ('::1', 6379, 0, 0), [Errno 10061] Connect call failed ('127.0.0.1', 6379) connecting to localhost:6379.", "location": {"file": "D:\\dex\\backend\\app\\middleware\\rate_limiting.py", "line": 303, "function": "connect"}}
{"timestamp": "2025-08-27T14:55:59.325320Z", "level": "ERROR", "trace_id": "2f33911a-20bf-4748-a5d9-412d1d6633b7", "module": "app.middleware.rate_limiting", "message": "Redis connection failed: Error Multiple exceptions: [Errno 10061] Connect call failed ('::1', 6379, 0, 0), [Errno 10061] Connect call failed ('127.0.0.1', 6379) connecting to localhost:6379.", "location": {"file": "D:\\dex\\backend\\app\\middleware\\rate_limiting.py", "line": 303, "function": "connect"}}
{"timestamp": "2025-08-27T14:56:03.431173Z", "level": "ERROR", "trace_id": "2f33911a-20bf-4748-a5d9-412d1d6633b7", "module": "app.middleware.rate_limiting", "message": "Redis connection failed: Error Multiple exceptions: [Errno 10061] Connect call failed ('::1', 6379, 0, 0), [Errno 10061] Connect call failed ('127.0.0.1', 6379) connecting to localhost:6379.", "location": {"file": "D:\\dex\\backend\\app\\middleware\\rate_limiting.py", "line": 303, "function": "connect"}}
{"timestamp": "2025-08-27T14:56:03.432220Z", "level": "ERROR", "trace_id": "2f33911a-20bf-4748-a5d9-412d1d6633b7", "module": "app.middleware.rate_limiting", "message": "Redis connection failed: Error Multiple exceptions: [Errno 10061] Connect call failed ('::1', 6379, 0, 0), [Errno 10061] Connect call failed ('127.0.0.1', 6379) connecting to localhost:6379.", "location": {"file": "D:\\dex\\backend\\app\\middleware\\rate_limiting.py", "line": 303, "function": "connect"}}
{"timestamp": "2025-08-27T14:56:03.432220Z", "level": "ERROR", "trace_id": "2f33911a-20bf-4748-a5d9-412d1d6633b7", "module": "app.middleware.rate_limiting", "message": "Redis connection failed: Error Multiple exceptions: [Errno 10061] Connect call failed ('::1', 6379, 0, 0), [Errno 10061] Connect call failed ('127.0.0.1', 6379) connecting to localhost:6379.", "location": {"file": "D:\\dex\\backend\\app\\middleware\\rate_limiting.py", "line": 303, "function": "connect"}}
{"timestamp": "2025-08-27T14:56:07.517724Z", "level": "ERROR", "trace_id": "2f33911a-20bf-4748-a5d9-412d1d6633b7", "module": "app.middleware.rate_limiting", "message": "Redis connection failed: Error Multiple exceptions: [Errno 10061] Connect call failed ('::1', 6379, 0, 0), [Errno 10061] Connect call failed ('127.0.0.1', 6379) connecting to localhost:6379.", "location": {"file": "D:\\dex\\backend\\app\\middleware\\rate_limiting.py", "line": 303, "function": "connect"}}
{"timestamp": "2025-08-27T14:56:07.518733Z", "level": "ERROR", "trace_id": "2f33911a-20bf-4748-a5d9-412d1d6633b7", "module": "app.middleware.rate_limiting", "message": "Redis connection failed: Error Multiple exceptions: [Errno 10061] Connect call failed ('::1', 6379, 0, 0), [Errno 10061] Connect call failed ('127.0.0.1', 6379) connecting to localhost:6379.", "location": {"file": "D:\\dex\\backend\\app\\middleware\\rate_limiting.py", "line": 303, "function": "connect"}}
{"timestamp": "2025-08-27T14:56:07.518768Z", "level": "ERROR", "trace_id": "2f33911a-20bf-4748-a5d9-412d1d6633b7", "module": "app.middleware.rate_limiting", "message": "Redis connection failed: Error Multiple exceptions: [Errno 10061] Connect call failed ('::1', 6379, 0, 0), [Errno 10061] Connect call failed ('127.0.0.1', 6379) connecting to localhost:6379.", "location": {"file": "D:\\dex\\backend\\app\\middleware\\rate_limiting.py", "line": 303, "function": "connect"}}
{"timestamp": "2025-08-27T14:56:11.577610Z", "level": "ERROR", "trace_id": "2f33911a-20bf-4748-a5d9-412d1d6633b7", "module": "app.middleware.rate_limiting", "message": "Redis connection failed: Error Multiple exceptions: [Errno 10061] Connect call failed ('::1', 6379, 0, 0), [Errno 10061] Connect call failed ('127.0.0.1', 6379) connecting to localhost:6379.", "location": {"file": "D:\\dex\\backend\\app\\middleware\\rate_limiting.py", "line": 303, "function": "connect"}}
{"timestamp": "2025-08-27T14:56:11.607948Z", "level": "ERROR", "trace_id": "2f33911a-20bf-4748-a5d9-412d1d6633b7", "module": "app.middleware.rate_limiting", "message": "Redis connection failed: Error Multiple exceptions: [Errno 10061] Connect call failed ('::1', 6379, 0, 0), [Errno 10061] Connect call failed ('127.0.0.1', 6379) connecting to localhost:6379.", "location": {"file": "D:\\dex\\backend\\app\\middleware\\rate_limiting.py", "line": 303, "function": "connect"}}
{"timestamp": "2025-08-27T14:56:15.658686Z", "level": "ERROR", "trace_id": "2f33911a-20bf-4748-a5d9-412d1d6633b7", "module": "app.middleware.rate_limiting", "message": "Redis connection failed: Error Multiple exceptions: [Errno 10061] Connect call failed ('::1', 6379, 0, 0), [Errno 10061] Connect call failed ('127.0.0.1', 6379) connecting to localhost:6379.", "location": {"file": "D:\\dex\\backend\\app\\middleware\\rate_limiting.py", "line": 303, "function": "connect"}}
{"timestamp": "2025-08-27T14:56:17.110867Z", "level": "ERROR", "trace_id": "2f33911a-20bf-4748-a5d9-412d1d6633b7", "module": "app.middleware.rate_limiting", "message": "Redis connection failed: Error Multiple exceptions: [Errno 10061] Connect call failed ('::1', 6379, 0, 0), [Errno 10061] Connect call failed ('127.0.0.1', 6379) connecting to localhost:6379.", "location": {"file": "D:\\dex\\backend\\app\\middleware\\rate_limiting.py", "line": 303, "function": "connect"}}
{"timestamp": "2025-08-27T14:56:17.111910Z", "level": "ERROR", "trace_id": "2f33911a-20bf-4748-a5d9-412d1d6633b7", "module": "app.api.wallet", "message": "Logging failed: \"Attempt to overwrite 'message' in LogRecord\". Original message: Wallet connection check", "location": {"file": "D:\\dex\\backend\\app\\api\\wallet.py", "line": 198, "function": "log_wallet_operation"}}
{"timestamp": "2025-08-27T14:56:21.144709Z", "level": "ERROR", "trace_id": "2f33911a-20bf-4748-a5d9-412d1d6633b7", "module": "app.middleware.rate_limiting", "message": "Redis connection failed: Error Multiple exceptions: [Errno 10061] Connect call failed ('::1', 6379, 0, 0), [Errno 10061] Connect call failed ('127.0.0.1', 6379) connecting to localhost:6379.", "location": {"file": "D:\\dex\\backend\\app\\middleware\\rate_limiting.py", "line": 303, "function": "connect"}}
{"timestamp": "2025-08-27T14:56:21.149171Z", "level": "ERROR", "trace_id": "2f33911a-20bf-4748-a5d9-412d1d6633b7", "module": "app.api.wallet", "message": "Logging failed: \"Attempt to overwrite 'message' in LogRecord\". Original message: Wallet connection check", "location": {"file": "D:\\dex\\backend\\app\\api\\wallet.py", "line": 198, "function": "log_wallet_operation"}}
{"timestamp": "2025-08-27T14:56:21.168778Z", "level": "ERROR", "trace_id": "2f33911a-20bf-4748-a5d9-412d1d6633b7", "module": "app.middleware.rate_limiting", "message": "Redis connection failed: Error Multiple exceptions: [Errno 10061] Connect call failed ('::1', 6379, 0, 0), [Errno 10061] Connect call failed ('127.0.0.1', 6379) connecting to localhost:6379.", "location": {"file": "D:\\dex\\backend\\app\\middleware\\rate_limiting.py", "line": 303, "function": "connect"}}
{"timestamp": "2025-08-27T14:59:09.936141Z", "level": "ERROR", "trace_id": "81f3a5b9-433d-4c9c-b49c-dd4da9f2c7f5", "module": "app.discovery.event_processor", "message": "Failed to initialize Market Intelligence: \"Attempt to overwrite 'module' in LogRecord\"", "location": {"file": "D:\\dex\\backend\\app\\discovery\\event_processor.py", "line": 131, "function": "__init__"}}
{"timestamp": "2025-08-27T14:59:13.989012Z", "level": "ERROR", "trace_id": "81f3a5b9-433d-4c9c-b49c-dd4da9f2c7f5", "module": "app.middleware.rate_limiting", "message": "Redis connection failed: Error Multiple exceptions: [Errno 10061] Connect call failed ('::1', 6379, 0, 0), [Errno 10061] Connect call failed ('127.0.0.1', 6379) connecting to localhost:6379.", "location": {"file": "D:\\dex\\backend\\app\\middleware\\rate_limiting.py", "line": 303, "function": "connect"}}
{"timestamp": "2025-08-27T14:59:13.989012Z", "level": "ERROR", "trace_id": "81f3a5b9-433d-4c9c-b49c-dd4da9f2c7f5", "module": "app.core.lifespan", "message": "Failed to initialize Redis rate limiter", "location": {"file": "D:\\dex\\backend\\app\\core\\lifespan.py", "line": 94, "function": "setup_enhanced_rate_limiting"}}
{"timestamp": "2025-08-27T14:59:14.405767Z", "level": "ERROR", "trace_id": "81f3a5b9-433d-4c9c-b49c-dd4da9f2c7f5", "module": "app.ws.intelligence_hub", "message": "Failed to start Intelligence WebSocket hub: \"Attempt to overwrite 'module' in LogRecord\"", "location": {"file": "D:\\dex\\backend\\app\\ws\\intelligence_hub.py", "line": 94, "function": "start_hub"}}
{"timestamp": "2025-08-27T14:59:14.405767Z", "level": "ERROR", "trace_id": "81f3a5b9-433d-4c9c-b49c-dd4da9f2c7f5", "module": "app.core.lifespan", "message": "Intelligence hub initialization failed: \"Attempt to overwrite 'module' in LogRecord\"", "location": {"file": "D:\\dex\\backend\\app\\core\\lifespan.py", "line": 276, "function": "lifespan"}}
{"timestamp": "2025-08-27T14:59:17.375841Z", "level": "ERROR", "trace_id": "d7487deb-d049-4dcc-b147-b045c43907ca", "module": "app.discovery.event_processor", "message": "Failed to initialize Market Intelligence: \"Attempt to overwrite 'module' in LogRecord\"", "location": {"file": "D:\\dex\\backend\\app\\discovery\\event_processor.py", "line": 131, "function": "__init__"}}
{"timestamp": "2025-08-27T14:59:21.420484Z", "level": "ERROR", "trace_id": "d7487deb-d049-4dcc-b147-b045c43907ca", "module": "app.middleware.rate_limiting", "message": "Redis connection failed: Error Multiple exceptions: [Errno 10061] Connect call failed ('::1', 6379, 0, 0), [Errno 10061] Connect call failed ('127.0.0.1', 6379) connecting to localhost:6379.", "location": {"file": "D:\\dex\\backend\\app\\middleware\\rate_limiting.py", "line": 303, "function": "connect"}}
{"timestamp": "2025-08-27T14:59:21.420484Z", "level": "ERROR", "trace_id": "d7487deb-d049-4dcc-b147-b045c43907ca", "module": "app.core.lifespan", "message": "Failed to initialize Redis rate limiter", "location": {"file": "D:\\dex\\backend\\app\\core\\lifespan.py", "line": 94, "function": "setup_enhanced_rate_limiting"}}
{"timestamp": "2025-08-27T14:59:21.838383Z", "level": "ERROR", "trace_id": "d7487deb-d049-4dcc-b147-b045c43907ca", "module": "app.ws.intelligence_hub", "message": "Failed to start Intelligence WebSocket hub: \"Attempt to overwrite 'module' in LogRecord\"", "location": {"file": "D:\\dex\\backend\\app\\ws\\intelligence_hub.py", "line": 94, "function": "start_hub"}}
{"timestamp": "2025-08-27T14:59:21.838383Z", "level": "ERROR", "trace_id": "d7487deb-d049-4dcc-b147-b045c43907ca", "module": "app.core.lifespan", "message": "Intelligence hub initialization failed: \"Attempt to overwrite 'module' in LogRecord\"", "location": {"file": "D:\\dex\\backend\\app\\core\\lifespan.py", "line": 276, "function": "lifespan"}}
{"timestamp": "2025-08-27T14:59:52.142466Z", "level": "ERROR", "trace_id": "e53cc9d7-7930-4194-bb7b-894b758df1ca", "module": "app.middleware.rate_limiting", "message": "Redis connection failed: Error Multiple exceptions: [Errno 10061] Connect call failed ('::1', 6379, 0, 0), [Errno 10061] Connect call failed ('127.0.0.1', 6379) connecting to localhost:6379.", "location": {"file": "D:\\dex\\backend\\app\\middleware\\rate_limiting.py", "line": 303, "function": "connect"}}
{"timestamp": "2025-08-27T14:59:52.142466Z", "level": "ERROR", "trace_id": "e53cc9d7-7930-4194-bb7b-894b758df1ca", "module": "app.core.lifespan", "message": "Failed to initialize Redis rate limiter", "location": {"file": "D:\\dex\\backend\\app\\core\\lifespan.py", "line": 94, "function": "setup_enhanced_rate_limiting"}}
{"timestamp": "2025-08-27T14:59:53.090114Z", "level": "ERROR", "trace_id": "e53cc9d7-7930-4194-bb7b-894b758df1ca", "module": "app.discovery.event_processor", "message": "Failed to initialize Market Intelligence: \"Attempt to overwrite 'module' in LogRecord\"", "location": {"file": "D:\\dex\\backend\\app\\discovery\\event_processor.py", "line": 131, "function": "__init__"}}
{"timestamp": "2025-08-27T15:00:49.026427Z", "level": "ERROR", "trace_id": "36898fed-2a02-4e55-8a6c-1e43f52792de", "module": "app.middleware.rate_limiting", "message": "Redis connection failed: Error Multiple exceptions: [Errno 10061] Connect call failed ('::1', 6379, 0, 0), [Errno 10061] Connect call failed ('127.0.0.1', 6379) connecting to localhost:6379.", "location": {"file": "D:\\dex\\backend\\app\\middleware\\rate_limiting.py", "line": 303, "function": "connect"}}
{"timestamp": "2025-08-27T15:00:49.029171Z", "level": "ERROR", "trace_id": "36898fed-2a02-4e55-8a6c-1e43f52792de", "module": "app.core.lifespan", "message": "Failed to initialize Redis rate limiter", "location": {"file": "D:\\dex\\backend\\app\\core\\lifespan.py", "line": 94, "function": "setup_enhanced_rate_limiting"}}
{"timestamp": "2025-08-27T15:00:50.014612Z", "level": "ERROR", "trace_id": "36898fed-2a02-4e55-8a6c-1e43f52792de", "module": "app.discovery.event_processor", "message": "Failed to initialize Market Intelligence: \"Attempt to overwrite 'module' in LogRecord\"", "location": {"file": "D:\\dex\\backend\\app\\discovery\\event_processor.py", "line": 130, "function": "__init__"}}
{"timestamp": "2025-08-27T15:02:20.544300Z", "level": "ERROR", "trace_id": "2b7137f5-4aa0-4942-8895-1a56f5fe86e4", "module": "app.middleware.rate_limiting", "message": "Redis connection failed: Error Multiple exceptions: [Errno 10061] Connect call failed ('::1', 6379, 0, 0), [Errno 10061] Connect call failed ('127.0.0.1', 6379) connecting to localhost:6379.", "location": {"file": "D:\\dex\\backend\\app\\middleware\\rate_limiting.py", "line": 303, "function": "connect"}}
{"timestamp": "2025-08-27T15:02:20.545297Z", "level": "ERROR", "trace_id": "2b7137f5-4aa0-4942-8895-1a56f5fe86e4", "module": "app.core.lifespan", "message": "Failed to initialize Redis rate limiter", "location": {"file": "D:\\dex\\backend\\app\\core\\lifespan.py", "line": 94, "function": "setup_enhanced_rate_limiting"}}
{"timestamp": "2025-08-27T15:02:29.104458Z", "level": "ERROR", "trace_id": "fb7b97fc-d9d6-4981-bbfc-0ec96de672a2", "module": "app.middleware.rate_limiting", "message": "Redis connection failed: Error Multiple exceptions: [Errno 10061] Connect call failed ('::1', 6379, 0, 0), [Errno 10061] Connect call failed ('127.0.0.1', 6379) connecting to localhost:6379.", "location": {"file": "D:\\dex\\backend\\app\\middleware\\rate_limiting.py", "line": 303, "function": "connect"}}
{"timestamp": "2025-08-27T15:02:29.104965Z", "level": "ERROR", "trace_id": "fb7b97fc-d9d6-4981-bbfc-0ec96de672a2", "module": "app.core.lifespan", "message": "Failed to initialize Redis rate limiter", "location": {"file": "D:\\dex\\backend\\app\\core\\lifespan.py", "line": 94, "function": "setup_enhanced_rate_limiting"}}
{"timestamp": "2025-08-27T15:02:30.066401Z", "level": "ERROR", "trace_id": "fb7b97fc-d9d6-4981-bbfc-0ec96de672a2", "module": "app.discovery.event_processor", "message": "Failed to initialize Market Intelligence: \"Attempt to overwrite 'module' in LogRecord\"", "location": {"file": "D:\\dex\\backend\\app\\discovery\\event_processor.py", "line": 130, "function": "__init__"}}
{"timestamp": "2025-08-27T15:02:36.589147Z", "level": "ERROR", "trace_id": "6edb4852-c648-4aa1-8f9d-1aaf51518857", "module": "app.middleware.rate_limiting", "message": "Redis connection failed: Error Multiple exceptions: [Errno 10061] Connect call failed ('::1', 6379, 0, 0), [Errno 10061] Connect call failed ('127.0.0.1', 6379) connecting to localhost:6379.", "location": {"file": "D:\\dex\\backend\\app\\middleware\\rate_limiting.py", "line": 303, "function": "connect"}}
{"timestamp": "2025-08-27T15:02:36.590156Z", "level": "ERROR", "trace_id": "6edb4852-c648-4aa1-8f9d-1aaf51518857", "module": "app.core.lifespan", "message": "Failed to initialize Redis rate limiter", "location": {"file": "D:\\dex\\backend\\app\\core\\lifespan.py", "line": 94, "function": "setup_enhanced_rate_limiting"}}
{"timestamp": "2025-08-27T15:02:37.520718Z", "level": "ERROR", "trace_id": "6edb4852-c648-4aa1-8f9d-1aaf51518857", "module": "app.discovery.event_processor", "message": "Failed to initialize Market Intelligence: \"Attempt to overwrite 'module' in LogRecord\"", "location": {"file": "D:\\dex\\backend\\app\\discovery\\event_processor.py", "line": 130, "function": "__init__"}}
{"timestamp": "2025-08-27T15:02:47.911515Z", "level": "ERROR", "trace_id": "143ace1b-1c2d-4fd1-bb75-466626f79149", "module": "app.middleware.rate_limiting", "message": "Redis connection failed: Error Multiple exceptions: [Errno 10061] Connect call failed ('::1', 6379, 0, 0), [Errno 10061] Connect call failed ('127.0.0.1', 6379) connecting to localhost:6379.", "location": {"file": "D:\\dex\\backend\\app\\middleware\\rate_limiting.py", "line": 303, "function": "connect"}}
{"timestamp": "2025-08-27T15:02:47.914220Z", "level": "ERROR", "trace_id": "143ace1b-1c2d-4fd1-bb75-466626f79149", "module": "app.core.lifespan", "message": "Failed to initialize Redis rate limiter", "location": {"file": "D:\\dex\\backend\\app\\core\\lifespan.py", "line": 94, "function": "setup_enhanced_rate_limiting"}}
{"timestamp": "2025-08-27T15:02:48.891726Z", "level": "ERROR", "trace_id": "143ace1b-1c2d-4fd1-bb75-466626f79149", "module": "app.discovery.event_processor", "message": "Failed to initialize Market Intelligence: \"Attempt to overwrite 'module' in LogRecord\"", "location": {"file": "D:\\dex\\backend\\app\\discovery\\event_processor.py", "line": 130, "function": "__init__"}}
{"timestamp": "2025-08-27T15:05:28.142788Z", "level": "ERROR", "trace_id": "2e412975-ec5b-4075-94a2-a650766c60f5", "module": "app.middleware.rate_limiting", "message": "Redis connection failed: Error Multiple exceptions: [Errno 10061] Connect call failed ('::1', 6379, 0, 0), [Errno 10061] Connect call failed ('127.0.0.1', 6379) connecting to localhost:6379.", "location": {"file": "D:\\dex\\backend\\app\\middleware\\rate_limiting.py", "line": 303, "function": "connect"}}
{"timestamp": "2025-08-27T15:05:28.143706Z", "level": "ERROR", "trace_id": "2e412975-ec5b-4075-94a2-a650766c60f5", "module": "app.core.lifespan", "message": "Failed to initialize Redis rate limiter", "location": {"file": "D:\\dex\\backend\\app\\core\\lifespan.py", "line": 94, "function": "setup_enhanced_rate_limiting"}}
{"timestamp": "2025-08-27T15:05:29.092812Z", "level": "ERROR", "trace_id": "2e412975-ec5b-4075-94a2-a650766c60f5", "module": "app.discovery.event_processor", "message": "Failed to initialize Market Intelligence: \"Attempt to overwrite 'module' in LogRecord\"", "location": {"file": "D:\\dex\\backend\\app\\discovery\\event_processor.py", "line": 130, "function": "__init__"}}
{"timestamp": "2025-08-27T15:05:35.682630Z", "level": "ERROR", "trace_id": "b446b667-35e6-4642-9ceb-f53e6da0e4a9", "module": "app.middleware.rate_limiting", "message": "Redis connection failed: Error Multiple exceptions: [Errno 10061] Connect call failed ('::1', 6379, 0, 0), [Errno 10061] Connect call failed ('127.0.0.1', 6379) connecting to localhost:6379.", "location": {"file": "D:\\dex\\backend\\app\\middleware\\rate_limiting.py", "line": 303, "function": "connect"}}
{"timestamp": "2025-08-27T15:05:35.682630Z", "level": "ERROR", "trace_id": "b446b667-35e6-4642-9ceb-f53e6da0e4a9", "module": "app.core.lifespan", "message": "Failed to initialize Redis rate limiter", "location": {"file": "D:\\dex\\backend\\app\\core\\lifespan.py", "line": 94, "function": "setup_enhanced_rate_limiting"}}
{"timestamp": "2025-08-27T15:05:36.638951Z", "level": "ERROR", "trace_id": "b446b667-35e6-4642-9ceb-f53e6da0e4a9", "module": "app.discovery.event_processor", "message": "Failed to initialize Market Intelligence: \"Attempt to overwrite 'module' in LogRecord\"", "location": {"file": "D:\\dex\\backend\\app\\discovery\\event_processor.py", "line": 130, "function": "__init__"}}
{"timestamp": "2025-08-27T15:05:43.242090Z", "level": "ERROR", "trace_id": "96883830-38ea-4214-b0f5-36d65a71fc5b", "module": "app.middleware.rate_limiting", "message": "Redis connection failed: Error Multiple exceptions: [Errno 10061] Connect call failed ('::1', 6379, 0, 0), [Errno 10061] Connect call failed ('127.0.0.1', 6379) connecting to localhost:6379.", "location": {"file": "D:\\dex\\backend\\app\\middleware\\rate_limiting.py", "line": 303, "function": "connect"}}
{"timestamp": "2025-08-27T15:05:43.242090Z", "level": "ERROR", "trace_id": "96883830-38ea-4214-b0f5-36d65a71fc5b", "module": "app.core.lifespan", "message": "Failed to initialize Redis rate limiter", "location": {"file": "D:\\dex\\backend\\app\\core\\lifespan.py", "line": 94, "function": "setup_enhanced_rate_limiting"}}
{"timestamp": "2025-08-27T15:05:44.204480Z", "level": "ERROR", "trace_id": "96883830-38ea-4214-b0f5-36d65a71fc5b", "module": "app.discovery.event_processor", "message": "Failed to initialize Market Intelligence: \"Attempt to overwrite 'module' in LogRecord\"", "location": {"file": "D:\\dex\\backend\\app\\discovery\\event_processor.py", "line": 130, "function": "__init__"}}
{"timestamp": "2025-08-27T15:05:51.983554Z", "level": "ERROR", "trace_id": "c7170e50-05af-4d25-a752-d71533c8128b", "module": "app.middleware.rate_limiting", "message": "Redis connection failed: Error Multiple exceptions: [Errno 10061] Connect call failed ('::1', 6379, 0, 0), [Errno 10061] Connect call failed ('127.0.0.1', 6379) connecting to localhost:6379.", "location": {"file": "D:\\dex\\backend\\app\\middleware\\rate_limiting.py", "line": 303, "function": "connect"}}
{"timestamp": "2025-08-27T15:05:51.983554Z", "level": "ERROR", "trace_id": "c7170e50-05af-4d25-a752-d71533c8128b", "module": "app.core.lifespan", "message": "Failed to initialize Redis rate limiter", "location": {"file": "D:\\dex\\backend\\app\\core\\lifespan.py", "line": 94, "function": "setup_enhanced_rate_limiting"}}
{"timestamp": "2025-08-27T15:05:52.920898Z", "level": "ERROR", "trace_id": "c7170e50-05af-4d25-a752-d71533c8128b", "module": "app.discovery.event_processor", "message": "Failed to initialize Market Intelligence: \"Attempt to overwrite 'module' in LogRecord\"", "location": {"file": "D:\\dex\\backend\\app\\discovery\\event_processor.py", "line": 130, "function": "__init__"}}
{"timestamp": "2025-08-27T15:06:45.786100Z", "level": "ERROR", "trace_id": "a52d6faa-b491-46f4-85b4-d89c70106df3", "module": "app.api", "message": "\u274c Health Check API registration failed: name 'get_logger' is not defined", "location": {"file": "D:\\dex\\backend\\app\\api\\__init__.py", "line": 51, "function": "_register_router"}}
{"timestamp": "2025-08-27T15:06:46.500813Z", "level": "ERROR", "trace_id": "a52d6faa-b491-46f4-85b4-d89c70106df3", "module": "app.api", "message": "\u274c Presets API registration failed: name 'get_logger' is not defined", "location": {"file": "D:\\dex\\backend\\app\\api\\__init__.py", "line": 104, "function": "<module>"}}
{"timestamp": "2025-08-27T15:06:50.634579Z", "level": "ERROR", "trace_id": "a52d6faa-b491-46f4-85b4-d89c70106df3", "module": "app.middleware.rate_limiting", "message": "Redis connection failed: Error Multiple exceptions: [Errno 10061] Connect call failed ('::1', 6379, 0, 0), [Errno 10061] Connect call failed ('127.0.0.1', 6379) connecting to localhost:6379.", "location": {"file": "D:\\dex\\backend\\app\\middleware\\rate_limiting.py", "line": 303, "function": "connect"}}
{"timestamp": "2025-08-27T15:06:50.635598Z", "level": "ERROR", "trace_id": "a52d6faa-b491-46f4-85b4-d89c70106df3", "module": "app.core.lifespan", "message": "Failed to initialize Redis rate limiter", "location": {"file": "D:\\dex\\backend\\app\\core\\lifespan.py", "line": 94, "function": "setup_enhanced_rate_limiting"}}
{"timestamp": "2025-08-27T15:06:50.667771Z", "level": "ERROR", "trace_id": "a52d6faa-b491-46f4-85b4-d89c70106df3", "module": "app.core.lifespan", "message": "Wallet registry initialization failed: name 'get_logger' is not defined", "location": {"file": "D:\\dex\\backend\\app\\core\\lifespan.py", "line": 186, "function": "lifespan"}}
{"timestamp": "2025-08-27T15:06:51.101011Z", "level": "ERROR", "trace_id": "a52d6faa-b491-46f4-85b4-d89c70106df3", "module": "app.core.lifespan", "message": "Risk manager initialization failed: name 'get_logger' is not defined", "location": {"file": "D:\\dex\\backend\\app\\core\\lifespan.py", "line": 244, "function": "lifespan"}}
{"timestamp": "2025-08-27T15:06:51.105453Z", "level": "ERROR", "trace_id": "a52d6faa-b491-46f4-85b4-d89c70106df3", "module": "app.core.lifespan", "message": "Discovery service initialization failed: name 'get_logger' is not defined", "location": {"file": "D:\\dex\\backend\\app\\core\\lifespan.py", "line": 260, "function": "lifespan"}}
{"timestamp": "2025-08-27T15:06:53.412750Z", "level": "ERROR", "trace_id": "d8bae995-2002-4e64-a239-4beb195530e1", "module": "app.api", "message": "\u274c Health Check API registration failed: name 'get_logger' is not defined", "location": {"file": "D:\\dex\\backend\\app\\api\\__init__.py", "line": 51, "function": "_register_router"}}
{"timestamp": "2025-08-27T15:06:54.077251Z", "level": "ERROR", "trace_id": "d8bae995-2002-4e64-a239-4beb195530e1", "module": "app.api", "message": "\u274c Presets API registration failed: name 'get_logger' is not defined", "location": {"file": "D:\\dex\\backend\\app\\api\\__init__.py", "line": 104, "function": "<module>"}}
{"timestamp": "2025-08-27T15:06:58.195035Z", "level": "ERROR", "trace_id": "d8bae995-2002-4e64-a239-4beb195530e1", "module": "app.middleware.rate_limiting", "message": "Redis connection failed: Error Multiple exceptions: [Errno 10061] Connect call failed ('::1', 6379, 0, 0), [Errno 10061] Connect call failed ('127.0.0.1', 6379) connecting to localhost:6379.", "location": {"file": "D:\\dex\\backend\\app\\middleware\\rate_limiting.py", "line": 303, "function": "connect"}}
{"timestamp": "2025-08-27T15:06:58.195035Z", "level": "ERROR", "trace_id": "d8bae995-2002-4e64-a239-4beb195530e1", "module": "app.core.lifespan", "message": "Failed to initialize Redis rate limiter", "location": {"file": "D:\\dex\\backend\\app\\core\\lifespan.py", "line": 94, "function": "setup_enhanced_rate_limiting"}}
{"timestamp": "2025-08-27T15:06:58.226412Z", "level": "ERROR", "trace_id": "d8bae995-2002-4e64-a239-4beb195530e1", "module": "app.core.lifespan", "message": "Wallet registry initialization failed: name 'get_logger' is not defined", "location": {"file": "D:\\dex\\backend\\app\\core\\lifespan.py", "line": 186, "function": "lifespan"}}
{"timestamp": "2025-08-27T15:06:58.620502Z", "level": "ERROR", "trace_id": "d8bae995-2002-4e64-a239-4beb195530e1", "module": "app.core.lifespan", "message": "Risk manager initialization failed: name 'get_logger' is not defined", "location": {"file": "D:\\dex\\backend\\app\\core\\lifespan.py", "line": 244, "function": "lifespan"}}
{"timestamp": "2025-08-27T15:06:58.621511Z", "level": "ERROR", "trace_id": "d8bae995-2002-4e64-a239-4beb195530e1", "module": "app.core.lifespan", "message": "Discovery service initialization failed: name 'get_logger' is not defined", "location": {"file": "D:\\dex\\backend\\app\\core\\lifespan.py", "line": 260, "function": "lifespan"}}
{"timestamp": "2025-08-27T15:07:05.804056Z", "level": "ERROR", "trace_id": "0e0dfe3f-e000-41a8-a56b-0ae3adaf63e8", "module": "app.api", "message": "\u274c Presets API registration failed: name 'logging' is not defined", "location": {"file": "D:\\dex\\backend\\app\\api\\__init__.py", "line": 104, "function": "<module>"}}
{"timestamp": "2025-08-27T15:07:09.946191Z", "level": "ERROR", "trace_id": "0e0dfe3f-e000-41a8-a56b-0ae3adaf63e8", "module": "app.middleware.rate_limiting", "message": "Redis connection failed: Error Multiple exceptions: [Errno 10061] Connect call failed ('::1', 6379, 0, 0), [Errno 10061] Connect call failed ('127.0.0.1', 6379) connecting to localhost:6379.", "location": {"file": "D:\\dex\\backend\\app\\middleware\\rate_limiting.py", "line": 303, "function": "connect"}}
{"timestamp": "2025-08-27T15:07:09.946191Z", "level": "ERROR", "trace_id": "0e0dfe3f-e000-41a8-a56b-0ae3adaf63e8", "module": "app.core.lifespan", "message": "Failed to initialize Redis rate limiter", "location": {"file": "D:\\dex\\backend\\app\\core\\lifespan.py", "line": 94, "function": "setup_enhanced_rate_limiting"}}
{"timestamp": "2025-08-27T15:07:10.920687Z", "level": "ERROR", "trace_id": "0e0dfe3f-e000-41a8-a56b-0ae3adaf63e8", "module": "app.discovery.event_processor", "message": "Failed to initialize Market Intelligence: \"Attempt to overwrite 'module' in LogRecord\"", "location": {"file": "D:\\dex\\backend\\app\\discovery\\event_processor.py", "line": 130, "function": "__init__"}}
